Workbook

Sheet DB
A1: SCHEDULE AIRLINE | D1: PESAWAT
A3: FLIGHT NO | B3: ROUTE | D3: REGISTRASI | E3: TYPE | F3: MASKAPAI
A4: - | B4: EX RON | D4: PK-JTX | E4: BELL 407 | F4: AIR PASIFIC
A5: 0B 1001 | B5: WIII | D5: PK-ODC | E5: AS350 | F5: AIRFAST
A6: 0B 1051 | B6: WAJJ | D6: PK-OCF | E6: DHC 6 | F6: AIRFAST
A7: 0B 5021 | B7: WAAA | D7: PK-OCH | E7: TWIN OTTER | F7: AIRFAST
A8: 0B 5022 | B8: WAMM | D8: PK-OCI | E8: DHC 6 | F8: AIRFAST
A9: 0B 5024 | B9: WAAA | D9: PK-NKV | E9: B 733 | F9: AIRNESIA
A10: 0B 5271 | B10: WAOO | D10: PK-NMI | E10: B 733 | F10: AIRNESIA
A11: 0B 5272 | B11: WAOO | D11: PK-BBN | E11: B 738 | F11: B. B. N
A12: 0B 5273 | B12: WAOO | D12: PK-BBJ | E12: B 734 | F12: B. B. N.
A13: 0B 5274 | B13: WAOO | D13: PK-BKA | E13: A 320 | F13: BATIK AIR
A14: 0B 5275 | B14: WAOO | D14: PK-BKB | E14: A 320 | F14: BATIK AIR
... A317: GA 0463 | B317: WADD | D317: PK-GUH | E317: B 738 | F317: GARUDA
D318: PK-GUI | E318: B 738 | F318: GARUDA
D319: PK-GUJ | E319: B 738 | F319: GARUDA
D320: PK-GUK | E320: B 738 | F320: GARUDA
D321: PK-GUL | E321: B 738 | F321: GARUDA
D322: PK-GUM | E322: B 738 | F322: GARUDA
D323: PK-GUN | E323: B 738 | F323: GARUDA
D324: PK-GUO | E324: B 738 | F324: GARUDA
D325: PK-GUP | E325: B 738 | F325: GARUDA
D326: PK-GUQ | E326: B 738 | F326: GARUDA
D327: PK-GUR | E327: B 738 | F327: GARUDA
D328: PK-GUS | E328: B 738 | F328: GARUDA
D329: PK-GUT | E329: B 738 | F329: GARUDA
... D441: PK-YST | E441: B 733 | F441: TRIGANA
D442: T7-X14 | E442: G VI
D443: 20241 | E443: XIAN Y20 B
D444: 20248 | E444: XIAN Y20 B
D445: 13-031 | E445: DO 328
D446: 13-075 | E446: DO 328
D447: 9H-VCB | E447: CL 350
D448: 9H-VCR | E448: CL 350
D449: 9H-VIE | E449: G 7500
D450: 9H-VIT | E450: G 7500
D451: 9M-VEV | E451: AVANTI
D452: A56-003 | E452: FAL 7X
D453: B-8160 | E453: G V
D454: F-RAFP | E454: FAL 900
...

Sheet 01
A1: APRON MOVEMENT SHEET HALIM PERDANAKUSUMA
A7: AERODROME : | C7: WIHH
A8: TANGGAL : | C8: 45839
A9: PETUGAS AMC | C9: PAGI SIANG ( 07:00 - 18:59) | E9: MALAM (19:00 - 06:59)
C10: MALDIKA HASIBUAN | E10: NIKON
C11: NUZAR AFRIAN | E11: RYAN KHALIQ
C12: PELTU SUCIADI | E12: SERDA JIM MIM
C13: AHCMAD FAUZI
A15: NO | B15: REGISTRATION | C15: TYPE | D15: TIME OF | H15: PARKING STAND | I15: FROM | J15: TO | K15: FLIGHT NO | M15: OPERATOR / AIRLINES | N15: REMARKS | O15: STATUS
D16: ON BLOCK | F16: OFF BLOCK | K16: ARR | L16: DEP
Q17: 1 | R17: 2 | S17: 3 | T17: 4 | U17: 5
A18: 1 | B18: PK-VCD | C18: =IF(B18>1,VLOOKUP(B18,DB!$D$4:$E$800,2,0),"") -> PA 34 | D18: - | E18: FALSE | G18: FALSE | H18: NSA01 | I18: =IF(K18>1,VLOOKUP(K18,DB!$A$4:$B$500,2,0),"") | J18: =IF(L18>1,VLOOKUP(L18,DB!$A$4:$B$500,2,0),"") | M18: =IF(B18>1,VLOOKUP(B18,DB!$D$4:$F$800,3,0),"") -> PENAS | N18: UNSERVICEABLE | O18: =IF(ISBLANK(F18),"RON","") -> RON | Q18: =IF(R18="RON",H18,"") -> NSA01 | R18: =IF(O18="RON",O18,"") -> RON | S18: =IF(R18="RON",C18,"") -> PA 34 | T18: =IF(R18="RON",B18,"") -> PK-VCD | U18: =IF(R18="RON",M18,"") -> PENAS
A19: 2 | B19: PK-RSO | C19: =IF(B19>1,VLOOKUP(B19,DB!$D$4:$E$800,2,0),"") -> CT 650 | D19: - | E19: FALSE | G19: FALSE | H19: NSA02 | I19: =IF(K19>1,VLOOKUP(K19,DB!$A$4:$B$500,2,0),"") | J19: =IF(L19>1,VLOOKUP(L19,DB!$A$4:$B$500,2,0),"") | M19: =IF(B19>1,VLOOKUP(B19,DB!$D$4:$F$800,3,0),"") -> ENGGANG | N19: UNSERVICEABLE | O19: =IF(ISBLANK(F19),"RON","") -> RON | Q19: =IF(R19="RON",H19,"") -> NSA02 | R19: =IF(O19="RON",O19,"") -> RON | S19: =IF(R19="RON",C19,"") -> CT 650 | T19: =IF(R19="RON",B19,"") -> PK-RSO | U19: =IF(R19="RON",M19,"") -> ENGGANG
A20: 3 | B20: PK-RDA | C20: =IF(B20>1,VLOOKUP(B20,DB!$D$4:$E$800,2,0),"") -> HK 900 | D20: - | E20: FALSE | G20: FALSE | H20: NSA03 | I20: =IF(K20>1,VLOOKUP(K20,DB!$A$4:$B$500,2,0),"") | J20: =IF(L20>1,VLOOKUP(L20,DB!$A$4:$B$500,2,0),"") | M20: =IF(B20>1,VLOOKUP(B20,DB!$D$4:$F$800,3,0),"") -> TRI MG | N20: UNSERVICEABLE | O20: =IF(ISBLANK(F20),"RON","") -> RON | Q20: =IF(R20="RON",H20,"") -> NSA03 | R20: =IF(O20="RON",O20,"") -> RON | S20: =IF(R20="RON",C20,"") -> HK 900 | T20: =IF(R20="RON",B20,"") -> PK-RDA | U20: =IF(R20="RON",M20,"") -> TRI MG
A21: 4 | B21: PK-YGK | C21: =IF(B21>1,VLOOKUP(B21,DB!$D$4:$E$800,2,0),"") -> HK 400 | D21: - | E21: FALSE | G21: FALSE | H21: NSA04 | I21: =IF(K21>1,VLOOKUP(K21,DB!$A$4:$B$500,2,0),"") | J21: =IF(L21>1,VLOOKUP(L21,DB!$A$4:$B$500,2,0),"") | M21: =IF(B21>1,VLOOKUP(B21,DB!$D$4:$F$800,3,0),"") -> TRI MG | N21: UNSERVICEABLE | O21: =IF(ISBLANK(F21),"RON","") -> RON | Q21: =IF(R21="RON",H21,"") -> NSA04 | R21: =IF(O21="RON",O21,"") -> RON | S21: =IF(R21="RON",C21,"") -> HK 400 | T21: =IF(R21="RON",B21,"") -> PK-YGK | U21: =IF(R21="RON",M21,"") -> TRI MG
A22: 5 | B22: N-484BA | C22: =IF(B22>1,VLOOKUP(B22,DB!$D$4:$E$800,2,0),"") -> LJ 31 | D22: - | E22: FALSE | G22: FALSE | H22: NSA05 | I22: =IF(K22>1,VLOOKUP(K22,DB!$A$4:$B$500,2,0),"") | J22: =IF(L22>1,VLOOKUP(L22,DB!$A$4:$B$500,2,0),"") | M22: =IF(B22>1,VLOOKUP(B22,DB!$D$4:$F$800,3,0),"") -> IAP | N22: UNSERVICEABLE | O22: =IF(ISBLANK(F22),"RON","") -> RON | Q22: =IF(R22="RON",H22,"") -> NSA05 | R22: =IF(O22="RON",O22,"") -> RON | S22: =IF(R22="RON",C22,"") -> LJ 31 | T22: =IF(R22="RON",B22,"") -> N-484BA | U22: =IF(R22="RON",M22,"") -> IAP
A23: 6 | B23: A-2701 | C23: =IF(B23>1,VLOOKUP(B23,DB!$D$4:$E$800,2,0),"") -> FOKKER 27 | D23: - | E23: FALSE | G23: FALSE | H23: NSA06 | I23: =IF(K23>1,VLOOKUP(K23,DB!$A$4:$B$500,2,0),"") | J23: =IF(L23>1,VLOOKUP(L23,DB!$A$4:$B$500,2,0),"") | M23: =IF(B23>1,VLOOKUP(B23,DB!$D$4:$F$800,3,0),"") -> TNI AU | N23: UNSERVICEABLE | O23: =IF(ISBLANK(F23),"RON","") -> RON | Q23: =IF(R23="RON",H23,"") -> NSA06 | R23: =IF(O23="RON",O23,"") -> RON | S23: =IF(R23="RON",C23,"") -> FOKKER 27 | T23: =IF(R23="RON",B23,"") -> A-2701 | U23: =IF(R23="RON",M23,"") -> TNI AU
A24: 7 | B24: A-2706 | C24: =IF(B24>1,VLOOKUP(B24,DB!$D$4:$E$800,2,0),"") -> FOKKER 27 | D24: - | E24: FALSE | G24: FALSE | H24: NSA07 | I24: =IF(K24>1,VLOOKUP(K24,DB!$A$4:$B$500,2,0),"") | J24: =IF(L24>1,VLOOKUP(L24,DB!$A$4:$B$500,2,0),"") | M24: =IF(B24>1,VLOOKUP(B24,DB!$D$4:$F$800,3,0),"") -> TNI AU | N24: UNSERVICEABLE | O24: =IF(ISBLANK(F24),"RON","") -> RON | Q24: =IF(R24="RON",H24,"") -> NSA07 | R24: =IF(O24="RON",O24,"") -> RON | S24: =IF(R24="RON",C24,"") -> FOKKER 27 | T24: =IF(R24="RON",B24,"") -> A-2706 | U24: =IF(R24="RON",M24,"") -> TNI AU
A25: 8 | B25: A-2801 | C25: =IF(B25>1,VLOOKUP(B25,DB!$D$4:$E$800,2,0),"") -> FOKKER 28 | D25: - | E25: FALSE | G25: FALSE | H25: NSA08 | I25: =IF(K25>1,VLOOKUP(K25,DB!$A$4:$B$500,2,0),"") | J25: =IF(L25>1,VLOOKUP(L25,DB!$A$4:$B$500,2,0),"") | M25: =IF(B25>1,VLOOKUP(B25,DB!$D$4:$F$800,3,0),"") -> TNI AU | N25: UNSERVICEABLE | O25: =IF(ISBLANK(F25),"RON","") -> RON | Q25: =IF(R25="RON",H25,"") -> NSA08 | R25: =IF(O25="RON",O25,"") -> RON | S25: =IF(R25="RON",C25,"") -> FOKKER 28 | T25: =IF(R25="RON",B25,"") -> A-2801 | U25: =IF(R25="RON",M25,"") -> TNI AU
A26: 9 | B26: PK-YGR | C26: =IF(B26>1,VLOOKUP(B26,DB!$D$4:$E$800,2,0),"") -> HK 800 | D26: - | E26: FALSE | G26: FALSE | H26: NSA09 | I26: =IF(K26>1,VLOOKUP(K26,DB!$A$4:$B$500,2,0),"") | J26: =IF(L26>1,VLOOKUP(L26,DB!$A$4:$B$500,2,0),"") | M26: =IF(B26>1,VLOOKUP(B26,DB!$D$4:$F$800,3,0),"") -> TRI MG | N26: UNSERVICEABLE | O26: =IF(ISBLANK(F26),"RON","") -> RON | Q26: =IF(R26="RON",H26,"") -> NSA09 | R26: =IF(O26="RON",O26,"") -> RON | S26: =IF(R26="RON",C26,"") -> HK 800 | T26: =IF(R26="RON",B26,"") -> PK-YGR | U26: =IF(R26="RON",M26,"") -> TRI MG
A27: 10 | B27: N-2409K | C27: =IF(B27>1,VLOOKUP(B27,DB!$D$4:$E$800,2,0),"") -> HK 800 | D27: - | E27: FALSE | G27: FALSE | H27: NSA10 | I27: =IF(K27>1,VLOOKUP(K27,DB!$A$4:$B$500,2,0),"") | J27: =IF(L27>1,VLOOKUP(L27,DB!$A$4:$B$500,2,0),"") | M27: AFM | O27: =IF(ISBLANK(F27),"RON","") -> RON | Q27: =IF(R27="RON",H27,"") -> NSA10 | R27: =IF(O27="RON",O27,"") -> RON | S27: =IF(R27="RON",C27,"") -> HK 800 | T27: =IF(R27="RON",B27,"") -> N-2409K | U27: =IF(R27="RON",M27,"") -> AFM
A28: 11 | B28: T7-HNC | C28: =IF(B28>1,VLOOKUP(B28,DB!$D$4:$E$800,2,0),"") -> KING AIR | D28: - | E28: FALSE | G28: FALSE | H28: NSA11 | I28: =IF(K28>1,VLOOKUP(K28,DB!$A$4:$B$500,2,0),"") | J28: =IF(L28>1,VLOOKUP(L28,DB!$A$4:$B$500,2,0),"") | M28: AFM | O28: =IF(ISBLANK(F28),"RON","") -> RON | Q28: =IF(R28="RON",H28,"") -> NSA11 | R28: =IF(O28="RON",O28,"") -> RON | S28: =IF(R28="RON",C28,"") -> KING AIR | T28: =IF(R28="RON",B28,"") -> T7-HNC | U28: =IF(R28="RON",M28,"") -> AFM
A29: 12 | B29: T7-FCN | C29: =IF(B29>1,VLOOKUP(B29,DB!$D$4:$E$800,2,0),"") -> HK 800 | D29: - | E29: FALSE | G29: FALSE | H29: NSA12 | I29: =IF(K29>1,VLOOKUP(K29,DB!$A$4:$B$500,2,0),"") | J29: =IF(L29>1,VLOOKUP(L29,DB!$A$4:$B$500,2,0),"") | M29: KARISMA | O29: =IF(ISBLANK(F29),"RON","") -> RON | Q29: =IF(R29="RON",H29,"") -> NSA12 | R29: =IF(O29="RON",O29,"") -> RON | S29: =IF(R29="RON",C29,"") -> HK 800 | T29: =IF(R29="RON",B29,"") -> T7-FCN | U29: =IF(R29="RON",M29,"") -> KARISMA
A30: 13 | B30: PK-CEO | C30: =IF(B30>1,VLOOKUP(B30,DB!$D$4:$E$800,2,0),"") -> HK 800 | D30: - | E30: FALSE | F30: 0.74375 | G30: TRUE | H30: NSA13 | I30: =IF(K30>1,VLOOKUP(K30,DB!$A$4:$B$500,2,0),"") -> EX RON | J30: B3 | K30: - | M30: =IF(B30>1,VLOOKUP(B30,DB!$D$4:$F$800,3,0),"") -> JETSET | O30: =IF(ISBLANK(F30),"RON","") | Q30: =IF(R30="RON",H30,"") | R30: =IF(O30="RON",O30,"") | S30: =IF(R30="RON",C30,"") | T30: =IF(R30="RON",B30,"") | U30: =IF(R30="RON",M30,"")
A31: 14 | B31: T7-ARN | C31: =IF(B31>1,VLOOKUP(B31,DB!$D$4:$E$800,2,0),"") -> G VI | D31: - | E31: FALSE | F31: 0.625 | G31: TRUE | H31: SA01 | I31: =IF(K31>1,VLOOKUP(K31,DB!$A$4:$B$500,2,0),"") -> EX RON | J31: HGR | K31: - | M31: =IF(B31>1,VLOOKUP(B31,DB!$D$4:$F$800,3,0),"") -> PREMI | O31: =IF(ISBLANK(F31),"RON","") | Q31: =IF(R31="RON",H31,"") | R31: =IF(O31="RON",O31,"") | S31: =IF(R31="RON",C31,"") | T31: =IF(R31="RON",B31,"") | U31: =IF(R31="RON",M31,"")
A32: 15 | B32: PK-RJH | C32: =IF(B32>1,VLOOKUP(B32,DB!$D$4:$E$800,2,0),"") -> EC 135 | D32: - | E32: FALSE | G32: FALSE | H32: SA02 | I32: =IF(K32>1,VLOOKUP(K32,DB!$A$4:$B$500,2,0),"") | J32: =IF(L32>1,VLOOKUP(L32,DB!$A$4:$B$500,2,0),"") | M32: =IF(B32>1,VLOOKUP(B32,DB!$D$4:$F$800,3,0),"") -> PREMI | O32: =IF(ISBLANK(F32),"RON","") -> RON | Q32: =IF(R32="RON",H32,"") -> SA02 | R32: =IF(O32="RON",O32,"") -> RON | S32: =IF(R32="RON",C32,"") -> EC 135 | T32: =IF(R32="RON",B32,"") -> PK-RJH | U32: =IF(R32="RON",M32,"") -> PREMI
A33: 16 | B33: A97-448 | C33: =IF(B33>1,VLOOKUP(B33,DB!$D$4:$E$800,2,0),"") -> C 130J | D33: - | E33: FALSE | F33: 0.42777778 | G33: TRUE | H33: SA03 | I33: =IF(K33>1,VLOOKUP(K33,DB!$A$4:$B$500,2,0),"") -> EX RON | J33: YPDN | K33: - | M33: GAPURA | O33: =IF(ISBLANK(F33),"RON","") | Q33: =IF(R33="RON",H33,"") | R33: =IF(O33="RON",O33,"") | S33: =IF(R33="RON",C33,"") | T33: =IF(R33="RON",B33,"") | U33: =IF(R33="RON",M33,"")
A34: 17 | B34: N-227GV | C34: =IF(B34>1,VLOOKUP(B34,DB!$D$4:$E$800,2,0),"") -> L 1000 | D34: - | E34: FALSE | G34: FALSE | H34: SA04 | I34: =IF(K34>1,VLOOKUP(K34,DB!$A$4:$B$500,2,0),"") | J34: =IF(L34>1,VLOOKUP(L34,DB!$A$4:$B$500,2,0),"") | M34: =IF(B34>1,VLOOKUP(B34,DB!$D$4:$F$800,3,0),"") -> PREMI | O34: =IF(ISBLANK(F34),"RON","") -> RON | Q34: =IF(R34="RON",H34,"") -> SA04 | R34: =IF(O34="RON",O34,"") -> RON | S34: =IF(R34="RON",C34,"") -> L 1000 | T34: =IF(R34="RON",B34,"") -> N-227GV | U34: =IF(R34="RON",M34,"") -> PREMI
A35: 18 | B35: PK-LAL | C35: =IF(B35>1,VLOOKUP(B35,DB!$D$4:$E$800,2,0),"") -> A 320 | D35: - | E35: FALSE | F35: 0.37222222 | G35: TRUE | H35: SA05 | I35: =IF(K35>1,VLOOKUP(K35,DB!$A$4:$B$500,2,0),"") -> EX RON | J35: A3 | K35: - | M35: =IF(B35>1,VLOOKUP(B35,DB!$D$4:$F$800,3,0),"") -> BATIK AIR | O35: =IF(ISBLANK(F35),"RON","") | Q35: =IF(R35="RON",H35,"") | R35: =IF(O35="RON",O35,"") | S35: =IF(R35="RON",C35,"") | T35: =IF(R35="RON",B35,"") | U35: =IF(R35="RON",M35,"")
A36: 19 | B36: M-JGVJ | C36: =IF(B36>1,VLOOKUP(B36,DB!$D$4:$E$800,2,0),"") -> GLEX | D36: - | E36: FALSE | F36: 0.47569444 | G36: TRUE | H36: SA06 | I36: =IF(K36>1,VLOOKUP(K36,DB!$A$4:$B$500,2,0),"") -> EX RON | J36: B9 | K36: - | M36: KARISMA | O36: =IF(ISBLANK(F36),"RON","") | Q36: =IF(R36="RON",H36,"") | R36: =IF(O36="RON",O36,"") | S36: =IF(R36="RON",C36,"") | T36: =IF(R36="RON",B36,"") | U36: =IF(R36="RON",M36,"")
A37: 20 | B37: PK-LAM | C37: =IF(B37>1,VLOOKUP(B37,DB!$D$4:$E$800,2,0),"") -> A 320 | D37: - | E37: FALSE | F37: 0.4125 | G37: TRUE | H37: SA07 | I37: =IF(K37>1,VLOOKUP(K37,DB!$A$4:$B$500,2,0),"") -> EX RON | J37: A1 | K37: - | M37: =IF(B37>1,VLOOKUP(B37,DB!$D$4:$F$800,3,0),"") -> BATIK AIR | O37: =IF(ISBLANK(F37),"RON","") | Q37: =IF(R37="RON",H37,"") | R37: =IF(O37="RON",O37,"") | S37: =IF(R37="RON",C37,"") | T37: =IF(R37="RON",B37,"") | U37: =IF(R37="RON",M37,"")
A38: 21 | B38: PK-GJT | C38: =IF(B38>1,VLOOKUP(B38,DB!$D$4:$E$800,2,0),"") -> ATR 72 | D38: - | E38: FALSE | G38: FALSE | H38: SA08 | I38: =IF(K38>1,VLOOKUP(K38,DB!$A$4:$B$500,2,0),"") | J38: =IF(L38>1,VLOOKUP(L38,DB!$A$4:$B$500,2,0),"") | M38: =IF(B38>1,VLOOKUP(B38,DB!$D$4:$F$800,3,0),"") -> CITILINK | O38: =IF(ISBLANK(F38),"RON","") -> RON | Q38: =IF(R38="RON",H38,"") -> SA08 | R38: =IF(O38="RON",O38,"") -> RON | S38: =IF(R38="RON",C38,"") -> ATR 72 | T38: =IF(R38="RON",B38,"") -> PK-GJT | U38: =IF(R38="RON",M38,"") -> CITILINK
A39: 22 | B39: PK-BON | C39: =IF(B39>1,VLOOKUP(B39,DB!$D$4:$E$800,2,0),"") -> G IV | D39: - | E39: FALSE | F39: 0.29583333 | G39: TRUE | H39: SA09 | I39: =IF(K39>1,VLOOKUP(K39,DB!$A$4:$B$500,2,0),"") -> EX RON | J39: B5 | K39: - | M39: =IF(B39>1,VLOOKUP(B39,DB!$D$4:$F$800,3,0),"") -> JETSET | O39: =IF(ISBLANK(F39),"RON","") | Q39: =IF(R39="RON",H39,"") | R39: =IF(O39="RON",O39,"") | S39: =IF(R39="RON",C39,"") | T39: =IF(R39="RON",B39,"") | U39: =IF(R39="RON",M39,"")
A40: 23 | B40: VP-CGO | C40: =IF(B40>1,VLOOKUP(B40,DB!$D$4:$E$800,2,0),"") -> GLEX | D40: - | E40: FALSE | G40: FALSE | H40: SA10 | I40: =IF(K40>1,VLOOKUP(K40,DB!$A$4:$B$500,2,0),"") | J40: =IF(L40>1,VLOOKUP(L40,DB!$A$4:$B$500,2,0),"") | M40: AFM | O40: =IF(ISBLANK(F40),"RON","") -> RON | Q40: =IF(R40="RON",H40,"") -> SA10 | R40: =IF(O40="RON",O40,"") -> RON | S40: =IF(R40="RON",C40,"") -> GLEX | T40: =IF(R40="RON",B40,"") -> VP-CGO | U40: =IF(R40="RON",M40,"") -> AFM
A41: 24 | B41: T7-GBS | C41: =IF(B41>1,VLOOKUP(B41,DB!$D$4:$E$800,2,0),"") -> EMB 135 | D41: - | E41: FALSE | G41: FALSE | H41: SA11 | I41: =IF(K41>1,VLOOKUP(K41,DB!$A$4:$B$500,2,0),"") | J41: =IF(L41>1,VLOOKUP(L41,DB!$A$4:$B$500,2,0),"") | M41: KARISMA | O41: =IF(ISBLANK(F41),"RON","") -> RON | Q41: =IF(R41="RON",H41,"") -> SA11 | R41: =IF(O41="RON",O41,"") -> RON | S41: =IF(R41="RON",C41,"") -> EMB 135 | T41: =IF(R41="RON",B41,"") -> T7-GBS | U41: =IF(R41="RON",M41,"") -> KARISMA
A42: 25 | B42: PK-GRD | C42: =IF(B42>1,VLOOKUP(B42,DB!$D$4:$E$800,2,0),"") -> BBJ 2 | D42: - | E42: FALSE | F42: 0.48611111 | G42: TRUE | H42: SA12 | I42: =IF(K42>1,VLOOKUP(K42,DB!$A$4:$B$500,2,0),"") -> EX RON | J42: B7 | K42: - | M42: =IF(B42>1,VLOOKUP(B42,DB!$D$4:$F$800,3,0),"") -> PTN | O42: =IF(ISBLANK(F42),"RON","") | Q42: =IF(R42="RON",H42,"") | R42: =IF(O42="RON",O42,"") | S42: =IF(R42="RON",C42,"") | T42: =IF(R42="RON",B42,"") | U42: =IF(R42="RON",M42,"")
A43: 26 | B43: A-2117 | C43: =IF(B43>1,VLOOKUP(B43,DB!$D$4:$E$800,2,0),"") -> C 212 | D43: - | E43: FALSE | F43: 0.23611111 | G43: FALSE | H43: SA13 | I43: =IF(K43>1,VLOOKUP(K43,DB!$A$4:$B$500,2,0),"") -> EX RON | J43: LOCAL | K43: - | M43: =IF(B43>1,VLOOKUP(B43,DB!$D$4:$F$800,3,0),"") -> TNI AU | O43: =IF(ISBLANK(F43),"RON","") | Q43: =IF(R43="RON",H43,"") | R43: =IF(O43="RON",O43,"") | S43: =IF(R43="RON",C43,"") | T43: =IF(R43="RON",B43,"") | U43: =IF(R43="RON",M43,"")
A44: 27 | B44: A-2104 | C44: =IF(B44>1,VLOOKUP(B44,DB!$D$4:$E$800,2,0),"") -> C 212 | D44: - | E44: FALSE | F44: 0.30208333 | G44: FALSE | H44: SA14 | I44: =IF(K44>1,VLOOKUP(K44,DB!$A$4:$B$500,2,0),"") -> EX RON | J44: LOCAL | K44: - | M44: =IF(B44>1,VLOOKUP(B44,DB!$D$4:$F$800,3,0),"") -> TNI AU | O44: =IF(ISBLANK(F44),"RON","") | Q44: =IF(R44="RON",H44,"") | R44: =IF(O44="RON",O44,"") | S44: =IF(R44="RON",C44,"") | T44: =IF(R44="RON",B44,"") | U44: =IF(R44="RON",M44,"")
A45: 28 | B45: PK-RSS | C45: =IF(B45>1,VLOOKUP(B45,DB!$D$4:$E$800,2,0),"") -> EMB 135 | D45: - | E45: FALSE | G45: FALSE | H45: SA15 | I45: =IF(K45>1,VLOOKUP(K45,DB!$A$4:$B$500,2,0),"") | J45: =IF(L45>1,VLOOKUP(L45,DB!$A$4:$B$500,2,0),"") | M45: PTN | O45: =IF(ISBLANK(F45),"RON","") -> RON | Q45: =IF(R45="RON",H45,"") -> SA15 | R45: =IF(O45="RON",O45,"") -> RON | S45: =IF(R45="RON",C45,"") -> EMB 135 | T45: =IF(R45="RON",B45,"") -> PK-RSS | U45: =IF(R45="RON",M45,"") -> PTN
A46: 29 | B46: N-939AP | C46: =IF(B46>1,VLOOKUP(B46,DB!$D$4:$E$800,2,0),"") -> GLEX | D46: - | E46: FALSE | G46: FALSE | H46: RE01 | I46: =IF(K46>1,VLOOKUP(K46,DB!$A$4:$B$500,2,0),"") | J46: =IF(L46>1,VLOOKUP(L46,DB!$A$4:$B$500,2,0),"") | M46: =IF(B46>1,VLOOKUP(B46,DB!$D$4:$F$800,3,0),"") -> BIOMANTARA | O46: =IF(ISBLANK(F46),"RON","") -> RON | Q46: =IF(R46="RON",H46,"") -> RE01 | R46: =IF(O46="RON",O46,"") -> RON | S46: =IF(R46="RON",C46,"") -> GLEX | T46: =IF(R46="RON",B46,"") -> N-939AP | U46: =IF(R46="RON",M46,"") -> BIOMANTARA
...

Sheet 02
A1: APRON MOVEMENT SHEET HALIM PERDANAKUSUMA
A7: AERODROME : | C7: WIHH
A8: TANGGAL : | C8: 45840
A9: PETUGAS AMC | C9: PAGI SIANG ( 07:00 - 18:59) | E9: MALAM (19:00 - 06:59)
C10: RIZA IBNU FAJAR | E10: MALDIKA HASIBUAN
C11: RIDWAN WINANTO | E11: NUZAR AFRIAN
C12: PELTU UUM | E12: PELTU SUCIADI
C13: AHCMAD FAUZI
A15: NO | B15: REGISTRATION | C15: TYPE | D15: TIME OF | H15: PARKING STAND | I15: FROM | J15: TO | K15: FLIGHT NO | M15: OPERATOR / AIRLINES | N15: REMARKS | O15: STATUS
D16: ON BLOCK | F16: OFF BLOCK | K16: ARR | L16: DEP
Q17: 1 | R17: 2 | S17: 3 | T17: 4 | U17: 5
A18: 1 | B18: PK-VCD | C18: =IF(B18>1,VLOOKUP(B18,DB!$D$4:$E$800,2,0),"") -> PA 34 | D18: - | E18: FALSE | G18: FALSE | H18: NSA01 | I18: =IF(K18>1,VLOOKUP(K18,DB!$A$4:$B$500,2,0),"") | J18: =IF(L18>1,VLOOKUP(L18,DB!$A$4:$B$500,2,0),"") | M18: =IF(B18>1,VLOOKUP(B18,DB!$D$4:$F$800,3,0),"") -> PENAS | N18: UNSERVICEABLE | O18: =IF(ISBLANK(F18),"RON","") -> RON | Q18: =IF(R18="RON",H18,"") -> NSA01 | R18: =IF(O18="RON",O18,"") -> RON | S18: =IF(R18="RON",C18,"") -> PA 34 | T18: =IF(R18="RON",B18,"") -> PK-VCD | U18: =IF(R18="RON",M18,"") -> PENAS
A19: 2 | B19: PK-RSO | C19: =IF(B19>1,VLOOKUP(B19,DB!$D$4:$E$800,2,0),"") -> CT 650 | D19: - | E19: FALSE | G19: FALSE | H19: NSA02 | I19: =IF(K19>1,VLOOKUP(K19,DB!$A$4:$B$500,2,0),"") | J19: =IF(L19>1,VLOOKUP(L19,DB!$A$4:$B$500,2,0),"") | M19: =IF(B19>1,VLOOKUP(B19,DB!$D$4:$F$800,3,0),"") -> ENGGANG | N19: UNSERVICEABLE | O19: =IF(ISBLANK(F19),"RON","") -> RON | Q19: =IF(R19="RON",H19,"") -> NSA02 | R19: =IF(O19="RON",O19,"") -> RON | S19: =IF(R19="RON",C19,"") -> CT 650 | T19: =IF(R19="RON",B19,"") -> PK-RSO | U19: =IF(R19="RON",M19,"") -> ENGGANG
A20: 3 | B20: PK-RDA | C20: =IF(B20>1,VLOOKUP(B20,DB!$D$4:$E$800,2,0),"") -> HK 900 | D20: - | E20: FALSE | G20: FALSE | H20: NSA03 | I20: =IF(K20>1,VLOOKUP(K20,DB!$A$4:$B$500,2,0),"") | J20: =IF(L20>1,VLOOKUP(L20,DB!$A$4:$B$500,2,0),"") | M20: =IF(B20>1,VLOOKUP(B20,DB!$D$4:$F$800,3,0),"") -> TRI MG | N20: UNSERVICEABLE | O20: =IF(ISBLANK(F20),"RON","") -> RON | Q20: =IF(R20="RON",H20,"") -> NSA03 | R20: =IF(O20="RON",O20,"") -> RON | S20: =IF(R20="RON",C20,"") -> HK 900 | T20: =IF(R20="RON",B20,"") -> PK-RDA | U20: =IF(R20="RON",M20,"") -> TRI MG
A21: 4 | B21: PK-YGK | C21: =IF(B21>1,VLOOKUP(B21,DB!$D$4:$E$800,2,0),"") -> HK 400 | D21: - | E21: FALSE | G21: FALSE | H21: NSA04 | I21: =IF(K21>1,VLOOKUP(K21,DB!$A$4:$B$500,2,0),"") | J21: =IF(L21>1,VLOOKUP(L21,DB!$A$4:$B$500,2,0),"") | M21: =IF(B21>1,VLOOKUP(B21,DB!$D$4:$F$800,3,0),"") -> TRI MG | N21: UNSERVICEABLE | O21: =IF(ISBLANK(F21),"RON","") -> RON | Q21: =IF(R21="RON",H21,"") -> NSA04 | R21: =IF(O21="RON",O21,"") -> RON | S21: =IF(R21="RON",C21,"") -> HK 400 | T21: =IF(R21="RON",B21,"") -> PK-YGK | U21: =IF(R21="RON",M21,"") -> TRI MG
A22: 5 | B22: PK-YGR | C22: =IF(B22>1,VLOOKUP(B22,DB!$D$4:$E$800,2,0),"") -> HK 800 | D22: - | E22: FALSE | G22: FALSE | H22: NSA05 | I22: =IF(K22>1,VLOOKUP(K22,DB!$A$4:$B$500,2,0),"") | J22: =IF(L22>1,VLOOKUP(L22,DB!$A$4:$B$500,2,0),"") | M22: =IF(B22>1,VLOOKUP(B22,DB!$D$4:$F$800,3,0),"") -> TRI MG | N22: UNSERVICEABLE | O22: =IF(ISBLANK(F22),"RON","") -> RON | Q22: =IF(R22="RON",H22,"") -> NSA05 | R22: =IF(O22="RON",O22,"") -> RON | S22: =IF(R22="RON",C22,"") -> HK 800 | T22: =IF(R22="RON",B22,"") -> PK-YGR | U22: =IF(R22="RON",M22,"") -> TRI MG
A23: 6 | B23: N-484BA | C23: =IF(B23>1,VLOOKUP(B23,DB!$D$4:$E$800,2,0),"") -> LJ 31 | D23: - | E23: FALSE | G23: FALSE | H23: NSA06 | I23: =IF(K23>1,VLOOKUP(K23,DB!$A$4:$B$500,2,0),"") | J23: =IF(L23>1,VLOOKUP(L23,DB!$A$4:$B$500,2,0),"") | M23: =IF(B23>1,VLOOKUP(B23,DB!$D$4:$F$800,3,0),"") -> IAP | N23: UNSERVICEABLE | O23: =IF(ISBLANK(F23),"RON","") -> RON | Q23: =IF(R23="RON",H23,"") -> NSA06 | R23: =IF(O23="RON",O23,"") -> RON | S23: =IF(R23="RON",C23,"") -> LJ 31 | T23: =IF(R23="RON",B23,"") -> N-484BA | U23: =IF(R23="RON",M23,"") -> IAP
A24: 7 | B24: A-2701 | C24: =IF(B24>1,VLOOKUP(B24,DB!$D$4:$E$800,2,0),"") -> FOKKER 27 | D24: - | E24: FALSE | G24: FALSE | H24: NSA07 | I24: =IF(K24>1,VLOOKUP(K24,DB!$A$4:$B$500,2,0),"") | J24: =IF(L24>1,VLOOKUP(L24,DB!$A$4:$B$500,2,0),"") | M24: =IF(B24>1,VLOOKUP(B24,DB!$D$4:$F$800,3,0),"") -> TNI AU | N24: UNSERVICEABLE | O24: =IF(ISBLANK(F24),"RON","") -> RON | Q24: =IF(R24="RON",H24,"") -> NSA07 | R24: =IF(O24="RON",O24,"") -> RON | S24: =IF(R24="RON",C24,"") -> FOKKER 27 | T24: =IF(R24="RON",B24,"") -> A-2701 | U24: =IF(R24="RON",M24,"") -> TNI AU
A25: 8 | B25: A-2706 | C25: =IF(B25>1,VLOOKUP(B25,DB!$D$4:$E$800,2,0),"") -> FOKKER 27 | D25: - | E25: FALSE | G25: FALSE | H25: NSA08 | I25: =IF(K25>1,VLOOKUP(K25,DB!$A$4:$B$500,2,0),"") | J25: =IF(L25>1,VLOOKUP(L25,DB!$A$4:$B$500,2,0),"") | M25: =IF(B25>1,VLOOKUP(B25,DB!$D$4:$F$800,3,0),"") -> TNI AU | N25: UNSERVICEABLE | O25: =IF(ISBLANK(F25),"RON","") -> RON | Q25: =IF(R25="RON",H25,"") -> NSA08 | R25: =IF(O25="RON",O25,"") -> RON | S25: =IF(R25="RON",C25,"") -> FOKKER 27 | T25: =IF(R25="RON",B25,"") -> A-2706 | U25: =IF(R25="RON",M25,"") -> TNI AU
A26: 9 | B26: A-2801 | C26: =IF(B26>1,VLOOKUP(B26,DB!$D$4:$E$800,2,0),"") -> FOKKER 28 | D26: - | E26: FALSE | G26: FALSE | H26: NSA09 | I26: =IF(K26>1,VLOOKUP(K26,DB!$A$4:$B$500,2,0),"") | J26: =IF(L26>1,VLOOKUP(L26,DB!$A$4:$B$500,2,0),"") | M26: =IF(B26>1,VLOOKUP(B26,DB!$D$4:$F$800,3,0),"") -> TNI AU | N26: UNSERVICEABLE | O26: =IF(ISBLANK(F26),"RON","") -> RON | Q26: =IF(R26="RON",H26,"") -> NSA09 | R26: =IF(O26="RON",O26,"") -> RON | S26: =IF(R26="RON",C26,"") -> FOKKER 28 | T26: =IF(R26="RON",B26,"") -> A-2801 | U26: =IF(R26="RON",M26,"") -> TNI AU
A27: 10 | B27: N-2409K | C27: =IF(B27>1,VLOOKUP(B27,DB!$D$4:$E$800,2,0),"") -> HK 800 | D27: - | E27: FALSE | G27: FALSE | H27: NSA10 | I27: =IF(K27>1,VLOOKUP(K27,DB!$A$4:$B$500,2,0),"") | J27: =IF(L27>1,VLOOKUP(L27,DB!$A$4:$B$500,2,0),"") | M27: AFM | O27: =IF(ISBLANK(F27),"RON","") -> RON | Q27: =IF(R27="RON",H27,"") -> NSA10 | R27: =IF(O27="RON",O27,"") -> RON | S27: =IF(R27="RON",C27,"") -> HK 800 | T27: =IF(R27="RON",B27,"") -> N-2409K | U27: =IF(R27="RON",M27,"") -> AFM
A28: 11 | B28: T7-HNC | C28: =IF(B28>1,VLOOKUP(B28,DB!$D$4:$E$800,2,0),"") -> KING AIR | D28: - | E28: FALSE | G28: FALSE | H28: NSA11 | I28: =IF(K28>1,VLOOKUP(K28,DB!$A$4:$B$500,2,0),"") | J28: =IF(L28>1,VLOOKUP(L28,DB!$A$4:$B$500,2,0),"") | M28: AFM | O28: =IF(ISBLANK(F28),"RON","") -> RON | Q28: =IF(R28="RON",H28,"") -> NSA11 | R28: =IF(O28="RON",O28,"") -> RON | S28: =IF(R28="RON",C28,"") -> KING AIR | T28: =IF(R28="RON",B28,"") -> T7-HNC | U28: =IF(R28="RON",M28,"") -> AFM
A29: 12 | B29: T7-FCN | C29: =IF(B29>1,VLOOKUP(B29,DB!$D$4:$E$800,2,0),"") -> HK 800 | D29: - | E29: FALSE | G29: FALSE | H29: NSA12 | I29: =IF(K29>1,VLOOKUP(K29,DB!$A$4:$B$500,2,0),"") | J29: =IF(L29>1,VLOOKUP(L29,DB!$A$4:$B$500,2,0),"") | M29: KARISMA | O29: =IF(ISBLANK(F29),"RON","") -> RON | Q29: =IF(R29="RON",H29,"") -> NSA12 | R29: =IF(O29="RON",O29,"") -> RON | S29: =IF(R29="RON",C29,"") -> HK 800 | T29: =IF(R29="RON",B29,"") -> T7-FCN | U29: =IF(R29="RON",M29,"") -> KARISMA
A30: 13 | B30: N-977JH | C30: =IF(B30>1,VLOOKUP(B30,DB!$D$4:$E$800,2,0),"") -> CT 680 | D30: - | E30: FALSE | F30: 0.19236111 | G30: TRUE | H30: NSA13 | I30: =IF(K30>1,VLOOKUP(K30,DB!$A$4:$B$500,2,0),"") -> EX RON | J30: B4 | K30: - | M30: =IF(B30>1,VLOOKUP(B30,DB!$D$4:$F$800,3,0),"") -> JIP | O30: =IF(ISBLANK(F30),"RON","") | Q30: =IF(R30="RON",H30,"") | R30: =IF(O30="RON",O30,"") | S30: =IF(R30="RON",C30,"") | T30: =IF(R30="RON",B30,"") | U30: =IF(R30="RON",M30,"")
A31: 14 | B31: N-939AP | C31: =IF(B31>1,VLOOKUP(B31,DB!$D$4:$E$800,2,0),"") -> GLEX | D31: - | E31: FALSE | G31: FALSE | H31: RE01 | I31: =IF(K31>1,VLOOKUP(K31,DB!$A$4:$B$500,2,0),"") | J31: =IF(L31>1,VLOOKUP(L31,DB!$A$4:$B$500,2,0),"") | M31: =IF(B31>1,VLOOKUP(B31,DB!$D$4:$F$800,3,0),"") -> BIOMANTARA | O31: =IF(ISBLANK(F31),"RON","") -> RON | Q31: =IF(R31="RON",H31,"") -> RE01 | R31: =IF(O31="RON",O31,"") -> RON | S31: =IF(R31="RON",C31,"") -> GLEX | T31: =IF(R31="RON",B31,"") -> N-939AP | U31: =IF(R31="RON",M31,"") -> BIOMANTARA
A32: 15 | B32: T7-977 | C32: =IF(B32>1,VLOOKUP(B32,DB!$D$4:$E$800,2,0),"") -> G IV | D32: - | E32: FALSE | G32: FALSE | H32: RE03 | I32: =IF(K32>1,VLOOKUP(K32,DB!$A$4:$B$500,2,0),"") | J32: =IF(L32>1,VLOOKUP(L32,DB!$A$4:$B$500,2,0),"") | M32: =IF(B32>1,VLOOKUP(B32,DB!$D$4:$F$800,3,0),"") -> JIP | O32: =IF(ISBLANK(F32),"RON","") -> RON | Q32: =IF(R32="RON",H32,"") -> RE03 | R32: =IF(O32="RON",O32,"") -> RON | S32: =IF(R32="RON",C32,"") -> G IV | T32: =IF(R32="RON",B32,"") -> T7-977 | U32: =IF(R32="RON",M32,"") -> JIP
A33: 16 | B33: T7-HNA | C33: =IF(B33>1,VLOOKUP(B33,DB!$D$4:$E$800,2,0),"") -> G IV | D33: - | E33: FALSE | G33: FALSE | H33: RE04 | I33: =IF(K33>1,VLOOKUP(K33,DB!$A$4:$B$500,2,0),"") | J33: =IF(L33>1,VLOOKUP(L33,DB!$A$4:$B$500,2,0),"") | M33: AFM | O33: =IF(ISBLANK(F33),"RON","") -> RON | Q33: =IF(R33="RON",H33,"") -> RE04 | R33: =IF(O33="RON",O33,"") -> RON | S33: =IF(R33="RON",C33,"") -> G IV | T33: =IF(R33="RON",B33,"") -> T7-HNA | U33: =IF(R33="RON",M33,"") -> AFM
A34: 17 | B34: VP-CLL | C34: =IF(B34>1,VLOOKUP(B34,DB!$D$4:$E$800,2,0),"") -> EMB 135 | D34: - | E34: FALSE | G34: FALSE | H34: SA01 | I34: =IF(K34>1,VLOOKUP(K34,DB!$A$4:$B$500,2,0),"") | J34: =IF(L34>1,VLOOKUP(L34,DB!$A$4:$B$500,2,0),"") | M34: KARISMA | O34: =IF(ISBLANK(F34),"RON","") -> RON | Q34: =IF(R34="RON",H34,"") -> SA01 | R34: =IF(O34="RON",O34,"") -> RON | S34: =IF(R34="RON",C34,"") -> EMB 135 | T34: =IF(R34="RON",B34,"") -> VP-CLL | U34: =IF(R34="RON",M34,"") -> KARISMA
A35: 18 | B35: PK-RJH | C35: =IF(B35>1,VLOOKUP(B35,DB!$D$4:$E$800,2,0),"") -> EC 135 | D35: - | E35: FALSE | G35: FALSE | H35: SA02 | I35: =IF(K35>1,VLOOKUP(K35,DB!$A$4:$B$500,2,0),"") | J35: =IF(L35>1,VLOOKUP(L35,DB!$A$4:$B$500,2,0),"") | M35: =IF(B35>1,VLOOKUP(B35,DB!$D$4:$F$800,3,0),"") -> PREMI | O35: =IF(ISBLANK(F35),"RON","") -> RON | Q35: =IF(R35="RON",H35,"") -> SA02 | R35: =IF(O35="RON",O35,"") -> RON | S35: =IF(R35="RON",C35,"") -> EC 135 | T35: =IF(R35="RON",B35,"") -> PK-RJH | U35: =IF(R35="RON",M35,"") -> PREMI
A36: 19 | B36: PK-LUF | C36: =IF(B36>1,VLOOKUP(B36,DB!$D$4:$E$800,2,0),"") -> A 320 | D36: - | E36: FALSE | F36: 0.33125 | G36: TRUE | H36: SA03 | I36: =IF(K36>1,VLOOKUP(K36,DB!$A$4:$B$500,2,0),"") -> EX RON | J36: B7 | K36: - | M36: =IF(B36>1,VLOOKUP(B36,DB!$D$4:$F$800,3,0),"") -> BATIK AIR | O36: =IF(ISBLANK(F36),"RON","") | Q36: =IF(R36="RON",H36,"") | R36: =IF(O36="RON",O36,"") | S36: =IF(R36="RON",C36,"") | T36: =IF(R36="RON",B36,"") | U36: =IF(R36="RON",M36,"")
A37: 20 | B37: N-227GV | C37: =IF(B37>1,VLOOKUP(B37,DB!$D$4:$E$800,2,0),"") -> L 1000 | D37: - | E37: FALSE | G37: FALSE | H37: SA04 | I37: =IF(K37>1,VLOOKUP(K37,DB!$A$4:$B$500,2,0),"") | J37: =IF(L37>1,VLOOKUP(L37,DB!$A$4:$B$500,2,0),"") | M37: =IF(B37>1,VLOOKUP(B37,DB!$D$4:$F$800,3,0),"") -> PREMI | O37: =IF(ISBLANK(F37),"RON","") -> RON | Q37: =IF(R37="RON",H37,"") -> SA04 | R37: =IF(O37="RON",O37,"") -> RON | S37: =IF(R37="RON",C37,"") -> L 1000 | T37: =IF(R37="RON",B37,"") -> N-227GV | U37: =IF(R37="RON",M37,"") -> PREMI
A38: 21 | B38: T7-X14 | C38: =IF(B38>1,VLOOKUP(B38,DB!$D$4:$E$800,2,0),"") -> G VI | D38: - | E38: FALSE | G38: FALSE | H38: SA05 | I38: =IF(K38>1,VLOOKUP(K38,DB!$A$4:$B$500,2,0),"") | J38: =IF(L38>1,VLOOKUP(L38,DB!$A$4:$B$500,2,0),"") | M38: AFM | O38: =IF(ISBLANK(F38),"RON","") -> RON | Q38: =IF(R38="RON",H38,"") -> SA05 | R38: =IF(O38="RON",O38,"") -> RON | S38: =IF(R38="RON",C38,"") -> G VI | T38: =IF(R38="RON",B38,"") -> T7-X14 | U38: =IF(R38="RON",M38,"") -> AFM
A39: 22 | B39: PK-RJA | C39: =IF(B39>1,VLOOKUP(B39,DB!$D$4:$E$800,2,0),"") -> EMB 135 | D39: - | E39: FALSE | G39: FALSE | H39: SA06 | I39: =IF(K39>1,VLOOKUP(K39,DB!$A$4:$B$500,2,0),"") | J39: =IF(L39>1,VLOOKUP(L39,DB!$A$4:$B$500,2,0),"") | M39: =IF(B39>1,VLOOKUP(B39,DB!$D$4:$F$800,3,0),"") -> PREMI | O39: =IF(ISBLANK(F39),"RON","") -> RON | Q39: =IF(R39="RON",H39,"") -> SA06 | R39: =IF(O39="RON",O39,"") -> RON | S39: =IF(R39="RON",C39,"") -> EMB 135 | T39: =IF(R39="RON",B39,"") -> PK-RJA | U39: =IF(R39="RON",M39,"") -> PREMI
A40: 23 | B40: N-970NX | C40: =IF(B40>1,VLOOKUP(B40,DB!$D$4:$E$800,2,0),"") -> GLEX | D40: - | E40: FALSE | G40: FALSE | H40: SA07 | I40: =IF(K40>1,VLOOKUP(K40,DB!$A$4:$B$500,2,0),"") | J40: =IF(L40>1,VLOOKUP(L40,DB!$A$4:$B$500,2,0),"") | M40: =IF(B40>1,VLOOKUP(B40,DB!$D$4:$F$800,3,0),"") -> PREMI | O40: =IF(ISBLANK(F40),"RON","") -> RON | Q40: =IF(R40="RON",H40,"") -> SA07 | R40: =IF(O40="RON",O40,"") -> RON | S40: =IF(R40="RON",C40,"") -> GLEX | T40: =IF(R40="RON",B40,"") -> N-970NX | U40: =IF(R40="RON",M40,"") -> PREMI
A41: 24 | B41: PK-GJT | C41: =IF(B41>1,VLOOKUP(B41,DB!$D$4:$E$800,2,0),"") -> ATR 72 | D41: - | E41: FALSE | G41: FALSE | H41: SA08 | I41: =IF(K41>1,VLOOKUP(K41,DB!$A$4:$B$500,2,0),"") | J41: =IF(L41>1,VLOOKUP(L41,DB!$A$4:$B$500,2,0),"") | M41: =IF(B41>1,VLOOKUP(B41,DB!$D$4:$F$800,3,0),"") -> CITILINK | O41: =IF(ISBLANK(F41),"RON","") -> RON | Q41: =IF(R41="RON",H41,"") -> SA08 | R41: =IF(O41="RON",O41,"") -> RON | S41: =IF(R41="RON",C41,"") -> ATR 72 | T41: =IF(R41="RON",B41,"") -> PK-GJT | U41: =IF(R41="RON",M41,"") -> CITILINK
A42: 25 | B42: VP-CGO | C42: =IF(B42>1,VLOOKUP(B42,DB!$D$4:$E$800,2,0),"") -> GLEX | D42: - | E42: FALSE | G42: FALSE | H42: SA10 | I42: =IF(K42>1,VLOOKUP(K42,DB!$A$4:$B$500,2,0),"") | J42: =IF(L42>1,VLOOKUP(L42,DB!$A$4:$B$500,2,0),"") | M42: AFM | O42: =IF(ISBLANK(F42),"RON","") -> RON | Q42: =IF(R42="RON",H42,"") -> SA10 | R42: =IF(O42="RON",O42,"") -> RON | S42: =IF(R42="RON",C42,"") -> GLEX | T42: =IF(R42="RON",B42,"") -> VP-CGO | U42: =IF(R42="RON",M42,"") -> AFM
A43: 26 | B43: T7-GBS | C43: =IF(B43>1,VLOOKUP(B43,DB!$D$4:$E$800,2,0),"") -> EMB 135 | D43: - | E43: FALSE | G43: FALSE | H43: SA11 | I43: =IF(K43>1,VLOOKUP(K43,DB!$A$4:$B$500,2,0),"") | J43: =IF(L43>1,VLOOKUP(L43,DB!$A$4:$B$500,2,0),"") | M43: KARISMA | O43: =IF(ISBLANK(F43),"RON","") -> RON | Q43: =IF(R43="RON",H43,"") -> SA11 | R43: =IF(O43="RON",O43,"") -> RON | S43: =IF(R43="RON",C43,"") -> EMB 135 | T43: =IF(R43="RON",B43,"") -> T7-GBS | U43: =IF(R43="RON",M43,"") -> KARISMA
A44: 27 | B44: PK-FJA | C44: =IF(B44>1,VLOOKUP(B44,DB!$D$4:$E$800,2,0),"") -> ATR 72 | D44: - | E44: FALSE | F44: 0.31736111 | G44: TRUE | H44: SA12 | I44: =IF(K44>1,VLOOKUP(K44,DB!$A$4:$B$500,2,0),"") -> EX RON | J44: B2 | K44: - | M44: =IF(B44>1,VLOOKUP(B44,DB!$D$4:$F$800,3,0),"") -> FLY JAYA | O44: =IF(ISBLANK(F44),"RON","") | Q44: =IF(R44="RON",H44,"") | R44: =IF(O44="RON",O44,"") | S44: =IF(R44="RON",C44,"") | T44: =IF(R44="RON",B44,"") | U44: =IF(R44="RON",M44,"")
A45: 28 | B45: A-2104 | C45: =IF(B45>1,VLOOKUP(B45,DB!$D$4:$E$800,2,0),"") -> C 212 | D45: - | E45: FALSE | F45: 0.40625 | G45: FALSE | H45: SA13 | I45: =IF(K45>1,VLOOKUP(K45,DB!$A$4:$B$500,2,0),"") -> EX RON | J45: WARA | K45: - | M45: =IF(B45>1,VLOOKUP(B45,DB!$D$4:$F$800,3,0),"") -> TNI AU | O45: =IF(ISBLANK(F45),"RON","") | Q45: =IF(R45="RON",H45,"") | R45: =IF(O45="RON",O45,"") | S45: =IF(R45="RON",C45,"") | T45: =IF(R45="RON",B45,"") | U45: =IF(R45="RON",M45,"")
A46: 29 | B46: A-2117 | C46: =IF(B46>1,VLOOKUP(B46,DB!$D$4:$E$800,2,0),"") -> C 212 | D46: - | E46: FALSE | F46: 0.44444444 | G46: FALSE | H46: SA14 | I46: =IF(K46>1,VLOOKUP(K46,DB!$A$4:$B$500,2,0),"") -> EX RON | J46: WARA | K46: - | M46: =IF(B46>1,VLOOKUP(B46,DB!$D$4:$F$800,3,0),"") -> TNI AU | O46: =IF(ISBLANK(F46),"RON","") | Q46: =IF(R46="RON",H46,"") | R46: =IF(O46="RON",O46,"") | S46: =IF(R46="RON",C46,"") | T46: =IF(R46="RON",B46,"") | U46: =IF(R46="RON",M46,"")
...

Sheet 03
A1: APRON MOVEMENT SHEET HALIM PERDANAKUSUMA
A7: AERODROME : | C7: WIHH
A8: TANGGAL : | C8: 45841
A9: PETUGAS AMC | C9: PAGI SIANG ( 07:00 - 18:59) | E9: MALAM (19:00 - 06:59)
C10: NIKON | E10: RIZA IBNU FAJAR
C11: RYAN KHALIQ | E11: RIDWAN WINANTO
C12: SERDA JIM MIM | E12: PELTU UUM
C13: AHCMAD FAUZI
A15: NO | B15: REGISTRATION | C15: TYPE | D15: TIME OF | H15: PARKING STAND | I15: FROM | J15: TO | K15: FLIGHT NO | M15: OPERATOR / AIRLINES | N15: REMARKS | O15: STATUS
D16: ON BLOCK | F16: OFF BLOCK | K16: ARR | L16: DEP
Q17: 1 | R17: 2 | S17: 3 | T17: 4 | U17: 5
A18: 1 | B18: PK-VCD | C18: =IF(B18>1,VLOOKUP(B18,DB!$D$4:$E$800,2,0),"") -> PA 34 | D18: - | E18: FALSE | G18: FALSE | H18: NSA01 | I18: =IF(K18>1,VLOOKUP(K18,DB!$A$4:$B$500,2,0),"") | J18: =IF(L18>1,VLOOKUP(L18,DB!$A$4:$B$500,2,0),"") | M18: =IF(B18>1,VLOOKUP(B18,DB!$D$4:$F$800,3,0),"") -> PENAS | N18: UNSERVICEABLE | O18: =IF(ISBLANK(F18),"RON","") -> RON | Q18: =IF(R18="RON",H18,"") -> NSA01 | R18: =IF(O18="RON",O18,"") -> RON | S18: =IF(R18="RON",C18,"") -> PA 34 | T18: =IF(R18="RON",B18,"") -> PK-VCD | U18: =IF(R18="RON",M18,"") -> PENAS
A19: 2 | B19: PK-RSO | C19: =IF(B19>1,VLOOKUP(B19,DB!$D$4:$E$800,2,0),"") -> CT 650 | D19: - | E19: FALSE | G19: FALSE | H19: NSA02 | I19: =IF(K19>1,VLOOKUP(K19,DB!$A$4:$B$500,2,0),"") | J19: =IF(L19>1,VLOOKUP(L19,DB!$A$4:$B$500,2,0),"") | M19: =IF(B19>1,VLOOKUP(B19,DB!$D$4:$F$800,3,0),"") -> ENGGANG | N19: UNSERVICEABLE | O19: =IF(ISBLANK(F19),"RON","") -> RON | Q19: =IF(R19="RON",H19,"") -> NSA02 | R19: =IF(O19="RON",O19,"") -> RON | S19: =IF(R19="RON",C19,"") -> CT 650 | T19: =IF(R19="RON",B19,"") -> PK-RSO | U19: =IF(R19="RON",M19,"") -> ENGGANG
A20: 3 | B20: PK-RDA | C20: =IF(B20>1,VLOOKUP(B20,DB!$D$4:$E$800,2,0),"") -> HK 900 | D20: - | E20: FALSE | G20: FALSE | H20: NSA03 | I20: =IF(K20>1,VLOOKUP(K20,DB!$A$4:$B$500,2,0),"") | J20: =IF(L20>1,VLOOKUP(L20,DB!$A$4:$B$500,2,0),"") | M20: =IF(B20>1,VLOOKUP(B20,DB!$D$4:$F$800,3,0),"") -> TRI MG | N20: UNSERVICEABLE | O20: =IF(ISBLANK(F20),"RON","") -> RON | Q20: =IF(R20="RON",H20,"") -> NSA03 | R20: =IF(O20="RON",O20,"") -> RON | S20: =IF(R20="RON",C20,"") -> HK 900 | T20: =IF(R20="RON",B20,"") -> PK-RDA | U20: =IF(R20="RON",M20,"") -> TRI MG
A21: 4 | B21: PK-YGK | C21: =IF(B21>1,VLOOKUP(B21,DB!$D$4:$E$800,2,0),"") -> HK 400 | D21: - | E21: FALSE | G21: FALSE | H21: NSA04 | I21: =IF(K21>1,VLOOKUP(K21,DB!$A$4:$B$500,2,0),"") | J21: =IF(L21>1,VLOOKUP(L21,DB!$A$4:$B$500,2,0),"") | M21: =IF(B21>1,VLOOKUP(B21,DB!$D$4:$F$800,3,0),"") -> TRI MG | N21: UNSERVICEABLE | O21: =IF(ISBLANK(F21),"RON","") -> RON | Q21: =IF(R21="RON",H21,"") -> NSA04 | R21: =IF(O21="RON",O21,"") -> RON | S21: =IF(R21="RON",C21,"") -> HK 400 | T21: =IF(R21="RON",B21,"") -> PK-YGK | U21: =IF(R21="RON",M21,"") -> TRI MG
A22: 5 | B22: PK-YGR | C22: =IF(B22>1,VLOOKUP(B22,DB!$D$4:$E$800,2,0),"") -> HK 800 | D22: - | E22: FALSE | G22: FALSE | H22: NSA05 | I22: =IF(K22>1,VLOOKUP(K22,DB!$A$4:$B$500,2,0),"") | J22: =IF(L22>1,VLOOKUP(L22,DB!$A$4:$B$500,2,0),"") | M22: =IF(B22>1,VLOOKUP(B22,DB!$D$4:$F$800,3,0),"") -> TRI MG | N22: UNSERVICEABLE | O22: =IF(ISBLANK(F22),"RON","") -> RON | Q22: =IF(R22="RON",H22,"") -> NSA05 | R22: =IF(O22="RON",O22,"") -> RON | S22: =IF(R22="RON",C22,"") -> HK 800 | T22: =IF(R22="RON",B22,"") -> PK-YGR | U22: =IF(R22="RON",M22,"") -> TRI MG
A23: 6 | B23: N-484BA | C23: =IF(B23>1,VLOOKUP(B23,DB!$D$4:$E$800,2,0),"") -> LJ 31 | D23: - | E23: FALSE | G23: FALSE | H23: NSA06 | I23: =IF(K23>1,VLOOKUP(K23,DB!$A$4:$B$500,2,0),"") | J23: =IF(L23>1,VLOOKUP(L23,DB!$A$4:$B$500,2,0),"") | M23: =IF(B23>1,VLOOKUP(B23,DB!$D$4:$F$800,3,0),"") -> IAP | N23: UNSERVICEABLE | O23: =IF(ISBLANK(F23),"RON","") -> RON | Q23: =IF(R23="RON",H23,"") -> NSA06 | R23: =IF(O23="RON",O23,"") -> RON | S23: =IF(R23="RON",C23,"") -> LJ 31 | T23: =IF(R23="RON",B23,"") -> N-484BA | U23: =IF(R23="RON",M23,"") -> IAP
A24: 7 | B24: A-2701 | C24: =IF(B24>1,VLOOKUP(B24,DB!$D$4:$E$800,2,0),"") -> FOKKER 27 | D24: - | E24: FALSE | G24: FALSE | H24: NSA07 | I24: =IF(K24>1,VLOOKUP(K24,DB!$A$4:$B$500,2,0),"") | J24: =IF(L24>1,VLOOKUP(L24,DB!$A$4:$B$500,2,0),"") | M24: =IF(B24>1,VLOOKUP(B24,DB!$D$4:$F$800,3,0),"") -> TNI AU | N24: UNSERVICEABLE | O24: =IF(ISBLANK(F24),"RON","") -> RON | Q24: =IF(R24="RON",H24,"") -> NSA07 | R24: =IF(O24="RON",O24,"") -> RON | S24: =IF(R24="RON",C24,"") -> FOKKER 27 | T24: =IF(R24="RON",B24,"") -> A-2701 | U24: =IF(R24="RON",M24,"") -> TNI AU
A25: 8 | B25: A-2706 | C25: =IF(B25>1,VLOOKUP(B25,DB!$D$4:$E$800,2,0),"") -> FOKKER 27 | D25: - | E25: FALSE | G25: FALSE | H25: NSA08 | I25: =IF(K25>1,VLOOKUP(K25,DB!$A$4:$B$500,2,0),"") | J25: =IF(L25>1,VLOOKUP(L25,DB!$A$4:$B$500,2,0),"") | M25: =IF(B25>1,VLOOKUP(B25,DB!$D$4:$F$800,3,0),"") -> TNI AU | N25: UNSERVICEABLE | O25: =IF(ISBLANK(F25),"RON","") -> RON | Q25: =IF(R25="RON",H25,"") -> NSA08 | R25: =IF(O25="RON",O25,"") -> RON | S25: =IF(R25="RON",C25,"") -> FOKKER 27 | T25: =IF(R25="RON",B25,"") -> A-2706 | U25: =IF(R25="RON",M25,"") -> TNI AU
A26: 9 | B26: A-2801 | C26: =IF(B26>1,VLOOKUP(B26,DB!$D$4:$E$800,2,0),"") -> FOKKER 28 | D26: - | E26: FALSE | G26: FALSE | H26: NSA09 | I26: =IF(K26>1,VLOOKUP(K26,DB!$A$4:$B$500,2,0),"") | J26: =IF(L26>1,VLOOKUP(L26,DB!$A$4:$B$500,2,0),"") | M26: =IF(B26>1,VLOOKUP(B26,DB!$D$4:$F$800,3,0),"") -> TNI AU | N26: UNSERVICEABLE | O26: =IF(ISBLANK(F26),"RON","") -> RON | Q26: =IF(R26="RON",H26,"") -> NSA09 | R26: =IF(O26="RON",O26,"") -> RON | S26: =IF(R26="RON",C26,"") -> FOKKER 28 | T26: =IF(R26="RON",B26,"") -> A-2801 | U26: =IF(R26="RON",M26,"") -> TNI AU
A27: 10 | B27: N-2409K | C27: =IF(B27>1,VLOOKUP(B27,DB!$D$4:$E$800,2,0),"") -> HK 800 | D27: - | E27: FALSE | G27: FALSE | H27: NSA10 | I27: =IF(K27>1,VLOOKUP(K27,DB!$A$4:$B$500,2,0),"") | J27: =IF(L27>1,VLOOKUP(L27,DB!$A$4:$B$500,2,0),"") | M27: AFM | O27: =IF(ISBLANK(F27),"RON","") -> RON | Q27: =IF(R27="RON",H27,"") -> NSA10 | R27: =IF(O27="RON",O27,"") -> RON | S27: =IF(R27="RON",C27,"") -> HK 800 | T27: =IF(R27="RON",B27,"") -> N-2409K | U27: =IF(R27="RON",M27,"") -> AFM
A28: 11 | B28: T7-HNC | C28: =IF(B28>1,VLOOKUP(B28,DB!$D$4:$E$800,2,0),"") -> KING AIR | D28: - | E28: FALSE | G28: FALSE | H28: NSA11 | I28: =IF(K28>1,VLOOKUP(K28,DB!$A$4:$B$500,2,0),"") | J28: =IF(L28>1,VLOOKUP(L28,DB!$A$4:$B$500,2,0),"") | M28: AFM | O28: =IF(ISBLANK(F28),"RON","") -> RON | Q28: =IF(R28="RON",H28,"") -> NSA11 | R28: =IF(O28="RON",O28,"") -> RON | S28: =IF(R28="RON",C28,"") -> KING AIR | T28: =IF(R28="RON",B28,"") -> T7-HNC | U28: =IF(R28="RON",M28,"") -> AFM
A29: 12 | B29: T7-FCN | C29: =IF(B29>1,VLOOKUP(B29,DB!$D$4:$E$800,2,0),"") -> HK 800 | D29: - | E29: FALSE | G29: FALSE | H29: NSA12 | I29: =IF(K29>1,VLOOKUP(K29,DB!$A$4:$B$500,2,0),"") | J29: =IF(L29>1,VLOOKUP(L29,DB!$A$4:$B$500,2,0),"") | M29: KARISMA | O29: =IF(ISBLANK(F29),"RON","") -> RON | Q29: =IF(R29="RON",H29,"") -> NSA12 | R29: =IF(O29="RON",O29,"") -> RON | S29: =IF(R29="RON",C29,"") -> HK 800 | T29: =IF(R29="RON",B29,"") -> T7-FCN | U29: =IF(R29="RON",M29,"") -> KARISMA
A30: 13 | B30: VP-CLL | C30: =IF(B30>1,VLOOKUP(B30,DB!$D$4:$E$800,2,0),"") -> EMB 135 | D30: - | E30: FALSE | F30: 0.54861111 | G30: TRUE | H30: SA01 | I30: =IF(K30>1,VLOOKUP(K30,DB!$A$4:$B$500,2,0),"") -> EX RON | J30: B4 | K30: - | M30: KARISMA | O30: =IF(ISBLANK(F30),"RON","") | Q30: =IF(R30="RON",H30,"") | R30: =IF(O30="RON",O30,"") | S30: =IF(R30="RON",C30,"") | T30: =IF(R30="RON",B30,"") | U30: =IF(R30="RON",M30,"")
A31: 14 | B31: PK-RJH | C31: =IF(B31>1,VLOOKUP(B31,DB!$D$4:$E$800,2,0),"") -> EC 135 | D31: - | E31: FALSE | G31: FALSE | H31: SA02 | I31: =IF(K31>1,VLOOKUP(K31,DB!$A$4:$B$500,2,0),"") | J31: =IF(L31>1,VLOOKUP(L31,DB!$A$4:$B$500,2,0),"") | M31: =IF(B31>1,VLOOKUP(B31,DB!$D$4:$F$800,3,0),"") -> PREMI | O31: =IF(ISBLANK(F31),"RON","") -> RON | Q31: =IF(R31="RON",H31,"") -> SA02 | R31: =IF(O31="RON",O31,"") -> RON | S31: =IF(R31="RON",C31,"") -> EC 135 | T31: =IF(R31="RON",B31,"") -> PK-RJH | U31: =IF(R31="RON",M31,"") -> PREMI
A32: 15 | B32: PK-LUR | C32: =IF(B32>1,VLOOKUP(B32,DB!$D$4:$E$800,2,0),"") -> A 320 | D32: - | E32: FALSE | G32: FALSE | H32: SA03 | I32: =IF(K32>1,VLOOKUP(K32,DB!$A$4:$B$500,2,0),"") | J32: =IF(L32>1,VLOOKUP(L32,DB!$A$4:$B$500,2,0),"") | M32: =IF(B32>1,VLOOKUP(B32,DB!$D$4:$F$800,3,0),"") -> BATIK AIR | O32: =IF(ISBLANK(F32),"RON","") -> RON | Q32: =IF(R32="RON",H32,"") -> SA03 | R32: =IF(O32="RON",O32,"") -> RON | S32: =IF(R32="RON",C32,"") -> A 320 | T32: =IF(R32="RON",B32,"") -> PK-LUR | U32: =IF(R32="RON",M32,"") -> BATIK AIR
A33: 16 | B33: N-227GV | C33: =IF(B33>1,VLOOKUP(B33,DB!$D$4:$E$800,2,0),"") -> L 1000 | D33: - | E33: FALSE | F33: 0.36180556 | G33: TRUE | H33: SA04 | I33: =IF(K33>1,VLOOKUP(K33,DB!$A$4:$B$500,2,0),"") -> EX RON | J33: B3 | K33: - | M33: =IF(B33>1,VLOOKUP(B33,DB!$D$4:$F$800,3,0),"") -> PREMI | O33: =IF(ISBLANK(F33),"RON","") | Q33: =IF(R33="RON",H33,"") | R33: =IF(O33="RON",O33,"") | S33: =IF(R33="RON",C33,"") | T33: =IF(R33="RON",B33,"") | U33: =IF(R33="RON",M33,"")
A34: 17 | B34: T7-X14 | C34: =IF(B34>1,VLOOKUP(B34,DB!$D$4:$E$800,2,0),"") -> G VI | D34: - | E34: FALSE | G34: FALSE | H34: SA05 | I34: =IF(K34>1,VLOOKUP(K34,DB!$A$4:$B$500,2,0),"") | J34: =IF(L34>1,VLOOKUP(L34,DB!$A$4:$B$500,2,0),"") | M34: AFM | O34: =IF(ISBLANK(F34),"RON","") -> RON | Q34: =IF(R34="RON",H34,"") -> SA05 | R34: =IF(O34="RON",O34,"") -> RON | S34: =IF(R34="RON",C34,"") -> G VI | T34: =IF(R34="RON",B34,"") -> T7-X14 | U34: =IF(R34="RON",M34,"") -> AFM
A35: 18 | B35: PK-RJA | C35: =IF(B35>1,VLOOKUP(B35,DB!$D$4:$E$800,2,0),"") -> EMB 135 | D35: - | E35: FALSE | F35: 0.66666667 | G35: TRUE | H35: SA06 | I35: =IF(K35>1,VLOOKUP(K35,DB!$A$4:$B$500,2,0),"") -> EX RON | J35: HGR | K35: - | M35: =IF(B35>1,VLOOKUP(B35,DB!$D$4:$F$800,3,0),"") -> PREMI | O35: =IF(ISBLANK(F35),"RON","") | Q35: =IF(R35="RON",H35,"") | R35: =IF(O35="RON",O35,"") | S35: =IF(R35="RON",C35,"") | T35: =IF(R35="RON",B35,"") | U35: =IF(R35="RON",M35,"")
A36: 19 | B36: N-970NX | C36: =IF(B36>1,VLOOKUP(B36,DB!$D$4:$E$800,2,0),"") -> GLEX | D36: - | E36: FALSE | F36: 0.64027778 | G36: TRUE | H36: SA07 | I36: =IF(K36>1,VLOOKUP(K36,DB!$A$4:$B$500,2,0),"") -> EX RON | J36: HGR | K36: - | M36: =IF(B36>1,VLOOKUP(B36,DB!$D$4:$F$800,3,0),"") -> PREMI | O36: =IF(ISBLANK(F36),"RON","") | Q36: =IF(R36="RON",H36,"") | R36: =IF(O36="RON",O36,"") | S36: =IF(R36="RON",C36,"") | T36: =IF(R36="RON",B36,"") | U36: =IF(R36="RON",M36,"")
A37: 20 | B37: PK-GJT | C37: =IF(B37>1,VLOOKUP(B37,DB!$D$4:$E$800,2,0),"") -> ATR 72 | D37: - | E37: FALSE | G37: FALSE | H37: SA08 | I37: =IF(K37>1,VLOOKUP(K37,DB!$A$4:$B$500,2,0),"") | J37: =IF(L37>1,VLOOKUP(L37,DB!$A$4:$B$500,2,0),"") | M37: =IF(B37>1,VLOOKUP(B37,DB!$D$4:$F$800,3,0),"") -> CITILINK | O37: =IF(ISBLANK(F37),"RON","") -> RON | Q37: =IF(R37="RON",H37,"") -> SA08 | R37: =IF(O37="RON",O37,"") -> RON | S37: =IF(R37="RON",C37,"") -> ATR 72 | T37: =IF(R37="RON",B37,"") -> PK-GJT | U37: =IF(R37="RON",M37,"") -> CITILINK
A38: 21 | B38: T7-777 | C38: =IF(B38>1,VLOOKUP(B38,DB!$D$4:$E$800,2,0),"") -> BBJ | D38: - | E38: FALSE | F38: 0.20833333 | G38: TRUE | H38: SA09 | I38: =IF(K38>1,VLOOKUP(K38,DB!$A$4:$B$500,2,0),"") -> EX RON | J38: B4 | K38: - | M38: =IF(B38>1,VLOOKUP(B38,DB!$D$4:$F$800,3,0),"") -> JIP | O38: =IF(ISBLANK(F38),"RON","") | Q38: =IF(R38="RON",H38,"") | R38: =IF(O38="RON",O38,"") | S38: =IF(R38="RON",C38,"") | T38: =IF(R38="RON",B38,"") | U38: =IF(R38="RON",M38,"")
A39: 22 | B39: VP-CGO | C39: =IF(B39>1,VLOOKUP(B39,DB!$D$4:$E$800,2,0),"") -> GLEX | D39: - | E39: FALSE | G39: FALSE | H39: SA10 | I39: =IF(K39>1,VLOOKUP(K39,DB!$A$4:$B$500,2,0),"") | J39: =IF(L39>1,VLOOKUP(L39,DB!$A$4:$B$500,2,0),"") | M39: AFM | O39: =IF(ISBLANK(F39),"RON","") -> RON | Q39: =IF(R39="RON",H39,"") -> SA10 | R39: =IF(O39="RON",O39,"") -> RON | S39: =IF(R39="RON",C39,"") -> GLEX | T39: =IF(R39="RON",B39,"") -> VP-CGO | U39: =IF(R39="RON",M39,"") -> AFM
A40: 23 | B40: T7-GBS | C40: =IF(B40>1,VLOOKUP(B40,DB!$D$4:$E$800,2,0),"") -> EMB 135 | D40: - | E40: FALSE | G40: FALSE | H40: SA11 | I40: =IF(K40>1,VLOOKUP(K40,DB!$A$4:$B$500,2,0),"") | J40: =IF(L40>1,VLOOKUP(L40,DB!$A$4:$B$500,2,0),"") | M40: KARISMA | O40: =IF(ISBLANK(F40),"RON","") -> RON | Q40: =IF(R40="RON",H40,"") -> SA11 | R40: =IF(O40="RON",O40,"") -> RON | S40: =IF(R40="RON",C40,"") -> EMB 135 | T40: =IF(R40="RON",B40,"") -> T7-GBS | U40: =IF(R40="RON",M40,"") -> KARISMA
A41: 24 | B41: PK-FJA | C41: =IF(B41>1,VLOOKUP(B41,DB!$D$4:$E$800,2,0),"") -> ATR 72 | D41: - | E41: FALSE | F41: 0.23472222 | G41: TRUE | H41: SA12 | I41: =IF(K41>1,VLOOKUP(K41,DB!$A$4:$B$500,2,0),"") -> EX RON | J41: A2 | K41: - | M41: =IF(B41>1,VLOOKUP(B41,DB!$D$4:$F$800,3,0),"") -> FLY JAYA | O41: =IF(ISBLANK(F41),"RON","") | Q41: =IF(R41="RON",H41,"") | R41: =IF(O41="RON",O41,"") | S41: =IF(R41="RON",C41,"") | T41: =IF(R41="RON",B41,"") | U41: =IF(R41="RON",M41,"")
A42: 25 | B42: PK-LUS | C42: =IF(B42>1,VLOOKUP(B42,DB!$D$4:$E$800,2,0),"") -> A 320 | D42: - | E42: FALSE | F42: 0.43541667 | G42: TRUE | H42: SA13 | I42: =IF(K42>1,VLOOKUP(K42,DB!$A$4:$B$500,2,0),"") -> EX RON | J42: B8 | K42: - | M42: =IF(B42>1,VLOOKUP(B42,DB!$D$4:$F$800,3,0),"") -> BATIK AIR | O42: =IF(ISBLANK(F42),"RON","") | Q42: =IF(R42="RON",H42,"") | R42: =IF(O42="RON",O42,"") | S42: =IF(R42="RON",C42,"") | T42: =IF(R42="RON",B42,"") | U42: =IF(R42="RON",M42,"")
A43: 26 | B43: PK-RSS | C43: =IF(B43>1,VLOOKUP(B43,DB!$D$4:$E$800,2,0),"") -> EMB 135 | D43: - | E43: FALSE | F43: 0.37708333 | G43: TRUE | H43: SA15 | I43: =IF(K43>1,VLOOKUP(K43,DB!$A$4:$B$500,2,0),"") -> EX RON | J43: B5 | K43: - | M43: PTN | O43: =IF(ISBLANK(F43),"RON","") | Q43: =IF(R43="RON",H43,"") | R43: =IF(O43="RON",O43,"") | S43: =IF(R43="RON",C43,"") | T43: =IF(R43="RON",B43,"") | U43: =IF(R43="RON",M43,"")
A44: 27 | B44: PK-OTR | C44: =IF(B44>1,VLOOKUP(B44,DB!$D$4:$E$800,2,0),"") -> ATR 72 | D44: - | E44: FALSE | G44: FALSE | H44: SA12 | I44: =IF(K44>1,VLOOKUP(K44,DB!$A$4:$B$500,2,0),"") | J44: =IF(L44>1,VLOOKUP(L44,DB!$A$4:$B$500,2,0),"") | M44: =IF(B44>1,VLOOKUP(B44,DB!$D$4:$F$800,3,0),"") -> TAS | O44: =IF(ISBLANK(F44),"RON","") -> RON | Q44: =IF(R44="RON",H44,"") -> SA12 | R44: =IF(O44="RON",O44,"") -> RON | S44: =IF(R44="RON",C44,"") -> ATR 72 | T44: =IF(R44="RON",B44,"") -> PK-OTR | U44: =IF(R44="RON",M44,"") -> TAS
A45: 28 | B45: N-939AP | C45: =IF(B45>1,VLOOKUP(B45,DB!$D$4:$E$800,2,0),"") -> GLEX | D45: - | E45: FALSE | G45: FALSE | H45: RE01 | I45: =IF(K45>1,VLOOKUP(K45,DB!$A$4:$B$500,2,0),"") | J45: =IF(L45>1,VLOOKUP(L45,DB!$A$4:$B$500,2,0),"") | M45: =IF(B45>1,VLOOKUP(B45,DB!$D$4:$F$800,3,0),"") -> BIOMANTARA | O45: =IF(ISBLANK(F45),"RON","") -> RON | Q45: =IF(R45="RON",H45,"") -> RE01 | R45: =IF(O45="RON",O45,"") -> RON | S45: =IF(R45="RON",C45,"") -> GLEX | T45: =IF(R45="RON",B45,"") -> N-939AP | U45: =IF(R45="RON",M45,"") -> BIOMANTARA
A46: 29 | B46: PK-KAS | C46: =IF(B46>1,VLOOKUP(B46,DB!$D$4:$E$800,2,0),"") -> CL 850 | D46: - | E46: FALSE | F46: 0.25694444 | G46: TRUE | H46: RE02 | I46: =IF(K46>1,VLOOKUP(K46,DB!$A$4:$B$500,2,0),"") -> EX RON | J46: B2 | K46: - | M46: =IF(B46>1,VLOOKUP(B46,DB!$D$4:$F$800,3,0),"") -> JETSET | O46: =IF(ISBLANK(F46),"RON","") | Q46: =IF(R46="RON",H46,"") | R46: =IF(O46="RON",O46,"") | S46: =IF(R46="RON",C46,"") | T46: =IF(R46="RON",B46,"") | U46: =IF(R46="RON",M46,"")
...

Sheet 04
A1: APRON MOVEMENT SHEET HALIM PERDANAKUSUMA
A7: AERODROME : | C7: WIHH
A8: TANGGAL : | C8: 45842
A9: PETUGAS AMC | C9: PAGI SIANG ( 07:00 - 18:59) | E9: MALAM (19:00 - 06:59)
C10: MALDIKA HASIBUAN | E10: NIKON
C11: NUZAR AFRIAN | E11: RYAN KHALIQ
C12: PELTU SUCIADI | E12: SERDA JIM MIM
C13: AHCMAD FAUZI
A15: NO | B15: REGISTRATION | C15: TYPE | D15: TIME OF | H15: PARKING STAND | I15: FROM | J15: TO | K15: FLIGHT NO | M15: OPERATOR / AIRLINES | N15: REMARKS | O15: STATUS
D16: ON BLOCK | F16: OFF BLOCK | K16: ARR | L16: DEP
Q17: 1 | R17: 2 | S17: 3 | T17: 4 | U17: 5
A18: 1 | B18: PK-VCD | C18: =IF(B18>1,VLOOKUP(B18,DB!$D$4:$E$800,2,0),"") -> PA 34 | D18: - | E18: FALSE | G18: FALSE | H18: NSA01 | I18: =IF(K18>1,VLOOKUP(K18,DB!$A$4:$B$500,2,0),"") | J18: =IF(L18>1,VLOOKUP(L18,DB!$A$4:$B$500,2,0),"") | M18: =IF(B18>1,VLOOKUP(B18,DB!$D$4:$F$800,3,0),"") -> PENAS | N18: UNSERVICEABLE | O18: =IF(ISBLANK(F18),"RON","") -> RON | Q18: =IF(R18="RON",H18,"") -> NSA01 | R18: =IF(O18="RON",O18,"") -> RON | S18: =IF(R18="RON",C18,"") -> PA 34 | T18: =IF(R18="RON",B18,"") -> PK-VCD | U18: =IF(R18="RON",M18,"") -> PENAS
A19: 2 | B19: PK-RSO | C19: =IF(B19>1,VLOOKUP(B19,DB!$D$4:$E$800,2,0),"") -> CT 650 | D19: - | E19: FALSE | G19: FALSE | H19: NSA02 | I19: =IF(K19>1,VLOOKUP(K19,DB!$A$4:$B$500,2,0),"") | J19: =IF(L19>1,VLOOKUP(L19,DB!$A$4:$B$500,2,0),"") | M19: =IF(B19>1,VLOOKUP(B19,DB!$D$4:$F$800,3,0),"") -> ENGGANG | N19: UNSERVICEABLE | O19: =IF(ISBLANK(F19),"RON","") -> RON | Q19: =IF(R19="RON",H19,"") -> NSA02 | R19: =IF(O19="RON",O19,"") -> RON | S19: =IF(R19="RON",C19,"") -> CT 650 | T19: =IF(R19="RON",B19,"") -> PK-RSO | U19: =IF(R19="RON",M19,"") -> ENGGANG
A20: 3 | B20: PK-RDA | C20: =IF(B20>1,VLOOKUP(B20,DB!$D$4:$E$800,2,0),"") -> HK 900 | D20: - | E20: FALSE | G20: FALSE | H20: NSA03 | I20: =IF(K20>1,VLOOKUP(K20,DB!$A$4:$B$500,2,0),"") | J20: =IF(L20>1,VLOOKUP(L20,DB!$A$4:$B$500,2,0),"") | M20: =IF(B20>1,VLOOKUP(B20,DB!$D$4:$F$800,3,0),"") -> TRI MG | N20: UNSERVICEABLE | O20: =IF(ISBLANK(F20),"RON","") -> RON | Q20: =IF(R20="RON",H20,"") -> NSA03 | R20: =IF(O20="RON",O20,"") -> RON | S20: =IF(R20="RON",C20,"") -> HK 900 | T20: =IF(R20="RON",B20,"") -> PK-RDA | U20: =IF(R20="RON",M20,"") -> TRI MG
A21: 4 | B21: PK-YGK | C21: =IF(B21>1,VLOOKUP(B21,DB!$D$4:$E$800,2,0),"") -> HK 400 | D21: - | E21: FALSE | G21: FALSE | H21: NSA04 | I21: =IF(K21>1,VLOOKUP(K21,DB!$A$4:$B$500,2,0),"") | J21: =IF(L21>1,VLOOKUP(L21,DB!$A$4:$B$500,2,0),"") | M21: =IF(B21>1,VLOOKUP(B21,DB!$D$4:$F$800,3,0),"") -> TRI MG | N21: UNSERVICEABLE | O21: =IF(ISBLANK(F21),"RON","") -> RON | Q21: =IF(R21="RON",H21,"") -> NSA04 | R21: =IF(O21="RON",O21,"") -> RON | S21: =IF(R21="RON",C21,"") -> HK 400 | T21: =IF(R21="RON",B21,"") -> PK-YGK | U21: =IF(R21="RON",M21,"") -> TRI MG
A22: 5 | B22: PK-YGR | C22: =IF(B22>1,VLOOKUP(B22,DB!$D$4:$E$800,2,0),"") -> HK 800 | D22: - | E22: FALSE | G22: FALSE | H22: NSA05 | I22: =IF(K22>1,VLOOKUP(K22,DB!$A$4:$B$500,2,0),"") | J22: =IF(L22>1,VLOOKUP(L22,DB!$A$4:$B$500,2,0),"") | M22: =IF(B22>1,VLOOKUP(B22,DB!$D$4:$F$800,3,0),"") -> TRI MG | N22: UNSERVICEABLE | O22: =IF(ISBLANK(F22),"RON","") -> RON | Q22: =IF(R22="RON",H22,"") -> NSA05 | R22: =IF(O22="RON",O22,"") -> RON | S22: =IF(R22="RON",C22,"") -> HK 800 | T22: =IF(R22="RON",B22,"") -> PK-YGR | U22: =IF(R22="RON",M22,"") -> TRI MG
A23: 6 | B23: N-484BA | C23: =IF(B23>1,VLOOKUP(B23,DB!$D$4:$E$800,2,0),"") -> LJ 31 | D23: - | E23: FALSE | G23: FALSE | H23: NSA06 | I23: =IF(K23>1,VLOOKUP(K23,DB!$A$4:$B$500,2,0),"") | J23: =IF(L23>1,VLOOKUP(L23,DB!$A$4:$B$500,2,0),"") | M23: =IF(B23>1,VLOOKUP(B23,DB!$D$4:$F$800,3,0),"") -> IAP | N23: UNSERVICEABLE | O23: =IF(ISBLANK(F23),"RON","") -> RON | Q23: =IF(R23="RON",H23,"") -> NSA06 | R23: =IF(O23="RON",O23,"") -> RON | S23: =IF(R23="RON",C23,"") -> LJ 31 | T23: =IF(R23="RON",B23,"") -> N-484BA | U23: =IF(R23="RON",M23,"") -> IAP
A24: 7 | B24: A-2701 | C24: =IF(B24>1,VLOOKUP(B24,DB!$D$4:$E$800,2,0),"") -> FOKKER 27 | D24: - | E24: FALSE | G24: FALSE | H24: NSA07 | I24: =IF(K24>1,VLOOKUP(K24,DB!$A$4:$B$500,2,0),"") | J24: =IF(L24>1,VLOOKUP(L24,DB!$A$4:$B$500,2,0),"") | M24: =IF(B24>1,VLOOKUP(B24,DB!$D$4:$F$800,3,0),"") -> TNI AU | N24: UNSERVICEABLE | O24: =IF(ISBLANK(F24),"RON","") -> RON | Q24: =IF(R24="RON",H24,"") -> NSA07 | R24: =IF(O24="RON",O24,"") -> RON | S24: =IF(R24="RON",C24,"") -> FOKKER 27 | T24: =IF(R24="RON",B24,"") -> A-2701 | U24: =IF(R24="RON",M24,"") -> TNI AU
A25: 8 | B25: A-2706 | C25: =IF(B25>1,VLOOKUP(B25,DB!$D$4:$E$800,2,0),"") -> FOKKER 27 | D25: - | E25: FALSE | G25: FALSE | H25: NSA08 | I25: =IF(K25>1,VLOOKUP(K25,DB!$A$4:$B$500,2,0),"") | J25: =IF(L25>1,VLOOKUP(L25,DB!$A$4:$B$500,2,0),"") | M25: =IF(B25>1,VLOOKUP(B25,DB!$D$4:$F$800,3,0),"") -> TNI AU | N25: UNSERVICEABLE | O25: =IF(ISBLANK(F25),"RON","") -> RON | Q25: =IF(R25="RON",H25,"") -> NSA08 | R25: =IF(O25="RON",O25,"") -> RON | S25: =IF(R25="RON",C25,"") -> FOKKER 27 | T25: =IF(R25="RON",B25,"") -> A-2706 | U25: =IF(R25="RON",M25,"") -> TNI AU
A26: 9 | B26: A-2801 | C26: =IF(B26>1,VLOOKUP(B26,DB!$D$4:$E$800,2,0),"") -> FOKKER 28 | D26: - | E26: FALSE | G26: FALSE | H26: NSA09 | I26: =IF(K26>1,VLOOKUP(K26,DB!$A$4:$B$500,2,0),"") | J26: =IF(L26>1,VLOOKUP(L26,DB!$A$4:$B$500,2,0),"") | M26: =IF(B26>1,VLOOKUP(B26,DB!$D$4:$F$800,3,0),"") -> TNI AU | N26: UNSERVICEABLE | O26: =IF(ISBLANK(F26),"RON","") -> RON | Q26: =IF(R26="RON",H26,"") -> NSA09 | R26: =IF(O26="RON",O26,"") -> RON | S26: =IF(R26="RON",C26,"") -> FOKKER 28 | T26: =IF(R26="RON",B26,"") -> A-2801 | U26: =IF(R26="RON",M26,"") -> TNI AU
A27: 10 | B27: N-2409K | C27: =IF(B27>1,VLOOKUP(B27,DB!$D$4:$E$800,2,0),"") -> HK 800 | D27: - | E27: FALSE | G27: FALSE | H27: NSA10 | I27: =IF(K27>1,VLOOKUP(K27,DB!$A$4:$B$500,2,0),"") | J27: =IF(L27>1,VLOOKUP(L27,DB!$A$4:$B$500,2,0),"") | M27: AFM | O27: =IF(ISBLANK(F27),"RON","") -> RON | Q27: =IF(R27="RON",H27,"") -> NSA10 | R27: =IF(O27="RON",O27,"") -> RON | S27: =IF(R27="RON",C27,"") -> HK 800 | T27: =IF(R27="RON",B27,"") -> N-2409K | U27: =IF(R27="RON",M27,"") -> AFM
A28: 11 | B28: T7-HNC | C28: =IF(B28>1,VLOOKUP(B28,DB!$D$4:$E$800,2,0),"") -> KING AIR | D28: - | E28: FALSE | F28: 0.26458333 | G28: TRUE | H28: NSA11 | I28: =IF(K28>1,VLOOKUP(K28,DB!$A$4:$B$500,2,0),"") -> EX RON | J28: B3 | K28: - | M28: AFM | O28: =IF(ISBLANK(F28),"RON","") | Q28: =IF(R28="RON",H28,"") | R28: =IF(O28="RON",O28,"") | S28: =IF(R28="RON",C28,"") | T28: =IF(R28="RON",B28,"") | U28: =IF(R28="RON",M28,"")
A29: 12 | B29: T7-FCN | C29: =IF(B29>1,VLOOKUP(B29,DB!$D$4:$E$800,2,0),"") -> HK 800 | D29: - | E29: FALSE | G29: FALSE | H29: NSA12 | I29: =IF(K29>1,VLOOKUP(K29,DB!$A$4:$B$500,2,0),"") | J29: =IF(L29>1,VLOOKUP(L29,DB!$A$4:$B$500,2,0),"") | M29: KARISMA | O29: =IF(ISBLANK(F29),"RON","") -> RON | Q29: =IF(R29="RON",H29,"") -> NSA12 | R29: =IF(O29="RON",O29,"") -> RON | S29: =IF(R29="RON",C29,"") -> HK 800 | T29: =IF(R29="RON",B29,"") -> T7-FCN | U29: =IF(R29="RON",M29,"") -> KARISMA
A30: 13 | B30: N-977JH | C30: =IF(B30>1,VLOOKUP(B30,DB!$D$4:$E$800,2,0),"") -> CT 680 | D30: - | E30: FALSE | G30: FALSE | H30: NSA13 | I30: =IF(K30>1,VLOOKUP(K30,DB!$A$4:$B$500,2,0),"") | J30: =IF(L30>1,VLOOKUP(L30,DB!$A$4:$B$500,2,0),"") | M30: =IF(B30>1,VLOOKUP(B30,DB!$D$4:$F$800,3,0),"") -> JIP | O30: =IF(ISBLANK(F30),"RON","") -> RON | Q30: =IF(R30="RON",H30,"") -> NSA13 | R30: =IF(O30="RON",O30,"") -> RON | S30: =IF(R30="RON",C30,"") -> CT 680 | T30: =IF(R30="RON",B30,"") -> N-977JH | U30: =IF(R30="RON",M30,"") -> JIP
A31: 14 | B31: N-227GV | C31: =IF(B31>1,VLOOKUP(B31,DB!$D$4:$E$800,2,0),"") -> L 1000 | D31: - | E31: FALSE | G31: FALSE | H31: SA01 | I31: =IF(K31>1,VLOOKUP(K31,DB!$A$4:$B$500,2,0),"") | J31: =IF(L31>1,VLOOKUP(L31,DB!$A$4:$B$500,2,0),"") | M31: =IF(B31>1,VLOOKUP(B31,DB!$D$4:$F$800,3,0),"") -> PREMI | O31: =IF(ISBLANK(F31),"RON","") -> RON | Q31: =IF(R31="RON",H31,"") -> SA01 | R31: =IF(O31="RON",O31,"") -> RON | S31: =IF(R31="RON",C31,"") -> L 1000 | T31: =IF(R31="RON",B31,"") -> N-227GV | U31: =IF(R31="RON",M31,"") -> PREMI
A32: 15 | B32: PK-RJH | C32: =IF(B32>1,VLOOKUP(B32,DB!$D$4:$E$800,2,0),"") -> EC 135 | D32: - | E32: FALSE | G32: FALSE | H32: SA02 | I32: =IF(K32>1,VLOOKUP(K32,DB!$A$4:$B$500,2,0),"") | J32: =IF(L32>1,VLOOKUP(L32,DB!$A$4:$B$500,2,0),"") | M32: =IF(B32>1,VLOOKUP(B32,DB!$D$4:$F$800,3,0),"") -> PREMI | O32: =IF(ISBLANK(F32),"RON","") -> RON | Q32: =IF(R32="RON",H32,"") -> SA02 | R32: =IF(O32="RON",O32,"") -> RON | S32: =IF(R32="RON",C32,"") -> EC 135 | T32: =IF(R32="RON",B32,"") -> PK-RJH | U32: =IF(R32="RON",M32,"") -> PREMI
A33: 16 | B33: PK-LUR | C33: =IF(B33>1,VLOOKUP(B33,DB!$D$4:$E$800,2,0),"") -> A 320 | D33: - | E33: FALSE | F33: 0.22083333 | G33: TRUE | H33: SA03 | I33: =IF(K33>1,VLOOKUP(K33,DB!$A$4:$B$500,2,0),"") -> EX RON | J33: A1 | K33: - | M33: =IF(B33>1,VLOOKUP(B33,DB!$D$4:$F$800,3,0),"") -> BATIK AIR | O33: =IF(ISBLANK(F33),"RON","") | Q33: =IF(R33="RON",H33,"") | R33: =IF(O33="RON",O33,"") | S33: =IF(R33="RON",C33,"") | T33: =IF(R33="RON",B33,"") | U33: =IF(R33="RON",M33,"")
A34: 17 | B34: VP-CLL | C34: =IF(B34>1,VLOOKUP(B34,DB!$D$4:$E$800,2,0),"") -> EMB 135 | D34: - | E34: FALSE | G34: FALSE | H34: SA04 | I34: =IF(K34>1,VLOOKUP(K34,DB!$A$4:$B$500,2,0),"") | J34: =IF(L34>1,VLOOKUP(L34,DB!$A$4:$B$500,2,0),"") | M34: KARISMA | O34: =IF(ISBLANK(F34),"RON","") -> RON | Q34: =IF(R34="RON",H34,"") -> SA04 | R34: =IF(O34="RON",O34,"") -> RON | S34: =IF(R34="RON",C34,"") -> EMB 135 | T34: =IF(R34="RON",B34,"") -> VP-CLL | U34: =IF(R34="RON",M34,"") -> KARISMA
A35: 18 | B35: T7-X14 | C35: =IF(B35>1,VLOOKUP(B35,DB!$D$4:$E$800,2,0),"") -> G VI | D35: - | E35: FALSE | G35: FALSE | H35: SA05 | I35: =IF(K35>1,VLOOKUP(K35,DB!$A$4:$B$500,2,0),"") | J35: =IF(L35>1,VLOOKUP(L35,DB!$A$4:$B$500,2,0),"") | M35: AFM | O35: =IF(ISBLANK(F35),"RON","") -> RON | Q35: =IF(R35="RON",H35,"") -> SA05 | R35: =IF(O35="RON",O35,"") -> RON | S35: =IF(R35="RON",C35,"") -> G VI | T35: =IF(R35="RON",B35,"") -> T7-X14 | U35: =IF(R35="RON",M35,"") -> AFM
A36: 19 | B36: T7-MPI | C36: =IF(B36>1,VLOOKUP(B36,DB!$D$4:$E$800,2,0),"") -> EMB 135 | D36: - | E36: FALSE | G36: FALSE | H36: SA06 | I36: =IF(K36>1,VLOOKUP(K36,DB!$A$4:$B$500,2,0),"") | J36: =IF(L36>1,VLOOKUP(L36,DB!$A$4:$B$500,2,0),"") | M36: KARISMA | O36: =IF(ISBLANK(F36),"RON","") -> RON | Q36: =IF(R36="RON",H36,"") -> SA06 | R36: =IF(O36="RON",O36,"") -> RON | S36: =IF(R36="RON",C36,"") -> EMB 135 | T36: =IF(R36="RON",B36,"") -> T7-MPI | U36: =IF(R36="RON",M36,"") -> KARISMA
A37: 20 | B37: PK-BKP | C37: =IF(B37>1,VLOOKUP(B37,DB!$D$4:$E$800,2,0),"") -> A 320 | D37: - | E37: FALSE | F37: 0.19791667 | G37: TRUE | H37: SA07 | I37: =IF(K37>1,VLOOKUP(K37,DB!$A$4:$B$500,2,0),"") -> EX RON | J37: B6 | K37: - | M37: =IF(B37>1,VLOOKUP(B37,DB!$D$4:$F$800,3,0),"") -> BATIK AIR | O37: =IF(ISBLANK(F37),"RON","") | Q37: =IF(R37="RON",H37,"") | R37: =IF(O37="RON",O37,"") | S37: =IF(R37="RON",C37,"") | T37: =IF(R37="RON",B37,"") | U37: =IF(R37="RON",M37,"")
A38: 21 | B38: PK-GJT | C38: =IF(B38>1,VLOOKUP(B38,DB!$D$4:$E$800,2,0),"") -> ATR 72 | D38: - | E38: FALSE | G38: FALSE | H38: SA08 | I38: =IF(K38>1,VLOOKUP(K38,DB!$A$4:$B$500,2,0),"") | J38: =IF(L38>1,VLOOKUP(L38,DB!$A$4:$B$500,2,0),"") | M38: =IF(B38>1,VLOOKUP(B38,DB!$D$4:$F$800,3,0),"") -> CITILINK | O38: =IF(ISBLANK(F38),"RON","") -> RON | Q38: =IF(R38="RON",H38,"") -> SA08 | R38: =IF(O38="RON",O38,"") -> RON | S38: =IF(R38="RON",C38,"") -> ATR 72 | T38: =IF(R38="RON",B38,"") -> PK-GJT | U38: =IF(R38="RON",M38,"") -> CITILINK
A39: 22 | B39: PK-FJA | C39: =IF(B39>1,VLOOKUP(B39,DB!$D$4:$E$800,2,0),"") -> ATR 72 | D39: - | E39: FALSE | F39: 0.27986111 | G39: TRUE | H39: SA09 | I39: =IF(K39>1,VLOOKUP(K39,DB!$A$4:$B$500,2,0),"") -> EX RON | J39: B2 | K39: - | M39: =IF(B39>1,VLOOKUP(B39,DB!$D$4:$F$800,3,0),"") -> FLY JAYA | O39: =IF(ISBLANK(F39),"RON","") | Q39: =IF(R39="RON",H39,"") | R39: =IF(O39="RON",O39,"") | S39: =IF(R39="RON",C39,"") | T39: =IF(R39="RON",B39,"") | U39: =IF(R39="RON",M39,"")
