Workbook

Sheet DB
A1: SCHEDULE AIRLINE | D1: PESAWAT
A3: FLIGHT NO | B3: ROUTE | D3: REGISTRASI | E3: TYPE | F3: MASKAPAI
A4: - | B4: EX RON | D4: PK-JTX | E4: BELL 407 | F4: AIR PASIFIC
A5: 0B 1001 | B5: WIII | D5: PK-ODC | E5: AS350 | F5: AIRFAST
A6: 0B 1051 | B6: WAJJ | D6: PK-NKV | E6: B 733 | F6: AIRNESIA
A7: 0B 5021 | B7: WAAA | D7: PK-NMI | E7: B 733 | F7: AIRNESIA
A8: 0B 5022 | B8: WAMM | D8: PK-BBN | E8: B 738 | F8: B. B. N
A9: 0B 5024 | B9: WAAA | D9: PK-BBJ | E9: B 734 | F9: B. B. N.
A10: 0B 5273 | B10: WAOO | D10: PK-BKA | E10: A 320 | F10: BATIK AIR
A11: 0B 5274 | B11: WAOO | D11: PK-BKB | E11: A 320 | F11: BATIK AIR
A12: 0B 5275 | B12: WAOO | D12: PK-BKC | E12: A 320 | F12: BATIK AIR
A13: 0B 5276 | B13: WAOO | D13: PK-BKD | E13: A 320 | F13: BATIK AIR
A14: 0B 5611 | B14: WIOO | D14: PK-BKE | E14: A 320 | F14: BATIK AIR
... A287: ID 5002 | B287: WILL | D287: PK-GND | E287: B 738 | F287: GARUDA
D288: PK-GNE | E288: B 738 | F288: GARUDA
D289: PK-GNF | E289: B 738 | F289: GARUDA
D290: PK-GNG | E290: B 738 | F290: GARUDA
D291: PK-GNH | E291: B 738 | F291: GARUDA
D292: PK-GNI | E292: B 738 | F292: GARUDA
D293: PK-GNJ | E293: B 738 | F293: GARUDA
D294: PK-GNK | E294: B 738 | F294: GARUDA
D295: PK-GNL | E295: B 738 | F295: GARUDA
D296: PK-GNM | E296: B 738 | F296: GARUDA
D297: PK-GNN | E297: B 738 | F297: GARUDA
D298: PK-GNO | E298: B 738 | F298: GARUDA
D299: PK-GNP | E299: B 738 | F299: GARUDA
... D425: PK-YST | E425: B 733 | F425: TRIGANA
D426: 20241 | E426: XIAN Y20 B
D427: 20248 | E427: XIAN Y20 B
D428: 13-031 | E428: DO 328
D429: 13-075 | E429: DO 328
D430: 9H-VCB | E430: CL 350
D431: 9H-VCR | E431: CL 350
D432: 9H-VIE | E432: G 7500
D433: 9H-VIT | E433: G 7500
D434: 9M-VEV | E434: AVANTI
D435: A56-003 | E435: FAL 7X
D436: B-8160 | E436: G V
D437: F-RAFP | E437: FAL 900
D438: FNY-5663D | E438: CARACAL
...

Sheet 01
A1: APRON MOVEMENT SHEET HALIM PERDANAKUSUMA | V1: STAND MAIN APRON AVAILABLE
V2: STAND | W2: ACTUAL | X2: PLOTTING
V3: A0 | W3: =COUNTIFS($H$18:$H$167,V3,$D$18:$D$167,"<>",$F$18:$F$167,"") -> 0 | X3: =COUNTIFS($H$18:$H$167,V3,$D$18:$D$167,"",$F$18:$F$167,"") -> 0 | Y3: STAND | Z3: ACTUAL | AA3: PLOTTING
V4: A1 | W4: =COUNTIFS($H$18:$H$167,V4,$D$18:$D$167,"<>",$F$18:$F$167,"") -> 1 | X4: =COUNTIFS($H$18:$H$167,V4,$D$18:$D$167,"",$F$18:$F$167,"") -> 0 | Y4: B6 | Z4: =COUNTIFS($H$18:$H$167,Y4,$D$18:$D$167,"<>",$F$18:$F$167,"") -> 1 | AA4: =COUNTIFS($H$18:$H$167,Y4,$D$18:$D$167,"",$F$18:$F$167,"") -> 0
V5: A2 | W5: =COUNTIFS($H$18:$H$167,V5,$D$18:$D$167,"<>",$F$18:$F$167,"") -> 0 | X5: =COUNTIFS($H$18:$H$167,V5,$D$18:$D$167,"",$F$18:$F$167,"") -> 0 | Y5: B7 | Z5: =COUNTIFS($H$18:$H$167,Y5,$D$18:$D$167,"<>",$F$18:$F$167,"") -> 1 | AA5: =COUNTIFS($H$18:$H$167,Y5,$D$18:$D$167,"",$F$18:$F$167,"") -> 0
V6: A3 | W6: =COUNTIFS($H$18:$H$167,V6,$D$18:$D$167,"<>",$F$18:$F$167,"") -> 1 | X6: =COUNTIFS($H$18:$H$167,V6,$D$18:$D$167,"",$F$18:$F$167,"") -> 0 | Y6: B8 | Z6: =COUNTIFS($H$18:$H$167,Y6,$D$18:$D$167,"<>",$F$18:$F$167,"") -> 1 | AA6: =COUNTIFS($H$18:$H$167,Y6,$D$18:$D$167,"",$F$18:$F$167,"") -> 0
A7: AERODROME : | C7: WIHH | V7: B1 | W7: =COUNTIFS($H$18:$H$167,V7,$D$18:$D$167,"<>",$F$18:$F$167,"") -> 1 | X7: =COUNTIFS($H$18:$H$167,V7,$D$18:$D$167,"",$F$18:$F$167,"") -> 0 | Y7: B9 | Z7: =COUNTIFS($H$18:$H$167,Y7,$D$18:$D$167,"<>",$F$18:$F$167,"") -> 0 | AA7: =COUNTIFS($H$18:$H$167,Y7,$D$18:$D$167,"",$F$18:$F$167,"") -> 0
A8: TANGGAL : | C8: 45778 | V8: B2 | W8: =COUNTIFS($H$18:$H$167,V8,$D$18:$D$167,"<>",$F$18:$F$167,"") -> 1 | X8: =COUNTIFS($H$18:$H$167,V8,$D$18:$D$167,"",$F$18:$F$167,"") -> 0 | Y8: B10 | Z8: =COUNTIFS($H$18:$H$167,Y8,$D$18:$D$167,"<>",$F$18:$F$167,"") -> 0 | AA8: =COUNTIFS($H$18:$H$167,Y8,$D$18:$D$167,"",$F$18:$F$167,"") -> 0
A9: PETUGAS AMC | C9: PAGI SIANG ( 07:00 - 18:59) | E9: MALAM (19:00 - 06:59) | V9: B3 | W9: =COUNTIFS($H$18:$H$167,V9,$D$18:$D$167,"<>",$F$18:$F$167,"") -> 1 | X9: =COUNTIFS($H$18:$H$167,V9,$D$18:$D$167,"",$F$18:$F$167,"") -> 0 | Y9: B11 | Z9: =COUNTIFS($H$18:$H$167,Y9,$D$18:$D$167,"<>",$F$18:$F$167,"") -> 1 | AA9: =COUNTIFS($H$18:$H$167,Y9,$D$18:$D$167,"",$F$18:$F$167,"") -> 0
C10: NIKON | E10: RIZA IBNU FAJAR | V10: B4 | W10: =COUNTIFS($H$18:$H$167,V10,$D$18:$D$167,"<>",$F$18:$F$167,"") -> 0 | X10: =COUNTIFS($H$18:$H$167,V10,$D$18:$D$167,"",$F$18:$F$167,"") -> 0 | Y10: B12 | Z10: =COUNTIFS($H$18:$H$167,Y10,$D$18:$D$167,"<>",$F$18:$F$167,"") -> 1 | AA10: =COUNTIFS($H$18:$H$167,Y10,$D$18:$D$167,"",$F$18:$F$167,"") -> 0
C11: RYAN KHALIQ | E11: RIDWAN WINANTO | V11: B5 | W11: =COUNTIFS($H$18:$H$167,V11,$D$18:$D$167,"<>",$F$18:$F$167,"") -> 0 | X11: =COUNTIFS($H$18:$H$167,V11,$D$18:$D$167,"",$F$18:$F$167,"") -> 0 | Y11: B13 | Z11: =COUNTIFS($H$18:$H$167,Y11,$D$18:$D$167,"<>",$F$18:$F$167,"") -> 0 | AA11: =COUNTIFS($H$18:$H$167,Y11,$D$18:$D$167,"",$F$18:$F$167,"") -> 0
C12: ACHMAD FAUZI | E12: PELTU UUM
C13: PELTU SUCIADI | V13: AIRCRAFT RON | AF13: APRON MOVEMENT IN HOURS | AL13: PARKING STAND USE IN HOURS
A15: NO | B15: REGISTRATION | C15: TYPE | D15: TIME OF | H15: PARKING STAND | I15: FROM | J15: TO | K15: FLIGHT NO | M15: OPERATOR / AIRLINES | N15: REMARKS | O15: STATUS | V15: STAND | W15: REG | X15: TYPE A/C | Y15: COMPANY | AF15: TIME | AH15: ARR | AI15: DEP | AJ15: TOTAL | AM15: 0.00069444444 | AN15: 0.042361111 | AO15: 0.084027778 | AP15: 0.12569444 | AQ15: 0.16736111 | AR15: 0.20902778 | AS15: 0.25069444 | AT15: 0.29236111 | AU15: 0.33402778 | AV15: 0.37569444 | AW15: 0.41736111 | AX15: 0.45902778 | AY15: 0.50069444 | AZ15: 0.54236111 | BA15: 0.58402778 | BB15: 0.62569444 | BC15: 0.66736111 | BD15: 0.70902778 | BE15: 0.75069444 | BF15: 0.79236111 | BG15: 0.83402778 | BH15: 0.87569444 | BI15: 0.91736111 | BJ15: 0.95902778
D16: ON BLOCK | F16: OFF BLOCK | K16: ARR | L16: DEP | AM16: 0.041666667 | AN16: 0.083333333 | AO16: 0.125 | AP16: 0.16666667 | AQ16: 0.20833333 | AR16: 0.25 | AS16: 0.29166667 | AT16: 0.33333333 | AU16: 0.375 | AV16: 0.41666667 | AW16: 0.45833333 | AX16: 0.5 | AY16: 0.54166667 | AZ16: 0.58333333 | BA16: 0.625 | BB16: 0.66666667 | BC16: 0.70833333 | BD16: 0.75 | BE16: 0.79166667 | BF16: 0.83333333 | BG16: 0.875 | BH16: 0.91666667 | BI16: 0.95833333 | BJ16: 0
Q17: 1 | R17: 2 | S17: 3 | T17: 4 | U17: 5 | V17: A0 | W17: =IFERROR(INDEX($Q$18:$U$167,MATCH(V17,$Q$18:$Q$167,0),MATCH(4,$Q$17:$U$17,0)),"") | X17: =IFERROR(INDEX($Q$18:$U$167,MATCH(V17,$Q$18:$Q$167,0),MATCH(3,$Q$17:$U$17,0)),"") | Y17: =IFERROR(INDEX($Q$18:$U$167,MATCH(V17,$Q$18:$Q$167,0),MATCH(5,$Q$17:$U$17,0)),"") | Z17: FALSE | AD17: 1 | AE17: 2 | AF17: 0.00069444444 | AG17: 0.041666667 | AH17: =COUNTIF($AD$18:$AD$167,"<=01:00") -> 0 | AI17: =COUNTIF($AE$18:$AE$167,"<=01:00") -> 0 | AJ17: =AI17+AH17 -> 0 | AL17: A0 | AM17: =COUNTIFS($H$18:$H$167,AL17,$D$18:$D$167,"<=01:00") -> 0 | AN17: =COUNTIFS($H$18:$H$167,AL17,$D$18:$D$167,">01:00",$D$18:$D$167,"<=02:00") -> 0 | AO17: =COUNTIFS($H$18:$H$167,AL17,$D$18:$D$167,">02:00",$D$18:$D$167,"<=03:00") -> 0 | AP17: =COUNTIFS($H$18:$H$167,AL17,$D$18:$D$167,">03:00",$D$18:$D$167,"<=04:00") -> 0 | AQ17: =COUNTIFS($H$18:$H$167,AL17,$D$18:$D$167,">04:00",$D$18:$D$167,"<=05:00") -> 0 | AR17: =COUNTIFS($H$18:$H$167,AL17,$D$18:$D$167,">05:00",$D$18:$D$167,"<=06:00") -> 0 | AS17: =COUNTIFS($H$18:$H$167,AL17,$D$18:$D$167,">06:00",$D$18:$D$167,"<=07:00") -> 0 | AT17: =COUNTIFS($H$18:$H$167,AL17,$D$18:$D$167,">07:00",$D$18:$D$167,"<=08:00") -> 1 | AU17: =COUNTIFS($H$18:$H$167,AL17,$D$18:$D$167,">08:00",$D$18:$D$167,"<=09:00") -> 0 | AV17: =COUNTIFS($H$18:$H$167,AL17,$D$18:$D$167,">09:00",$D$18:$D$167,"<=10:00") -> 0 | AW17: =COUNTIFS($H$18:$H$167,AL17,$D$18:$D$167,">10:00",$D$18:$D$167,"<=11:00") -> 1 | AX17: =COUNTIFS($H$18:$H$167,AL17,$D$18:$D$167,">11:00",$D$18:$D$167,"<=12:00") -> 0 | AY17: =COUNTIFS($H$18:$H$167,AL17,$D$18:$D$167,">12:00",$D$18:$D$167,"<=13:00") -> 0 | AZ17: =COUNTIFS($H$18:$H$167,AL17,$D$18:$D$167,">13:00",$D$18:$D$167,"<=14:00") -> 0 | BA17: =COUNTIFS($H$18:$H$167,AL17,$D$18:$D$167,">14:00",$D$18:$D$167,"<=15:00") -> 0 | BB17: =COUNTIFS($H$18:$H$167,AL17,$D$18:$D$167,">15:00",$D$18:$D$167,"<=16:00") -> 0 | BC17: =COUNTIFS($H$18:$H$167,AL17,$D$18:$D$167,">16:00",$D$18:$D$167,"<=17:00") -> 0 | BD17: =COUNTIFS($H$18:$H$167,AL17,$D$18:$D$167,">17:00",$D$18:$D$167,"<=18:00") -> 0 | BE17: =COUNTIFS($H$18:$H$167,AL17,$D$18:$D$167,">18:00",$D$18:$D$167,"<=19:00") -> 0 | BF17: =COUNTIFS($H$18:$H$167,AL17,$D$18:$D$167,">19:00",$D$18:$D$167,"<=20:00") -> 0 | BG17: =COUNTIFS($H$18:$H$167,AL17,$D$18:$D$167,">20:00",$D$18:$D$167,"<=21:00") -> 0 | BH17: =COUNTIFS($H$18:$H$167,AL17,$D$18:$D$167,">21:00",$D$18:$D$167,"<=22:00") -> 0 | BI17: =COUNTIFS($H$18:$H$167,AL17,$D$18:$D$167,">22:00",$D$18:$D$167,"<=23:00") -> 0 | BJ17: =COUNTIFS($H$18:$H$167,AL17,$D$18:$D$167,">23:00") -> 0 | BK17: =SUM(AM17:BJ17) -> 2
A18: 1 | B18: PK-VCD | C18: =IF(B18>1,VLOOKUP(B18,DB!$D$4:$E$800,2,0),"") -> PA 34 | D18: - | E18: FALSE | G18: FALSE | H18: NSA01 | I18: =IF(K18>1,VLOOKUP(K18,DB!$A$4:$B$500,2,0),"") | J18: =IF(L18>1,VLOOKUP(L18,DB!$A$4:$B$500,2,0),"") | M18: =IF(B18>1,VLOOKUP(B18,DB!$D$4:$F$800,3,0),"") -> PENAS | N18: UNSERVICEABLE | O18: =IF(ISBLANK(F18),"RON","") -> RON | Q18: =IF(R18="RON",H18,"") -> NSA01 | R18: =IF(O18="RON",O18,"") -> RON | S18: =IF(R18="RON",C18,"") -> PA 34 | T18: =IF(R18="RON",B18,"") -> PK-VCD | U18: =IF(R18="RON",M18,"") -> PENAS | V18: A1 | W18: =IFERROR(INDEX($Q$18:$U$167,MATCH(V18,$Q$18:$Q$167,0),MATCH(4,$Q$17:$U$17,0)),"") -> PK-GQI | X18: =IFERROR(INDEX($Q$18:$U$167,MATCH(V18,$Q$18:$Q$167,0),MATCH(3,$Q$17:$U$17,0)),"") -> A 320 | Y18: =IFERROR(INDEX($Q$18:$U$167,MATCH(V18,$Q$18:$Q$167,0),MATCH(5,$Q$17:$U$17,0)),"") -> CITILINK | Z18: TRUE | AD18: =IF(D18="","-",D18) -> - | AE18: =IF(F18="","-",F18) -> - | AF18: 0.042361111 | AG18: 0.083333333 | AH18: =COUNTIFS($AD$18:$AD$167,">01:00",$AD$18:$AD$167,"<=02:00") -> 0 | AI18: =COUNTIFS($AE$18:$AE$167,">01:00",$AE$18:$AE$167,"<=02:00") -> 0 | AJ18: =AI18+AH18 -> 0 | AL18: A1 | AM18: =COUNTIFS($H$18:$H$167,AL18,$D$18:$D$167,"<=01:00") -> 0 | AN18: =COUNTIFS($H$18:$H$167,AL18,$D$18:$D$167,">01:00",$D$18:$D$167,"<=02:00") -> 0 | AO18: =COUNTIFS($H$18:$H$167,AL18,$D$18:$D$167,">02:00",$D$18:$D$167,"<=03:00") -> 0 | AP18: =COUNTIFS($H$18:$H$167,AL18,$D$18:$D$167,">03:00",$D$18:$D$167,"<=04:00") -> 0 | AQ18: =COUNTIFS($H$18:$H$167,AL18,$D$18:$D$167,">04:00",$D$18:$D$167,"<=05:00") -> 0 | AR18: =COUNTIFS($H$18:$H$167,AL18,$D$18:$D$167,">05:00",$D$18:$D$167,"<=06:00") -> 0 | AS18: =COUNTIFS($H$18:$H$167,AL18,$D$18:$D$167,">06:00",$D$18:$D$167,"<=07:00") -> 0 | AT18: =COUNTIFS($H$18:$H$167,AL18,$D$18:$D$167,">07:00",$D$18:$D$167,"<=08:00") -> 0 | AU18: =COUNTIFS($H$18:$H$167,AL18,$D$18:$D$167,">08:00",$D$18:$D$167,"<=09:00") -> 1 | AV18: =COUNTIFS($H$18:$H$167,AL18,$D$18:$D$167,">09:00",$D$18:$D$167,"<=10:00") -> 0 | AW18: =COUNTIFS($H$18:$H$167,AL18,$D$18:$D$167,">10:00",$D$18:$D$167,"<=11:00") -> 0 | AX18: =COUNTIFS($H$18:$H$167,AL18,$D$18:$D$167,">11:00",$D$18:$D$167,"<=12:00") -> 1 | AY18: =COUNTIFS($H$18:$H$167,AL18,$D$18:$D$167,">12:00",$D$18:$D$167,"<=13:00") -> 0 | AZ18: =COUNTIFS($H$18:$H$167,AL18,$D$18:$D$167,">13:00",$D$18:$D$167,"<=14:00") -> 1 | BA18: =COUNTIFS($H$18:$H$167,AL18,$D$18:$D$167,">14:00",$D$18:$D$167,"<=15:00") -> 0 | BB18: =COUNTIFS($H$18:$H$167,AL18,$D$18:$D$167,">15:00",$D$18:$D$167,"<=16:00") -> 1 | BC18: =COUNTIFS($H$18:$H$167,AL18,$D$18:$D$167,">16:00",$D$18:$D$167,"<=17:00") -> 0 | BD18: =COUNTIFS($H$18:$H$167,AL18,$D$18:$D$167,">17:00",$D$18:$D$167,"<=18:00") -> 0 | BE18: =COUNTIFS($H$18:$H$167,AL18,$D$18:$D$167,">18:00",$D$18:$D$167,"<=19:00") -> 0 | BF18: =COUNTIFS($H$18:$H$167,AL18,$D$18:$D$167,">19:00",$D$18:$D$167,"<=20:00") -> 0 | BG18: =COUNTIFS($H$18:$H$167,AL18,$D$18:$D$167,">20:00",$D$18:$D$167,"<=21:00") -> 0 | BH18: =COUNTIFS($H$18:$H$167,AL18,$D$18:$D$167,">21:00",$D$18:$D$167,"<=22:00") -> 0 | BI18: =COUNTIFS($H$18:$H$167,AL18,$D$18:$D$167,">22:00",$D$18:$D$167,"<=23:00") -> 0 | BJ18: =COUNTIFS($H$18:$H$167,AL18,$D$18:$D$167,">23:00") -> 0 | BK18: =SUM(AM18:BJ18) -> 4
A19: 2 | B19: PK-RSO | C19: =IF(B19>1,VLOOKUP(B19,DB!$D$4:$E$800,2,0),"") -> CT 650 | D19: - | E19: FALSE | G19: FALSE | H19: NSA02 | I19: =IF(K19>1,VLOOKUP(K19,DB!$A$4:$B$500,2,0),"") | J19: =IF(L19>1,VLOOKUP(L19,DB!$A$4:$B$500,2,0),"") | M19: =IF(B19>1,VLOOKUP(B19,DB!$D$4:$F$800,3,0),"") -> ENGGANG | N19: UNSERVICEABLE | O19: =IF(ISBLANK(F19),"RON","") -> RON | Q19: =IF(R19="RON",H19,"") -> NSA02 | R19: =IF(O19="RON",O19,"") -> RON | S19: =IF(R19="RON",C19,"") -> CT 650 | T19: =IF(R19="RON",B19,"") -> PK-RSO | U19: =IF(R19="RON",M19,"") -> ENGGANG | V19: A2 | W19: =IFERROR(INDEX($Q$18:$U$167,MATCH(V19,$Q$18:$Q$167,0),MATCH(4,$Q$17:$U$17,0)),"") | X19: =IFERROR(INDEX($Q$18:$U$167,MATCH(V19,$Q$18:$Q$167,0),MATCH(3,$Q$17:$U$17,0)),"") | Y19: =IFERROR(INDEX($Q$18:$U$167,MATCH(V19,$Q$18:$Q$167,0),MATCH(5,$Q$17:$U$17,0)),"") | Z19: FALSE | AD19: =IF(D19="","-",D19) -> - | AE19: =IF(F19="","-",F19) -> - | AF19: 0.084027778 | AG19: 0.125 | AH19: =COUNTIFS($AD$18:$AD$167,">02:00",$AD$18:$AD$167,"<=03:00") -> 0 | AI19: =COUNTIFS($AE$18:$AE$167,">02:00",$AE$18:$AE$167,"<=03:00") -> 0 | AJ19: =AI19+AH19 -> 0 | AL19: A2 | AM19: =COUNTIFS($H$18:$H$167,AL19,$D$18:$D$167,"<=01:00") -> 0 | AN19: =COUNTIFS($H$18:$H$167,AL19,$D$18:$D$167,">01:00",$D$18:$D$167,"<=02:00") -> 0 | AO19: =COUNTIFS($H$18:$H$167,AL19,$D$18:$D$167,">02:00",$D$18:$D$167,"<=03:00") -> 0 | AP19: =COUNTIFS($H$18:$H$167,AL19,$D$18:$D$167,">03:00",$D$18:$D$167,"<=04:00") -> 0 | AQ19: =COUNTIFS($H$18:$H$167,AL19,$D$18:$D$167,">04:00",$D$18:$D$167,"<=05:00") -> 0 | AR19: =COUNTIFS($H$18:$H$167,AL19,$D$18:$D$167,">05:00",$D$18:$D$167,"<=06:00") -> 0 | AS19: =COUNTIFS($H$18:$H$167,AL19,$D$18:$D$167,">06:00",$D$18:$D$167,"<=07:00") -> 0 | AT19: =COUNTIFS($H$18:$H$167,AL19,$D$18:$D$167,">07:00",$D$18:$D$167,"<=08:00") -> 0 | AU19: =COUNTIFS($H$18:$H$167,AL19,$D$18:$D$167,">08:00",$D$18:$D$167,"<=09:00") -> 0 | AV19: =COUNTIFS($H$18:$H$167,AL19,$D$18:$D$167,">09:00",$D$18:$D$167,"<=10:00") -> 0 | AW19: =COUNTIFS($H$18:$H$167,AL19,$D$18:$D$167,">10:00",$D$18:$D$167,"<=11:00") -> 1 | AX19: =COUNTIFS($H$18:$H$167,AL19,$D$18:$D$167,">11:00",$D$18:$D$167,"<=12:00") -> 0 | AY19: =COUNTIFS($H$18:$H$167,AL19,$D$18:$D$167,">12:00",$D$18:$D$167,"<=13:00") -> 1 | AZ19: =COUNTIFS($H$18:$H$167,AL19,$D$18:$D$167,">13:00",$D$18:$D$167,"<=14:00") -> 0 | BA19: =COUNTIFS($H$18:$H$167,AL19,$D$18:$D$167,">14:00",$D$18:$D$167,"<=15:00") -> 0 | BB19: =COUNTIFS($H$18:$H$167,AL19,$D$18:$D$167,">15:00",$D$18:$D$167,"<=16:00") -> 0 | BC19: =COUNTIFS($H$18:$H$167,AL19,$D$18:$D$167,">16:00",$D$18:$D$167,"<=17:00") -> 1 | BD19: =COUNTIFS($H$18:$H$167,AL19,$D$18:$D$167,">17:00",$D$18:$D$167,"<=18:00") -> 0 | BE19: =COUNTIFS($H$18:$H$167,AL19,$D$18:$D$167,">18:00",$D$18:$D$167,"<=19:00") -> 0 | BF19: =COUNTIFS($H$18:$H$167,AL19,$D$18:$D$167,">19:00",$D$18:$D$167,"<=20:00") -> 0 | BG19: =COUNTIFS($H$18:$H$167,AL19,$D$18:$D$167,">20:00",$D$18:$D$167,"<=21:00") -> 0 | BH19: =COUNTIFS($H$18:$H$167,AL19,$D$18:$D$167,">21:00",$D$18:$D$167,"<=22:00") -> 0 | BI19: =COUNTIFS($H$18:$H$167,AL19,$D$18:$D$167,">22:00",$D$18:$D$167,"<=23:00") -> 0 | BJ19: =COUNTIFS($H$18:$H$167,AL19,$D$18:$D$167,">23:00") -> 0 | BK19: =SUM(AM19:BJ19) -> 3
A20: 3 | B20: PK-DGC | C20: =IF(B20>1,VLOOKUP(B20,DB!$D$4:$E$800,2,0),"") -> BAE ATP | D20: - | E20: FALSE | G20: FALSE | H20: NSA03 | I20: =IF(K20>1,VLOOKUP(K20,DB!$A$4:$B$500,2,0),"") | J20: =IF(L20>1,VLOOKUP(L20,DB!$A$4:$B$500,2,0),"") | M20: =IF(B20>1,VLOOKUP(B20,DB!$D$4:$F$800,3,0),"") -> DERAYA | N20: UNSERVICEABLE | O20: =IF(ISBLANK(F20),"RON","") -> RON | Q20: =IF(R20="RON",H20,"") -> NSA03 | R20: =IF(O20="RON",O20,"") -> RON | S20: =IF(R20="RON",C20,"") -> BAE ATP | T20: =IF(R20="RON",B20,"") -> PK-DGC | U20: =IF(R20="RON",M20,"") -> DERAYA | V20: A3 | W20: =IFERROR(INDEX($Q$18:$U$167,MATCH(V20,$Q$18:$Q$167,0),MATCH(4,$Q$17:$U$17,0)),"") -> PK-LAI | X20: =IFERROR(INDEX($Q$18:$U$167,MATCH(V20,$Q$18:$Q$167,0),MATCH(3,$Q$17:$U$17,0)),"") -> A 320 | Y20: =IFERROR(INDEX($Q$18:$U$167,MATCH(V20,$Q$18:$Q$167,0),MATCH(5,$Q$17:$U$17,0)),"") -> BATIK AIR | Z20: TRUE | AD20: =IF(D20="","-",D20) -> - | AE20: =IF(F20="","-",F20) -> - | AF20: 0.12569444 | AG20: 0.16666667 | AH20: =COUNTIFS($AD$18:$AD$167,">03:00",$AD$18:$AD$167,"<=04:00") -> 0 | AI20: =COUNTIFS($AE$18:$AE$167,">03:00",$AE$18:$AE$167,"<=04:00") -> 0 | AJ20: =AI20+AH20 -> 0 | AL20: A3 | AM20: =COUNTIFS($H$18:$H$167,AL20,$D$18:$D$167,"<=01:00") -> 0 | AN20: =COUNTIFS($H$18:$H$167,AL20,$D$18:$D$167,">01:00",$D$18:$D$167,"<=02:00") -> 0 | AO20: =COUNTIFS($H$18:$H$167,AL20,$D$18:$D$167,">02:00",$D$18:$D$167,"<=03:00") -> 0 | AP20: =COUNTIFS($H$18:$H$167,AL20,$D$18:$D$167,">03:00",$D$18:$D$167,"<=04:00") -> 0 | AQ20: =COUNTIFS($H$18:$H$167,AL20,$D$18:$D$167,">04:00",$D$18:$D$167,"<=05:00") -> 0 | AR20: =COUNTIFS($H$18:$H$167,AL20,$D$18:$D$167,">05:00",$D$18:$D$167,"<=06:00") -> 0 | AS20: =COUNTIFS($H$18:$H$167,AL20,$D$18:$D$167,">06:00",$D$18:$D$167,"<=07:00") -> 0 | AT20: =COUNTIFS($H$18:$H$167,AL20,$D$18:$D$167,">07:00",$D$18:$D$167,"<=08:00") -> 1 | AU20: =COUNTIFS($H$18:$H$167,AL20,$D$18:$D$167,">08:00",$D$18:$D$167,"<=09:00") -> 0 | AV20: =COUNTIFS($H$18:$H$167,AL20,$D$18:$D$167,">09:00",$D$18:$D$167,"<=10:00") -> 0 | AW20: =COUNTIFS($H$18:$H$167,AL20,$D$18:$D$167,">10:00",$D$18:$D$167,"<=11:00") -> 1 | AX20: =COUNTIFS($H$18:$H$167,AL20,$D$18:$D$167,">11:00",$D$18:$D$167,"<=12:00") -> 1 | AY20: =COUNTIFS($H$18:$H$167,AL20,$D$18:$D$167,">12:00",$D$18:$D$167,"<=13:00") -> 0 | AZ20: =COUNTIFS($H$18:$H$167,AL20,$D$18:$D$167,">13:00",$D$18:$D$167,"<=14:00") -> 0 | BA20: =COUNTIFS($H$18:$H$167,AL20,$D$18:$D$167,">14:00",$D$18:$D$167,"<=15:00") -> 0 | BB20: =COUNTIFS($H$18:$H$167,AL20,$D$18:$D$167,">15:00",$D$18:$D$167,"<=16:00") -> 0 | BC20: =COUNTIFS($H$18:$H$167,AL20,$D$18:$D$167,">16:00",$D$18:$D$167,"<=17:00") -> 1 | BD20: =COUNTIFS($H$18:$H$167,AL20,$D$18:$D$167,">17:00",$D$18:$D$167,"<=18:00") -> 0 | BE20: =COUNTIFS($H$18:$H$167,AL20,$D$18:$D$167,">18:00",$D$18:$D$167,"<=19:00") -> 1 | BF20: =COUNTIFS($H$18:$H$167,AL20,$D$18:$D$167,">19:00",$D$18:$D$167,"<=20:00") -> 0 | BG20: =COUNTIFS($H$18:$H$167,AL20,$D$18:$D$167,">20:00",$D$18:$D$167,"<=21:00") -> 0 | BH20: =COUNTIFS($H$18:$H$167,AL20,$D$18:$D$167,">21:00",$D$18:$D$167,"<=22:00") -> 0 | BI20: =COUNTIFS($H$18:$H$167,AL20,$D$18:$D$167,">22:00",$D$18:$D$167,"<=23:00") -> 0 | BJ20: =COUNTIFS($H$18:$H$167,AL20,$D$18:$D$167,">23:00") -> 0 | BK20: =SUM(AM20:BJ20) -> 5
A21: 4 | B21: PK-RDA | C21: =IF(B21>1,VLOOKUP(B21,DB!$D$4:$E$800,2,0),"") -> HK 900 | D21: - | E21: FALSE | G21: FALSE | H21: NSA04 | I21: =IF(K21>1,VLOOKUP(K21,DB!$A$4:$B$500,2,0),"") | J21: =IF(L21>1,VLOOKUP(L21,DB!$A$4:$B$500,2,0),"") | M21: =IF(B21>1,VLOOKUP(B21,DB!$D$4:$F$800,3,0),"") -> TRI MG | N21: UNSERVICEABLE | O21: =IF(ISBLANK(F21),"RON","") -> RON | Q21: =IF(R21="RON",H21,"") -> NSA04 | R21: =IF(O21="RON",O21,"") -> RON | S21: =IF(R21="RON",C21,"") -> HK 900 | T21: =IF(R21="RON",B21,"") -> PK-RDA | U21: =IF(R21="RON",M21,"") -> TRI MG | V21: B1 | W21: =IFERROR(INDEX($Q$18:$U$167,MATCH(V21,$Q$18:$Q$167,0),MATCH(4,$Q$17:$U$17,0)),"") -> PK-PAH | X21: =IFERROR(INDEX($Q$18:$U$167,MATCH(V21,$Q$18:$Q$167,0),MATCH(3,$Q$17:$U$17,0)),"") -> ATR 72 | Y21: =IFERROR(INDEX($Q$18:$U$167,MATCH(V21,$Q$18:$Q$167,0),MATCH(5,$Q$17:$U$17,0)),"") -> PELITA | Z21: TRUE | AD21: =IF(D21="","-",D21) -> - | AE21: =IF(F21="","-",F21) -> - | AF21: 0.16736111 | AG21: 0.20833333 | AH21: =COUNTIFS($AD$18:$AD$167,">04:00",$AD$18:$AD$167,"<=05:00") -> 3 | AI21: =COUNTIFS($AE$18:$AE$167,">04:00",$AE$18:$AE$167,"<=05:00") -> 1 | AJ21: =AI21+AH21 -> 4 | AL21: B1 | AM21: =COUNTIFS($H$18:$H$167,AL21,$D$18:$D$167,"<=01:00") -> 0 | AN21: =COUNTIFS($H$18:$H$167,AL21,$D$18:$D$167,">01:00",$D$18:$D$167,"<=02:00") -> 0 | AO21: =COUNTIFS($H$18:$H$167,AL21,$D$18:$D$167,">02:00",$D$18:$D$167,"<=03:00") -> 0 | AP21: =COUNTIFS($H$18:$H$167,AL21,$D$18:$D$167,">03:00",$D$18:$D$167,"<=04:00") -> 0 | AQ21: =COUNTIFS($H$18:$H$167,AL21,$D$18:$D$167,">04:00",$D$18:$D$167,"<=05:00") -> 0 | AR21: =COUNTIFS($H$18:$H$167,AL21,$D$18:$D$167,">05:00",$D$18:$D$167,"<=06:00") -> 0 | AS21: =COUNTIFS($H$18:$H$167,AL21,$D$18:$D$167,">06:00",$D$18:$D$167,"<=07:00") -> 0 | AT21: =COUNTIFS($H$18:$H$167,AL21,$D$18:$D$167,">07:00",$D$18:$D$167,"<=08:00") -> 0 | AU21: =COUNTIFS($H$18:$H$167,AL21,$D$18:$D$167,">08:00",$D$18:$D$167,"<=09:00") -> 1 | AV21: =COUNTIFS($H$18:$H$167,AL21,$D$18:$D$167,">09:00",$D$18:$D$167,"<=10:00") -> 0 | AW21: =COUNTIFS($H$18:$H$167,AL21,$D$18:$D$167,">10:00",$D$18:$D$167,"<=11:00") -> 0 | AX21: =COUNTIFS($H$18:$H$167,AL21,$D$18:$D$167,">11:00",$D$18:$D$167,"<=12:00") -> 1 | AY21: =COUNTIFS($H$18:$H$167,AL21,$D$18:$D$167,">12:00",$D$18:$D$167,"<=13:00") -> 1 | AZ21: =COUNTIFS($H$18:$H$167,AL21,$D$18:$D$167,">13:00",$D$18:$D$167,"<=14:00") -> 0 | BA21: =COUNTIFS($H$18:$H$167,AL21,$D$18:$D$167,">14:00",$D$18:$D$167,"<=15:00") -> 1 | BB21: =COUNTIFS($H$18:$H$167,AL21,$D$18:$D$167,">15:00",$D$18:$D$167,"<=16:00") -> 0 | BC21: =COUNTIFS($H$18:$H$167,AL21,$D$18:$D$167,">16:00",$D$18:$D$167,"<=17:00") -> 1 | BD21: =COUNTIFS($H$18:$H$167,AL21,$D$18:$D$167,">17:00",$D$18:$D$167,"<=18:00") -> 0 | BE21: =COUNTIFS($H$18:$H$167,AL21,$D$18:$D$167,">18:00",$D$18:$D$167,"<=19:00") -> 1 | BF21: =COUNTIFS($H$18:$H$167,AL21,$D$18:$D$167,">19:00",$D$18:$D$167,"<=20:00") -> 0 | BG21: =COUNTIFS($H$18:$H$167,AL21,$D$18:$D$167,">20:00",$D$18:$D$167,"<=21:00") -> 0 | BH21: =COUNTIFS($H$18:$H$167,AL21,$D$18:$D$167,">21:00",$D$18:$D$167,"<=22:00") -> 0 | BI21: =COUNTIFS($H$18:$H$167,AL21,$D$18:$D$167,">22:00",$D$18:$D$167,"<=23:00") -> 0 | BJ21: =COUNTIFS($H$18:$H$167,AL21,$D$18:$D$167,">23:00") -> 0 | BK21: =SUM(AM21:BJ21) -> 6
A22: 5 | B22: PK-YGK | C22: =IF(B22>1,VLOOKUP(B22,DB!$D$4:$E$800,2,0),"") -> HK 400 | D22: - | E22: FALSE | G22: FALSE | H22: NSA05 | I22: =IF(K22>1,VLOOKUP(K22,DB!$A$4:$B$500,2,0),"") | J22: =IF(L22>1,VLOOKUP(L22,DB!$A$4:$B$500,2,0),"") | M22: =IF(B22>1,VLOOKUP(B22,DB!$D$4:$F$800,3,0),"") -> TRI MG | N22: UNSERVICEABLE | O22: =IF(ISBLANK(F22),"RON","") -> RON | Q22: =IF(R22="RON",H22,"") -> NSA05 | R22: =IF(O22="RON",O22,"") -> RON | S22: =IF(R22="RON",C22,"") -> HK 400 | T22: =IF(R22="RON",B22,"") -> PK-YGK | U22: =IF(R22="RON",M22,"") -> TRI MG | V22: B2 | W22: =IFERROR(INDEX($Q$18:$U$167,MATCH(V22,$Q$18:$Q$167,0),MATCH(4,$Q$17:$U$17,0)),"") -> PK-GMY | X22: =IFERROR(INDEX($Q$18:$U$167,MATCH(V22,$Q$18:$Q$167,0),MATCH(3,$Q$17:$U$17,0)),"") -> B 738 | Y22: =IFERROR(INDEX($Q$18:$U$167,MATCH(V22,$Q$18:$Q$167,0),MATCH(5,$Q$17:$U$17,0)),"") -> GARUDA | Z22: TRUE | AD22: =IF(D22="","-",D22) -> - | AE22: =IF(F22="","-",F22) -> - | AF22: 0.20902778 | AG22: 0.25 | AH22: =COUNTIFS($AD$18:$AD$167,">05:00",$AD$18:$AD$167,"<=06:00") -> 2 | AI22: =COUNTIFS($AE$18:$AE$167,">05:00",$AE$18:$AE$167,"<=06:00") -> 7 | AJ22: =AI22+AH22 -> 9 | AL22: B2 | AM22: =COUNTIFS($H$18:$H$167,AL22,$D$18:$D$167,"<=01:00") -> 0 | AN22: =COUNTIFS($H$18:$H$167,AL22,$D$18:$D$167,">01:00",$D$18:$D$167,"<=02:00") -> 0 | AO22: =COUNTIFS($H$18:$H$167,AL22,$D$18:$D$167,">02:00",$D$18:$D$167,"<=03:00") -> 0 | AP22: =COUNTIFS($H$18:$H$167,AL22,$D$18:$D$167,">03:00",$D$18:$D$167,"<=04:00") -> 0 | AQ22: =COUNTIFS($H$18:$H$167,AL22,$D$18:$D$167,">04:00",$D$18:$D$167,"<=05:00") -> 0 | AR22: =COUNTIFS($H$18:$H$167,AL22,$D$18:$D$167,">05:00",$D$18:$D$167,"<=06:00") -> 0 | AS22: =COUNTIFS($H$18:$H$167,AL22,$D$18:$D$167,">06:00",$D$18:$D$167,"<=07:00") -> 0 | AT22: =COUNTIFS($H$18:$H$167,AL22,$D$18:$D$167,">07:00",$D$18:$D$167,"<=08:00") -> 0 | AU22: =COUNTIFS($H$18:$H$167,AL22,$D$18:$D$167,">08:00",$D$18:$D$167,"<=09:00") -> 0 | AV22: =COUNTIFS($H$18:$H$167,AL22,$D$18:$D$167,">09:00",$D$18:$D$167,"<=10:00") -> 2 | AW22: =COUNTIFS($H$18:$H$167,AL22,$D$18:$D$167,">10:00",$D$18:$D$167,"<=11:00") -> 0 | AX22: =COUNTIFS($H$18:$H$167,AL22,$D$18:$D$167,">11:00",$D$18:$D$167,"<=12:00") -> 1 | AY22: =COUNTIFS($H$18:$H$167,AL22,$D$18:$D$167,">12:00",$D$18:$D$167,"<=13:00") -> 0 | AZ22: =COUNTIFS($H$18:$H$167,AL22,$D$18:$D$167,">13:00",$D$18:$D$167,"<=14:00") -> 1 | BA22: =COUNTIFS($H$18:$H$167,AL22,$D$18:$D$167,">14:00",$D$18:$D$167,"<=15:00") -> 0 | BB22: =COUNTIFS($H$18:$H$167,AL22,$D$18:$D$167,">15:00",$D$18:$D$167,"<=16:00") -> 0 | BC22: =COUNTIFS($H$18:$H$167,AL22,$D$18:$D$167,">16:00",$D$18:$D$167,"<=17:00") -> 1 | BD22: =COUNTIFS($H$18:$H$167,AL22,$D$18:$D$167,">17:00",$D$18:$D$167,"<=18:00") -> 0 | BE22: =COUNTIFS($H$18:$H$167,AL22,$D$18:$D$167,">18:00",$D$18:$D$167,"<=19:00") -> 0 | BF22: =COUNTIFS($H$18:$H$167,AL22,$D$18:$D$167,">19:00",$D$18:$D$167,"<=20:00") -> 1 | BG22: =COUNTIFS($H$18:$H$167,AL22,$D$18:$D$167,">20:00",$D$18:$D$167,"<=21:00") -> 0 | BH22: =COUNTIFS($H$18:$H$167,AL22,$D$18:$D$167,">21:00",$D$18:$D$167,"<=22:00") -> 0 | BI22: =COUNTIFS($H$18:$H$167,AL22,$D$18:$D$167,">22:00",$D$18:$D$167,"<=23:00") -> 0 | BJ22: =COUNTIFS($H$18:$H$167,AL22,$D$18:$D$167,">23:00") -> 0 | BK22: =SUM(AM22:BJ22) -> 6
A23: 6 | B23: N-484BA | C23: =IF(B23>1,VLOOKUP(B23,DB!$D$4:$E$800,2,0),"") -> LJ 31 | D23: - | E23: FALSE | G23: FALSE | H23: NSA06 | I23: =IF(K23>1,VLOOKUP(K23,DB!$A$4:$B$500,2,0),"") | J23: =IF(L23>1,VLOOKUP(L23,DB!$A$4:$B$500,2,0),"") | M23: =IF(B23>1,VLOOKUP(B23,DB!$D$4:$F$800,3,0),"") -> IAP | N23: UNSERVICEABLE | O23: =IF(ISBLANK(F23),"RON","") -> RON | Q23: =IF(R23="RON",H23,"") -> NSA06 | R23: =IF(O23="RON",O23,"") -> RON | S23: =IF(R23="RON",C23,"") -> LJ 31 | T23: =IF(R23="RON",B23,"") -> N-484BA | U23: =IF(R23="RON",M23,"") -> IAP | V23: B3 | W23: =IFERROR(INDEX($Q$18:$U$167,MATCH(V23,$Q$18:$Q$167,0),MATCH(4,$Q$17:$U$17,0)),"") -> PK-GTD | X23: =IFERROR(INDEX($Q$18:$U$167,MATCH(V23,$Q$18:$Q$167,0),MATCH(3,$Q$17:$U$17,0)),"") -> A 320 | Y23: =IFERROR(INDEX($Q$18:$U$167,MATCH(V23,$Q$18:$Q$167,0),MATCH(5,$Q$17:$U$17,0)),"") -> CITILINK | Z23: TRUE | AD23: =IF(D23="","-",D23) -> - | AE23: =IF(F23="","-",F23) -> - | AF23: 0.25069444 | AG23: 0.29166667 | AH23: =COUNTIFS($AD$18:$AD$167,">06:00",$AD$18:$AD$167,"<=07:00") -> 5 | AI23: =COUNTIFS($AE$18:$AE$167,">06:00",$AE$18:$AE$167,"<=07:00") -> 6 | AJ23: =AI23+AH23 -> 11 | AL23: B3 | AM23: =COUNTIFS($H$18:$H$167,AL23,$D$18:$D$167,"<=01:00") -> 0 | AN23: =COUNTIFS($H$18:$H$167,AL23,$D$18:$D$167,">01:00",$D$18:$D$167,"<=02:00") -> 0 | AO23: =COUNTIFS($H$18:$H$167,AL23,$D$18:$D$167,">02:00",$D$18:$D$167,"<=03:00") -> 0 | AP23: =COUNTIFS($H$18:$H$167,AL23,$D$18:$D$167,">03:00",$D$18:$D$167,"<=04:00") -> 0 | AQ23: =COUNTIFS($H$18:$H$167,AL23,$D$18:$D$167,">04:00",$D$18:$D$167,"<=05:00") -> 0 | AR23: =COUNTIFS($H$18:$H$167,AL23,$D$18:$D$167,">05:00",$D$18:$D$167,"<=06:00") -> 0 | AS23: =COUNTIFS($H$18:$H$167,AL23,$D$18:$D$167,">06:00",$D$18:$D$167,"<=07:00") -> 1 | AT23: =COUNTIFS($H$18:$H$167,AL23,$D$18:$D$167,">07:00",$D$18:$D$167,"<=08:00") -> 0 | AU23: =COUNTIFS($H$18:$H$167,AL23,$D$18:$D$167,">08:00",$D$18:$D$167,"<=09:00") -> 0 | AV23: =COUNTIFS($H$18:$H$167,AL23,$D$18:$D$167,">09:00",$D$18:$D$167,"<=10:00") -> 0 | AW23: =COUNTIFS($H$18:$H$167,AL23,$D$18:$D$167,">10:00",$D$18:$D$167,"<=11:00") -> 0 | AX23: =COUNTIFS($H$18:$H$167,AL23,$D$18:$D$167,">11:00",$D$18:$D$167,"<=12:00") -> 0 | AY23: =COUNTIFS($H$18:$H$167,AL23,$D$18:$D$167,">12:00",$D$18:$D$167,"<=13:00") -> 0 | AZ23: =COUNTIFS($H$18:$H$167,AL23,$D$18:$D$167,">13:00",$D$18:$D$167,"<=14:00") -> 0 | BA23: =COUNTIFS($H$18:$H$167,AL23,$D$18:$D$167,">14:00",$D$18:$D$167,"<=15:00") -> 0 | BB23: =COUNTIFS($H$18:$H$167,AL23,$D$18:$D$167,">15:00",$D$18:$D$167,"<=16:00") -> 0 | BC23: =COUNTIFS($H$18:$H$167,AL23,$D$18:$D$167,">16:00",$D$18:$D$167,"<=17:00") -> 0 | BD23: =COUNTIFS($H$18:$H$167,AL23,$D$18:$D$167,">17:00",$D$18:$D$167,"<=18:00") -> 0 | BE23: =COUNTIFS($H$18:$H$167,AL23,$D$18:$D$167,">18:00",$D$18:$D$167,"<=19:00") -> 0 | BF23: =COUNTIFS($H$18:$H$167,AL23,$D$18:$D$167,">19:00",$D$18:$D$167,"<=20:00") -> 0 | BG23: =COUNTIFS($H$18:$H$167,AL23,$D$18:$D$167,">20:00",$D$18:$D$167,"<=21:00") -> 0 | BH23: =COUNTIFS($H$18:$H$167,AL23,$D$18:$D$167,">21:00",$D$18:$D$167,"<=22:00") -> 1 | BI23: =COUNTIFS($H$18:$H$167,AL23,$D$18:$D$167,">22:00",$D$18:$D$167,"<=23:00") -> 0 | BJ23: =COUNTIFS($H$18:$H$167,AL23,$D$18:$D$167,">23:00") -> 0 | BK23: =SUM(AM23:BJ23) -> 2
A24: 7 | B24: N-2409K | C24: =IF(B24>1,VLOOKUP(B24,DB!$D$4:$E$800,2,0),"") -> HK 800 | D24: - | E24: FALSE | G24: FALSE | H24: NSA07 | I24: =IF(K24>1,VLOOKUP(K24,DB!$A$4:$B$500,2,0),"") | J24: =IF(L24>1,VLOOKUP(L24,DB!$A$4:$B$500,2,0),"") | M24: TAS | O24: =IF(ISBLANK(F24),"RON","") -> RON | Q24: =IF(R24="RON",H24,"") -> NSA07 | R24: =IF(O24="RON",O24,"") -> RON | S24: =IF(R24="RON",C24,"") -> HK 800 | T24: =IF(R24="RON",B24,"") -> N-2409K | U24: =IF(R24="RON",M24,"") -> TAS | V24: B4 | W24: =IFERROR(INDEX($Q$18:$U$167,MATCH(V24,$Q$18:$Q$167,0),MATCH(4,$Q$17:$U$17,0)),"") | X24: =IFERROR(INDEX($Q$18:$U$167,MATCH(V24,$Q$18:$Q$167,0),MATCH(3,$Q$17:$U$17,0)),"") | Y24: =IFERROR(INDEX($Q$18:$U$167,MATCH(V24,$Q$18:$Q$167,0),MATCH(5,$Q$17:$U$17,0)),"") | Z24: FALSE | AD24: =IF(D24="","-",D24) -> - | AE24: =IF(F24="","-",F24) -> - | AF24: 0.29236111 | AG24: 0.33333333 | AH24: =COUNTIFS($AD$18:$AD$167,">07:00",$AD$18:$AD$167,"<=08:00") -> 4 | AI24: =COUNTIFS($AE$18:$AE$167,">07:00",$AE$18:$AE$167,"<=08:00") -> 4 | AJ24: =AI24+AH24 -> 8 | AL24: B4 | AM24: =COUNTIFS($H$18:$H$167,AL24,$D$18:$D$167,"<=01:00") -> 0 | AN24: =COUNTIFS($H$18:$H$167,AL24,$D$18:$D$167,">01:00",$D$18:$D$167,"<=02:00") -> 0 | AO24: =COUNTIFS($H$18:$H$167,AL24,$D$18:$D$167,">02:00",$D$18:$D$167,"<=03:00") -> 0 | AP24: =COUNTIFS($H$18:$H$167,AL24,$D$18:$D$167,">03:00",$D$18:$D$167,"<=04:00") -> 0 | AQ24: =COUNTIFS($H$18:$H$167,AL24,$D$18:$D$167,">04:00",$D$18:$D$167,"<=05:00") -> 0 | AR24: =COUNTIFS($H$18:$H$167,AL24,$D$18:$D$167,">05:00",$D$18:$D$167,"<=06:00") -> 0 | AS24: =COUNTIFS($H$18:$H$167,AL24,$D$18:$D$167,">06:00",$D$18:$D$167,"<=07:00") -> 0 | AT24: =COUNTIFS($H$18:$H$167,AL24,$D$18:$D$167,">07:00",$D$18:$D$167,"<=08:00") -> 1 | AU24: =COUNTIFS($H$18:$H$167,AL24,$D$18:$D$167,">08:00",$D$18:$D$167,"<=09:00") -> 0 | AV24: =COUNTIFS($H$18:$H$167,AL24,$D$18:$D$167,">09:00",$D$18:$D$167,"<=10:00") -> 0 | AW24: =COUNTIFS($H$18:$H$167,AL24,$D$18:$D$167,">10:00",$D$18:$D$167,"<=11:00") -> 0 | AX24: =COUNTIFS($H$18:$H$167,AL24,$D$18:$D$167,">11:00",$D$18:$D$167,"<=12:00") -> 0 | AY24: =COUNTIFS($H$18:$H$167,AL24,$D$18:$D$167,">12:00",$D$18:$D$167,"<=13:00") -> 0 | AZ24: =COUNTIFS($H$18:$H$167,AL24,$D$18:$D$167,">13:00",$D$18:$D$167,"<=14:00") -> 1 | BA24: =COUNTIFS($H$18:$H$167,AL24,$D$18:$D$167,">14:00",$D$18:$D$167,"<=15:00") -> 0 | BB24: =COUNTIFS($H$18:$H$167,AL24,$D$18:$D$167,">15:00",$D$18:$D$167,"<=16:00") -> 0 | BC24: =COUNTIFS($H$18:$H$167,AL24,$D$18:$D$167,">16:00",$D$18:$D$167,"<=17:00") -> 0 | BD24: =COUNTIFS($H$18:$H$167,AL24,$D$18:$D$167,">17:00",$D$18:$D$167,"<=18:00") -> 0 | BE24: =COUNTIFS($H$18:$H$167,AL24,$D$18:$D$167,">18:00",$D$18:$D$167,"<=19:00") -> 1 | BF24: =COUNTIFS($H$18:$H$167,AL24,$D$18:$D$167,">19:00",$D$18:$D$167,"<=20:00") -> 0 | BG24: =COUNTIFS($H$18:$H$167,AL24,$D$18:$D$167,">20:00",$D$18:$D$167,"<=21:00") -> 1 | BH24: =COUNTIFS($H$18:$H$167,AL24,$D$18:$D$167,">21:00",$D$18:$D$167,"<=22:00") -> 0 | BI24: =COUNTIFS($H$18:$H$167,AL24,$D$18:$D$167,">22:00",$D$18:$D$167,"<=23:00") -> 0 | BJ24: =COUNTIFS($H$18:$H$167,AL24,$D$18:$D$167,">23:00") -> 0 | BK24: =SUM(AM24:BJ24) -> 4
A25: 8 | B25: N-38SV | C25: =IF(B25>1,VLOOKUP(B25,DB!$D$4:$E$800,2,0),"") -> LJ 60 | D25: - | E25: FALSE | G25: FALSE | H25: NSA10 | I25: =IF(K25>1,VLOOKUP(K25,DB!$A$4:$B$500,2,0),"") | J25: =IF(L25>1,VLOOKUP(L25,DB!$A$4:$B$500,2,0),"") | M25: B. G. S. | O25: =IF(ISBLANK(F25),"RON","") -> RON | Q25: =IF(R25="RON",H25,"") -> NSA10 | R25: =IF(O25="RON",O25,"") -> RON | S25: =IF(R25="RON",C25,"") -> LJ 60 | T25: =IF(R25="RON",B25,"") -> N-38SV | U25: =IF(R25="RON",M25,"") -> B. G. S. | V25: B5 | W25: =IFERROR(INDEX($Q$18:$U$167,MATCH(V25,$Q$18:$Q$167,0),MATCH(4,$Q$17:$U$17,0)),"") | X25: =IFERROR(INDEX($Q$18:$U$167,MATCH(V25,$Q$18:$Q$167,0),MATCH(3,$Q$17:$U$17,0)),"") | Y25: =IFERROR(INDEX($Q$18:$U$167,MATCH(V25,$Q$18:$Q$167,0),MATCH(5,$Q$17:$U$17,0)),"") | Z25: FALSE | AD25: =IF(D25="","-",D25) -> - | AE25: =IF(F25="","-",F25) -> - | AF25: 0.33402778 | AG25: 0.375 | AH25: =COUNTIFS($AD$18:$AD$167,">08:00",$AD$18:$AD$167,"<=09:00") -> 3 | AI25: =COUNTIFS($AE$18:$AE$167,">08:00",$AE$18:$AE$167,"<=09:00") -> 6 | AJ25: =AI25+AH25 -> 9 | AL25: B5 | AM25: =COUNTIFS($H$18:$H$167,AL25,$D$18:$D$167,"<=01:00") -> 0 | AN25: =COUNTIFS($H$18:$H$167,AL25,$D$18:$D$167,">01:00",$D$18:$D$167,"<=02:00") -> 0 | AO25: =COUNTIFS($H$18:$H$167,AL25,$D$18:$D$167,">02:00",$D$18:$D$167,"<=03:00") -> 0 | AP25: =COUNTIFS($H$18:$H$167,AL25,$D$18:$D$167,">03:00",$D$18:$D$167,"<=04:00") -> 0 | AQ25: =COUNTIFS($H$18:$H$167,AL25,$D$18:$D$167,">04:00",$D$18:$D$167,"<=05:00") -> 0 | AR25: =COUNTIFS($H$18:$H$167,AL25,$D$18:$D$167,">05:00",$D$18:$D$167,"<=06:00") -> 1 | AS25: =COUNTIFS($H$18:$H$167,AL25,$D$18:$D$167,">06:00",$D$18:$D$167,"<=07:00") -> 0 | AT25: =COUNTIFS($H$18:$H$167,AL25,$D$18:$D$167,">07:00",$D$18:$D$167,"<=08:00") -> 0 | AU25: =COUNTIFS($H$18:$H$167,AL25,$D$18:$D$167,">08:00",$D$18:$D$167,"<=09:00") -> 0 | AV25: =COUNTIFS($H$18:$H$167,AL25,$D$18:$D$167,">09:00",$D$18:$D$167,"<=10:00") -> 1 | AW25: =COUNTIFS($H$18:$H$167,AL25,$D$18:$D$167,">10:00",$D$18:$D$167,"<=11:00") -> 0 | AX25: =COUNTIFS($H$18:$H$167,AL25,$D$18:$D$167,">11:00",$D$18:$D$167,"<=12:00") -> 0 | AY25: =COUNTIFS($H$18:$H$167,AL25,$D$18:$D$167,">12:00",$D$18:$D$167,"<=13:00") -> 1 | AZ25: =COUNTIFS($H$18:$H$167,AL25,$D$18:$D$167,">13:00",$D$18:$D$167,"<=14:00") -> 0 | BA25: =COUNTIFS($H$18:$H$167,AL25,$D$18:$D$167,">14:00",$D$18:$D$167,"<=15:00") -> 0 | BB25: =COUNTIFS($H$18:$H$167,AL25,$D$18:$D$167,">15:00",$D$18:$D$167,"<=16:00") -> 0 | BC25: =COUNTIFS($H$18:$H$167,AL25,$D$18:$D$167,">16:00",$D$18:$D$167,"<=17:00") -> 0 | BD25: =COUNTIFS($H$18:$H$167,AL25,$D$18:$D$167,">17:00",$D$18:$D$167,"<=18:00") -> 0 | BE25: =COUNTIFS($H$18:$H$167,AL25,$D$18:$D$167,">18:00",$D$18:$D$167,"<=19:00") -> 0 | BF25: =COUNTIFS($H$18:$H$167,AL25,$D$18:$D$167,">19:00",$D$18:$D$167,"<=20:00") -> 0 | BG25: =COUNTIFS($H$18:$H$167,AL25,$D$18:$D$167,">20:00",$D$18:$D$167,"<=21:00") -> 0 | BH25: =COUNTIFS($H$18:$H$167,AL25,$D$18:$D$167,">21:00",$D$18:$D$167,"<=22:00") -> 0 | BI25: =COUNTIFS($H$18:$H$167,AL25,$D$18:$D$167,">22:00",$D$18:$D$167,"<=23:00") -> 1 | BJ25: =COUNTIFS($H$18:$H$167,AL25,$D$18:$D$167,">23:00") -> 0 | BK25: =SUM(AM25:BJ25) -> 4
A26: 9 | B26: T7-TUN | C26: =IF(B26>1,VLOOKUP(B26,DB!$D$4:$E$800,2,0),"") -> HK 850 | D26: - | E26: FALSE | G26: FALSE | H26: NSA11 | I26: =IF(K26>1,VLOOKUP(K26,DB!$A$4:$B$500,2,0),"") | J26: =IF(L26>1,VLOOKUP(L26,DB!$A$4:$B$500,2,0),"") | M26: KARISMA | O26: =IF(ISBLANK(F26),"RON","") -> RON | Q26: =IF(R26="RON",H26,"") -> NSA11 | R26: =IF(O26="RON",O26,"") -> RON | S26: =IF(R26="RON",C26,"") -> HK 850 | T26: =IF(R26="RON",B26,"") -> T7-TUN | U26: =IF(R26="RON",M26,"") -> KARISMA | V26: B6 | W26: =IFERROR(INDEX($Q$18:$U$167,MATCH(V26,$Q$18:$Q$167,0),MATCH(4,$Q$17:$U$17,0)),"") -> PK-GJT | X26: =IFERROR(INDEX($Q$18:$U$167,MATCH(V26,$Q$18:$Q$167,0),MATCH(3,$Q$17:$U$17,0)),"") -> ATR 72 | Y26: =IFERROR(INDEX($Q$18:$U$167,MATCH(V26,$Q$18:$Q$167,0),MATCH(5,$Q$17:$U$17,0)),"") -> CITILINK | Z26: TRUE | AD26: =IF(D26="","-",D26) -> - | AE26: =IF(F26="","-",F26) -> - | AF26: 0.37569444 | AG26: 0.41666667 | AH26: =COUNTIFS($AD$18:$AD$167,">09:00",$AD$18:$AD$167,"<=10:00") -> 4 | AI26: =COUNTIFS($AE$18:$AE$167,">09:00",$AE$18:$AE$167,"<=10:00") -> 5 | AJ26: =AI26+AH26 -> 9 | AL26: B6 | AM26: =COUNTIFS($H$18:$H$167,AL26,$D$18:$D$167,"<=01:00") -> 0 | AN26: =COUNTIFS($H$18:$H$167,AL26,$D$18:$D$167,">01:00",$D$18:$D$167,"<=02:00") -> 0 | AO26: =COUNTIFS($H$18:$H$167,AL26,$D$18:$D$167,">02:00",$D$18:$D$167,"<=03:00") -> 0 | AP26: =COUNTIFS($H$18:$H$167,AL26,$D$18:$D$167,">03:00",$D$18:$D$167,"<=04:00") -> 0 | AQ26: =COUNTIFS($H$18:$H$167,AL26,$D$18:$D$167,">04:00",$D$18:$D$167,"<=05:00") -> 1 | AR26: =COUNTIFS($H$18:$H$167,AL26,$D$18:$D$167,">05:00",$D$18:$D$167,"<=06:00") -> 0 | AS26: =COUNTIFS($H$18:$H$167,AL26,$D$18:$D$167,">06:00",$D$18:$D$167,"<=07:00") -> 0 | AT26: =COUNTIFS($H$18:$H$167,AL26,$D$18:$D$167,">07:00",$D$18:$D$167,"<=08:00") -> 0 | AU26: =COUNTIFS($H$18:$H$167,AL26,$D$18:$D$167,">08:00",$D$18:$D$167,"<=09:00") -> 0 | AV26: =COUNTIFS($H$18:$H$167,AL26,$D$18:$D$167,">09:00",$D$18:$D$167,"<=10:00") -> 0 | AW26: =COUNTIFS($H$18:$H$167,AL26,$D$18:$D$167,">10:00",$D$18:$D$167,"<=11:00") -> 0 | AX26: =COUNTIFS($H$18:$H$167,AL26,$D$18:$D$167,">11:00",$D$18:$D$167,"<=12:00") -> 1 | AY26: =COUNTIFS($H$18:$H$167,AL26,$D$18:$D$167,">12:00",$D$18:$D$167,"<=13:00") -> 0 | AZ26: =COUNTIFS($H$18:$H$167,AL26,$D$18:$D$167,">13:00",$D$18:$D$167,"<=14:00") -> 1 | BA26: =COUNTIFS($H$18:$H$167,AL26,$D$18:$D$167,">14:00",$D$18:$D$167,"<=15:00") -> 0 | BB26: =COUNTIFS($H$18:$H$167,AL26,$D$18:$D$167,">15:00",$D$18:$D$167,"<=16:00") -> 0 | BC26: =COUNTIFS($H$18:$H$167,AL26,$D$18:$D$167,">16:00",$D$18:$D$167,"<=17:00") -> 0 | BD26: =COUNTIFS($H$18:$H$167,AL26,$D$18:$D$167,">17:00",$D$18:$D$167,"<=18:00") -> 0 | BE26: =COUNTIFS($H$18:$H$167,AL26,$D$18:$D$167,">18:00",$D$18:$D$167,"<=19:00") -> 0 | BF26: =COUNTIFS($H$18:$H$167,AL26,$D$18:$D$167,">19:00",$D$18:$D$167,"<=20:00") -> 0 | BG26: =COUNTIFS($H$18:$H$167,AL26,$D$18:$D$167,">20:00",$D$18:$D$167,"<=21:00") -> 0 | BH26: =COUNTIFS($H$18:$H$167,AL26,$D$18:$D$167,">21:00",$D$18:$D$167,"<=22:00") -> 0 | BI26: =COUNTIFS($H$18:$H$167,AL26,$D$18:$D$167,">22:00",$D$18:$D$167,"<=23:00") -> 0 | BJ26: =COUNTIFS($H$18:$H$167,AL26,$D$18:$D$167,">23:00") -> 0 | BK26: =SUM(AM26:BJ26) -> 3
A27: 10 | B27: PK-RJH | C27: =IF(B27>1,VLOOKUP(B27,DB!$D$4:$E$800,2,0),"") -> EC 135 | D27: - | E27: FALSE | G27: FALSE | H27: SA01 | I27: =IF(K27>1,VLOOKUP(K27,DB!$A$4:$B$500,2,0),"") | J27: =IF(L27>1,VLOOKUP(L27,DB!$A$4:$B$500,2,0),"") | M27: PREMI | O27: =IF(ISBLANK(F27),"RON","") -> RON | Q27: =IF(R27="RON",H27,"") -> SA01 | R27: =IF(O27="RON",O27,"") -> RON | S27: =IF(R27="RON",C27,"") -> EC 135 | T27: =IF(R27="RON",B27,"") -> PK-RJH | U27: =IF(R27="RON",M27,"") -> PREMI | V27: B7 | W27: =IFERROR(INDEX($Q$18:$U$167,MATCH(V27,$Q$18:$Q$167,0),MATCH(4,$Q$17:$U$17,0)),"") -> T7-187 | X27: =IFERROR(INDEX($Q$18:$U$167,MATCH(V27,$Q$18:$Q$167,0),MATCH(3,$Q$17:$U$17,0)),"") -> EMB 135 | Y27: =IFERROR(INDEX($Q$18:$U$167,MATCH(V27,$Q$18:$Q$167,0),MATCH(5,$Q$17:$U$17,0)),"") -> AFM | Z27: TRUE | AD27: =IF(D27="","-",D27) -> - | AE27: =IF(F27="","-",F27) -> - | AF27: 0.41736111 | AG27: 0.45833333 | AH27: =COUNTIFS($AD$18:$AD$167,">10:00",$AD$18:$AD$167,"<=11:00") -> 3 | AI27: =COUNTIFS($AE$18:$AE$167,">10:00",$AE$18:$AE$167,"<=11:00") -> 3 | AJ27: =AI27+AH27 -> 6 | AL27: B7 | AM27: =COUNTIFS($H$18:$H$167,AL27,$D$18:$D$167,"<=01:00") -> 0 | AN27: =COUNTIFS($H$18:$H$167,AL27,$D$18:$D$167,">01:00",$D$18:$D$167,"<=02:00") -> 0 | AO27: =COUNTIFS($H$18:$H$167,AL27,$D$18:$D$167,">02:00",$D$18:$D$167,"<=03:00") -> 0 | AP27: =COUNTIFS($H$18:$H$167,AL27,$D$18:$D$167,">03:00",$D$18:$D$167,"<=04:00") -> 0 | AQ27: =COUNTIFS($H$18:$H$167,AL27,$D$18:$D$167,">04:00",$D$18:$D$167,"<=05:00") -> 0 | AR27: =COUNTIFS($H$18:$H$167,AL27,$D$18:$D$167,">05:00",$D$18:$D$167,"<=06:00") -> 0 | AS27: =COUNTIFS($H$18:$H$167,AL27,$D$18:$D$167,">06:00",$D$18:$D$167,"<=07:00") -> 1 | AT27: =COUNTIFS($H$18:$H$167,AL27,$D$18:$D$167,">07:00",$D$18:$D$167,"<=08:00") -> 0 | AU27: =COUNTIFS($H$18:$H$167,AL27,$D$18:$D$167,">08:00",$D$18:$D$167,"<=09:00") -> 1 | AV27: =COUNTIFS($H$18:$H$167,AL27,$D$18:$D$167,">09:00",$D$18:$D$167,"<=10:00") -> 0 | AW27: =COUNTIFS($H$18:$H$167,AL27,$D$18:$D$167,">10:00",$D$18:$D$167,"<=11:00") -> 0 | AX27: =COUNTIFS($H$18:$H$167,AL27,$D$18:$D$167,">11:00",$D$18:$D$167,"<=12:00") -> 0 | AY27: =COUNTIFS($H$18:$H$167,AL27,$D$18:$D$167,">12:00",$D$18:$D$167,"<=13:00") -> 0 | AZ27: =COUNTIFS($H$18:$H$167,AL27,$D$18:$D$167,">13:00",$D$18:$D$167,"<=14:00") -> 1 | BA27: =COUNTIFS($H$18:$H$167,AL27,$D$18:$D$167,">14:00",$D$18:$D$167,"<=15:00") -> 0 | BB27: =COUNTIFS($H$18:$H$167,AL27,$D$18:$D$167,">15:00",$D$18:$D$167,"<=16:00") -> 1 | BC27: =COUNTIFS($H$18:$H$167,AL27,$D$18:$D$167,">16:00",$D$18:$D$167,"<=17:00") -> 0 | BD27: =COUNTIFS($H$18:$H$167,AL27,$D$18:$D$167,">17:00",$D$18:$D$167,"<=18:00") -> 0 | BE27: =COUNTIFS($H$18:$H$167,AL27,$D$18:$D$167,">18:00",$D$18:$D$167,"<=19:00") -> 0 | BF27: =COUNTIFS($H$18:$H$167,AL27,$D$18:$D$167,">19:00",$D$18:$D$167,"<=20:00") -> 0 | BG27: =COUNTIFS($H$18:$H$167,AL27,$D$18:$D$167,">20:00",$D$18:$D$167,"<=21:00") -> 1 | BH27: =COUNTIFS($H$18:$H$167,AL27,$D$18:$D$167,">21:00",$D$18:$D$167,"<=22:00") -> 0 | BI27: =COUNTIFS($H$18:$H$167,AL27,$D$18:$D$167,">22:00",$D$18:$D$167,"<=23:00") -> 0 | BJ27: =COUNTIFS($H$18:$H$167,AL27,$D$18:$D$167,">23:00") -> 0 | BK27: =SUM(AM27:BJ27) -> 5
A28: 11 | B28: N-227GV | C28: =IF(B28>1,VLOOKUP(B28,DB!$D$4:$E$800,2,0),"") -> L 1000 | D28: - | E28: FALSE | G28: FALSE | H28: SA03 | I28: =IF(K28>1,VLOOKUP(K28,DB!$A$4:$B$500,2,0),"") | J28: =IF(L28>1,VLOOKUP(L28,DB!$A$4:$B$500,2,0),"") | M28: =IF(B28>1,VLOOKUP(B28,DB!$D$4:$F$800,3,0),"") -> PREMI | O28: =IF(ISBLANK(F28),"RON","") -> RON | Q28: =IF(R28="RON",H28,"") -> SA03 | R28: =IF(O28="RON",O28,"") -> RON | S28: =IF(R28="RON",C28,"") -> L 1000 | T28: =IF(R28="RON",B28,"") -> N-227GV | U28: =IF(R28="RON",M28,"") -> PREMI | V28: B8 | W28: =IFERROR(INDEX($Q$18:$U$167,MATCH(V28,$Q$18:$Q$167,0),MATCH(4,$Q$17:$U$17,0)),"") -> PK-BKU | X28: =IFERROR(INDEX($Q$18:$U$167,MATCH(V28,$Q$18:$Q$167,0),MATCH(3,$Q$17:$U$17,0)),"") -> A 320 | Y28: =IFERROR(INDEX($Q$18:$U$167,MATCH(V28,$Q$18:$Q$167,0),MATCH(5,$Q$17:$U$17,0)),"") -> BATIK AIR | Z28: TRUE | AD28: =IF(D28="","-",D28) -> - | AE28: =IF(F28="","-",F28) -> - | AF28: 0.45902778 | AG28: 0.5 | AH28: =COUNTIFS($AD$18:$AD$167,">11:00",$AD$18:$AD$167,"<=12:00") -> 5 | AI28: =COUNTIFS($AE$18:$AE$167,">11:00",$AE$18:$AE$167,"<=12:00") -> 5 | AJ28: =AI28+AH28 -> 10 | AL28: B8 | AM28: =COUNTIFS($H$18:$H$167,AL28,$D$18:$D$167,"<=01:00") -> 0 | AN28: =COUNTIFS($H$18:$H$167,AL28,$D$18:$D$167,">01:00",$D$18:$D$167,"<=02:00") -> 0 | AO28: =COUNTIFS($H$18:$H$167,AL28,$D$18:$D$167,">02:00",$D$18:$D$167,"<=03:00") -> 0 | AP28: =COUNTIFS($H$18:$H$167,AL28,$D$18:$D$167,">03:00",$D$18:$D$167,"<=04:00") -> 0 | AQ28: =COUNTIFS($H$18:$H$167,AL28,$D$18:$D$167,">04:00",$D$18:$D$167,"<=05:00") -> 0 | AR28: =COUNTIFS($H$18:$H$167,AL28,$D$18:$D$167,">05:00",$D$18:$D$167,"<=06:00") -> 0 | AS28: =COUNTIFS($H$18:$H$167,AL28,$D$18:$D$167,">06:00",$D$18:$D$167,"<=07:00") -> 1 | AT28: =COUNTIFS($H$18:$H$167,AL28,$D$18:$D$167,">07:00",$D$18:$D$167,"<=08:00") -> 0 | AU28: =COUNTIFS($H$18:$H$167,AL28,$D$18:$D$167,">08:00",$D$18:$D$167,"<=09:00") -> 0 | AV28: =COUNTIFS($H$18:$H$167,AL28,$D$18:$D$167,">09:00",$D$18:$D$167,"<=10:00") -> 0 | AW28: =COUNTIFS($H$18:$H$167,AL28,$D$18:$D$167,">10:00",$D$18:$D$167,"<=11:00") -> 0 | AX28: =COUNTIFS($H$18:$H$167,AL28,$D$18:$D$167,">11:00",$D$18:$D$167,"<=12:00") -> 0 | AY28: =COUNTIFS($H$18:$H$167,AL28,$D$18:$D$167,">12:00",$D$18:$D$167,"<=13:00") -> 0 | AZ28: =COUNTIFS($H$18:$H$167,AL28,$D$18:$D$167,">13:00",$D$18:$D$167,"<=14:00") -> 0 | BA28: =COUNTIFS($H$18:$H$167,AL28,$D$18:$D$167,">14:00",$D$18:$D$167,"<=15:00") -> 0 | BB28: =COUNTIFS($H$18:$H$167,AL28,$D$18:$D$167,">15:00",$D$18:$D$167,"<=16:00") -> 1 | BC28: =COUNTIFS($H$18:$H$167,AL28,$D$18:$D$167,">16:00",$D$18:$D$167,"<=17:00") -> 0 | BD28: =COUNTIFS($H$18:$H$167,AL28,$D$18:$D$167,">17:00",$D$18:$D$167,"<=18:00") -> 0 | BE28: =COUNTIFS($H$18:$H$167,AL28,$D$18:$D$167,">18:00",$D$18:$D$167,"<=19:00") -> 0 | BF28: =COUNTIFS($H$18:$H$167,AL28,$D$18:$D$167,">19:00",$D$18:$D$167,"<=20:00") -> 0 | BG28: =COUNTIFS($H$18:$H$167,AL28,$D$18:$D$167,">20:00",$D$18:$D$167,"<=21:00") -> 0 | BH28: =COUNTIFS($H$18:$H$167,AL28,$D$18:$D$167,">21:00",$D$18:$D$167,"<=22:00") -> 0 | BI28: =COUNTIFS($H$18:$H$167,AL28,$D$18:$D$167,">22:00",$D$18:$D$167,"<=23:00") -> 0 | BJ28: =COUNTIFS($H$18:$H$167,AL28,$D$18:$D$167,">23:00") -> 0 | BK28: =SUM(AM28:BJ28) -> 2
A29: 12 | B29: T7-GBS | C29: =IF(B29>1,VLOOKUP(B29,DB!$D$4:$E$800,2,0),"") -> EMB 135 | D29: - | E29: FALSE | G29: FALSE | H29: SA04 | I29: =IF(K29>1,VLOOKUP(K29,DB!$A$4:$B$500,2,0),"") | J29: =IF(L29>1,VLOOKUP(L29,DB!$A$4:$B$500,2,0),"") | M29: KARISMA | O29: =IF(ISBLANK(F29),"RON","") -> RON | Q29: =IF(R29="RON",H29,"") -> SA04 | R29: =IF(O29="RON",O29,"") -> RON | S29: =IF(R29="RON",C29,"") -> EMB 135 | T29: =IF(R29="RON",B29,"") -> T7-GBS | U29: =IF(R29="RON",M29,"") -> KARISMA | V29: B9 | W29: =IFERROR(INDEX($Q$18:$U$167,MATCH(V29,$Q$18:$Q$167,0),MATCH(4,$Q$17:$U$17,0)),"") | X29: =IFERROR(INDEX($Q$18:$U$167,MATCH(V29,$Q$18:$Q$167,0),MATCH(3,$Q$17:$U$17,0)),"") | Y29: =IFERROR(INDEX($Q$18:$U$167,MATCH(V29,$Q$18:$Q$167,0),MATCH(5,$Q$17:$U$17,0)),"") | Z29: FALSE | AD29: =IF(D29="","-",D29) -> - | AE29: =IF(F29="","-",F29) -> - | AF29: 0.50069444 | AG29: 0.54166667 | AH29: =COUNTIFS($AD$18:$AD$167,">12:00",$AD$18:$AD$167,"<=13:00") -> 3 | AI29: =COUNTIFS($AE$18:$AE$167,">12:00",$AE$18:$AE$167,"<=13:00") -> 5 | AJ29: =AI29+AH29 -> 8 | AL29: B9 | AM29: =COUNTIFS($H$18:$H$167,AL29,$D$18:$D$167,"<=01:00") -> 0 | AN29: =COUNTIFS($H$18:$H$167,AL29,$D$18:$D$167,">01:00",$D$18:$D$167,"<=02:00") -> 0 | AO29: =COUNTIFS($H$18:$H$167,AL29,$D$18:$D$167,">02:00",$D$18:$D$167,"<=03:00") -> 0 | AP29: =COUNTIFS($H$18:$H$167,AL29,$D$18:$D$167,">03:00",$D$18:$D$167,"<=04:00") -> 0 | AQ29: =COUNTIFS($H$18:$H$167,AL29,$D$18:$D$167,">04:00",$D$18:$D$167,"<=05:00") -> 0 | AR29: =COUNTIFS($H$18:$H$167,AL29,$D$18:$D$167,">05:00",$D$18:$D$167,"<=06:00") -> 1 | AS29: =COUNTIFS($H$18:$H$167,AL29,$D$18:$D$167,">06:00",$D$18:$D$167,"<=07:00") -> 1 | AT29: =COUNTIFS($H$18:$H$167,AL29,$D$18:$D$167,">07:00",$D$18:$D$167,"<=08:00") -> 0 | AU29: =COUNTIFS($H$18:$H$167,AL29,$D$18:$D$167,">08:00",$D$18:$D$167,"<=09:00") -> 0 | AV29: =COUNTIFS($H$18:$H$167,AL29,$D$18:$D$167,">09:00",$D$18:$D$167,"<=10:00") -> 0 | AW29: =COUNTIFS($H$18:$H$167,AL29,$D$18:$D$167,">10:00",$D$18:$D$167,"<=11:00") -> 0 | AX29: =COUNTIFS($H$18:$H$167,AL29,$D$18:$D$167,">11:00",$D$18:$D$167,"<=12:00") -> 0 | AY29: =COUNTIFS($H$18:$H$167,AL29,$D$18:$D$167,">12:00",$D$18:$D$167,"<=13:00") -> 0 | AZ29: =COUNTIFS($H$18:$H$167,AL29,$D$18:$D$167,">13:00",$D$18:$D$167,"<=14:00") -> 0 | BA29: =COUNTIFS($H$18:$H$167,AL29,$D$18:$D$167,">14:00",$D$18:$D$167,"<=15:00") -> 0 | BB29: =COUNTIFS($H$18:$H$167,AL29,$D$18:$D$167,">15:00",$D$18:$D$167,"<=16:00") -> 1 | BC29: =COUNTIFS($H$18:$H$167,AL29,$D$18:$D$167,">16:00",$D$18:$D$167,"<=17:00") -> 0 | BD29: =COUNTIFS($H$18:$H$167,AL29,$D$18:$D$167,">17:00",$D$18:$D$167,"<=18:00") -> 0 | BE29: =COUNTIFS($H$18:$H$167,AL29,$D$18:$D$167,">18:00",$D$18:$D$167,"<=19:00") -> 0 | BF29: =COUNTIFS($H$18:$H$167,AL29,$D$18:$D$167,">19:00",$D$18:$D$167,"<=20:00") -> 0 | BG29: =COUNTIFS($H$18:$H$167,AL29,$D$18:$D$167,">20:00",$D$18:$D$167,"<=21:00") -> 1 | BH29: =COUNTIFS($H$18:$H$167,AL29,$D$18:$D$167,">21:00",$D$18:$D$167,"<=22:00") -> 0 | BI29: =COUNTIFS($H$18:$H$167,AL29,$D$18:$D$167,">22:00",$D$18:$D$167,"<=23:00") -> 0 | BJ29: =COUNTIFS($H$18:$H$167,AL29,$D$18:$D$167,">23:00") -> 0 | BK29: =SUM(AM29:BJ29) -> 4
A30: 13 | B30: PK-RSS | C30: =IF(B30>1,VLOOKUP(B30,DB!$D$4:$E$800,2,0),"") -> EMB 135 | D30: - | E30: FALSE | G30: FALSE | H30: SA05 | I30: =IF(K30>1,VLOOKUP(K30,DB!$A$4:$B$500,2,0),"") | J30: =IF(L30>1,VLOOKUP(L30,DB!$A$4:$B$500,2,0),"") | M30: B. G. S. | O30: =IF(ISBLANK(F30),"RON","") -> RON | Q30: =IF(R30="RON",H30,"") -> SA05 | R30: =IF(O30="RON",O30,"") -> RON | S30: =IF(R30="RON",C30,"") -> EMB 135 | T30: =IF(R30="RON",B30,"") -> PK-RSS | U30: =IF(R30="RON",M30,"") -> B. G. S. | V30: B10 | W30: =IFERROR(INDEX($Q$18:$U$167,MATCH(V30,$Q$18:$Q$167,0),MATCH(4,$Q$17:$U$17,0)),"") | X30: =IFERROR(INDEX($Q$18:$U$167,MATCH(V30,$Q$18:$Q$167,0),MATCH(3,$Q$17:$U$17,0)),"") | Y30: =IFERROR(INDEX($Q$18:$U$167,MATCH(V30,$Q$18:$Q$167,0),MATCH(5,$Q$17:$U$17,0)),"") | Z30: FALSE | AD30: =IF(D30="","-",D30) -> - | AE30: =IF(F30="","-",F30) -> - | AF30: 0.54236111 | AG30: 0.58333333 | AH30: =COUNTIFS($AD$18:$AD$167,">13:00",$AD$18:$AD$167,"<=14:00") -> 7 | AI30: =COUNTIFS($AE$18:$AE$167,">13:00",$AE$18:$AE$167,"<=14:00") -> 4 | AJ30: =AI30+AH30 -> 11 | AL30: B10 | AM30: =COUNTIFS($H$18:$H$167,AL30,$D$18:$D$167,"<=01:00") -> 0 | AN30: =COUNTIFS($H$18:$H$167,AL30,$D$18:$D$167,">01:00",$D$18:$D$167,"<=02:00") -> 0 | AO30: =COUNTIFS($H$18:$H$167,AL30,$D$18:$D$167,">02:00",$D$18:$D$167,"<=03:00") -> 0 | AP30: =COUNTIFS($H$18:$H$167,AL30,$D$18:$D$167,">03:00",$D$18:$D$167,"<=04:00") -> 0 | AQ30: =COUNTIFS($H$18:$H$167,AL30,$D$18:$D$167,">04:00",$D$18:$D$167,"<=05:00") -> 0 | AR30: =COUNTIFS($H$18:$H$167,AL30,$D$18:$D$167,">05:00",$D$18:$D$167,"<=06:00") -> 0 | AS30: =COUNTIFS($H$18:$H$167,AL30,$D$18:$D$167,">06:00",$D$18:$D$167,"<=07:00") -> 0 | AT30: =COUNTIFS($H$18:$H$167,AL30,$D$18:$D$167,">07:00",$D$18:$D$167,"<=08:00") -> 0 | AU30: =COUNTIFS($H$18:$H$167,AL30,$D$18:$D$167,">08:00",$D$18:$D$167,"<=09:00") -> 0 | AV30: =COUNTIFS($H$18:$H$167,AL30,$D$18:$D$167,">09:00",$D$18:$D$167,"<=10:00") -> 0 | AW30: =COUNTIFS($H$18:$H$167,AL30,$D$18:$D$167,">10:00",$D$18:$D$167,"<=11:00") -> 0 | AX30: =COUNTIFS($H$18:$H$167,AL30,$D$18:$D$167,">11:00",$D$18:$D$167,"<=12:00") -> 0 | AY30: =COUNTIFS($H$18:$H$167,AL30,$D$18:$D$167,">12:00",$D$18:$D$167,"<=13:00") -> 0 | AZ30: =COUNTIFS($H$18:$H$167,AL30,$D$18:$D$167,">13:00",$D$18:$D$167,"<=14:00") -> 0 | BA30: =COUNTIFS($H$18:$H$167,AL30,$D$18:$D$167,">14:00",$D$18:$D$167,"<=15:00") -> 0 | BB30: =COUNTIFS($H$18:$H$167,AL30,$D$18:$D$167,">15:00",$D$18:$D$167,"<=16:00") -> 0 | BC30: =COUNTIFS($H$18:$H$167,AL30,$D$18:$D$167,">16:00",$D$18:$D$167,"<=17:00") -> 0 | BD30: =COUNTIFS($H$18:$H$167,AL30,$D$18:$D$167,">17:00",$D$18:$D$167,"<=18:00") -> 1 | BE30: =COUNTIFS($H$18:$H$167,AL30,$D$18:$D$167,">18:00",$D$18:$D$167,"<=19:00") -> 0 | BF30: =COUNTIFS($H$18:$H$167,AL30,$D$18:$D$167,">19:00",$D$18:$D$167,"<=20:00") -> 1 | BG30: =COUNTIFS($H$18:$H$167,AL30,$D$18:$D$167,">20:00",$D$18:$D$167,"<=21:00") -> 0 | BH30: =COUNTIFS($H$18:$H$167,AL30,$D$18:$D$167,">21:00",$D$18:$D$167,"<=22:00") -> 0 | BI30: =COUNTIFS($H$18:$H$167,AL30,$D$18:$D$167,">22:00",$D$18:$D$167,"<=23:00") -> 0 | BJ30: =COUNTIFS($H$18:$H$167,AL30,$D$18:$D$167,">23:00") -> 0 | BK30: =SUM(AM30:BJ30) -> 2
A31: 14 | B31: PK-VCS | C31: =IF(B31>1,VLOOKUP(B31,DB!$D$4:$E$800,2,0),"") -> EMB 135 | D31: - | E31: FALSE | G31: FALSE | H31: SA06 | I31: =IF(K31>1,VLOOKUP(K31,DB!$A$4:$B$500,2,0),"") | J31: =IF(L31>1,VLOOKUP(L31,DB!$A$4:$B$500,2,0),"") | M31: =IF(B31>1,VLOOKUP(B31,DB!$D$4:$F$800,3,0),"") -> JETSET | O31: =IF(ISBLANK(F31),"RON","") -> RON | Q31: =IF(R31="RON",H31,"") -> SA06 | R31: =IF(O31="RON",O31,"") -> RON | S31: =IF(R31="RON",C31,"") -> EMB 135 | T31: =IF(R31="RON",B31,"") -> PK-VCS | U31: =IF(R31="RON",M31,"") -> JETSET | V31: B11 | W31: =IFERROR(INDEX($Q$18:$U$167,MATCH(V31,$Q$18:$Q$167,0),MATCH(4,$Q$17:$U$17,0)),"") -> PK-BBJ | X31: =IFERROR(INDEX($Q$18:$U$167,MATCH(V31,$Q$18:$Q$167,0),MATCH(3,$Q$17:$U$17,0)),"") -> B 734 | Y31: =IFERROR(INDEX($Q$18:$U$167,MATCH(V31,$Q$18:$Q$167,0),MATCH(5,$Q$17:$U$17,0)),"") -> B. B. N. | Z31: TRUE | AD31: =IF(D31="","-",D31) -> - | AE31: =IF(F31="","-",F31) -> - | AF31: 0.58402778 | AG31: 0.625 | AH31: =COUNTIFS($AD$18:$AD$167,">14:00",$AD$18:$AD$167,"<=15:00") -> 1 | AI31: =COUNTIFS($AE$18:$AE$167,">14:00",$AE$18:$AE$167,"<=15:00") -> 3 | AJ31: =AI31+AH31 -> 4 | AL31: B11 | AM31: =COUNTIFS($H$18:$H$167,AL31,$D$18:$D$167,"<=01:00") -> 0 | AN31: =COUNTIFS($H$18:$H$167,AL31,$D$18:$D$167,">01:00",$D$18:$D$167,"<=02:00") -> 0 | AO31: =COUNTIFS($H$18:$H$167,AL31,$D$18:$D$167,">02:00",$D$18:$D$167,"<=03:00") -> 0 | AP31: =COUNTIFS($H$18:$H$167,AL31,$D$18:$D$167,">03:00",$D$18:$D$167,"<=04:00") -> 0 | AQ31: =COUNTIFS($H$18:$H$167,AL31,$D$18:$D$167,">04:00",$D$18:$D$167,"<=05:00") -> 0 | AR31: =COUNTIFS($H$18:$H$167,AL31,$D$18:$D$167,">05:00",$D$18:$D$167,"<=06:00") -> 0 | AS31: =COUNTIFS($H$18:$H$167,AL31,$D$18:$D$167,">06:00",$D$18:$D$167,"<=07:00") -> 1 | AT31: =COUNTIFS($H$18:$H$167,AL31,$D$18:$D$167,">07:00",$D$18:$D$167,"<=08:00") -> 0 | AU31: =COUNTIFS($H$18:$H$167,AL31,$D$18:$D$167,">08:00",$D$18:$D$167,"<=09:00") -> 0 | AV31: =COUNTIFS($H$18:$H$167,AL31,$D$18:$D$167,">09:00",$D$18:$D$167,"<=10:00") -> 0 | AW31: =COUNTIFS($H$18:$H$167,AL31,$D$18:$D$167,">10:00",$D$18:$D$167,"<=11:00") -> 0 | AX31: =COUNTIFS($H$18:$H$167,AL31,$D$18:$D$167,">11:00",$D$18:$D$167,"<=12:00") -> 0 | AY31: =COUNTIFS($H$18:$H$167,AL31,$D$18:$D$167,">12:00",$D$18:$D$167,"<=13:00") -> 0 | AZ31: =COUNTIFS($H$18:$H$167,AL31,$D$18:$D$167,">13:00",$D$18:$D$167,"<=14:00") -> 1 | BA31: =COUNTIFS($H$18:$H$167,AL31,$D$18:$D$167,">14:00",$D$18:$D$167,"<=15:00") -> 0 | BB31: =COUNTIFS($H$18:$H$167,AL31,$D$18:$D$167,">15:00",$D$18:$D$167,"<=16:00") -> 0 | BC31: =COUNTIFS($H$18:$H$167,AL31,$D$18:$D$167,">16:00",$D$18:$D$167,"<=17:00") -> 0 | BD31: =COUNTIFS($H$18:$H$167,AL31,$D$18:$D$167,">17:00",$D$18:$D$167,"<=18:00") -> 0 | BE31: =COUNTIFS($H$18:$H$167,AL31,$D$18:$D$167,">18:00",$D$18:$D$167,"<=19:00") -> 0 | BF31: =COUNTIFS($H$18:$H$167,AL31,$D$18:$D$167,">19:00",$D$18:$D$167,"<=20:00") -> 1 | BG31: =COUNTIFS($H$18:$H$167,AL31,$D$18:$D$167,">20:00",$D$18:$D$167,"<=21:00") -> 0 | BH31: =COUNTIFS($H$18:$H$167,AL31,$D$18:$D$167,">21:00",$D$18:$D$167,"<=22:00") -> 0 | BI31: =COUNTIFS($H$18:$H$167,AL31,$D$18:$D$167,">22:00",$D$18:$D$167,"<=23:00") -> 0 | BJ31: =COUNTIFS($H$18:$H$167,AL31,$D$18:$D$167,">23:00") -> 0 | BK31: =SUM(AM31:BJ31) -> 3
A32: 15 | B32: N-939GS | C32: =IF(B32>1,VLOOKUP(B32,DB!$D$4:$E$800,2,0),"") -> GLEX | D32: - | E32: FALSE | G32: FALSE | H32: SA07 | I32: =IF(K32>1,VLOOKUP(K32,DB!$A$4:$B$500,2,0),"") | J32: =IF(L32>1,VLOOKUP(L32,DB!$A$4:$B$500,2,0),"") | M32: =IF(B32>1,VLOOKUP(B32,DB!$D$4:$F$800,3,0),"") -> BIOMANTARA | O32: =IF(ISBLANK(F32),"RON","") -> RON | Q32: =IF(R32="RON",H32,"") -> SA07 | R32: =IF(O32="RON",O32,"") -> RON | S32: =IF(R32="RON",C32,"") -> GLEX | T32: =IF(R32="RON",B32,"") -> N-939GS | U32: =IF(R32="RON",M32,"") -> BIOMANTARA | V32: B12 | W32: =IFERROR(INDEX($Q$18:$U$167,MATCH(V32,$Q$18:$Q$167,0),MATCH(4,$Q$17:$U$17,0)),"") -> PK-YSH | X32: =IFERROR(INDEX($Q$18:$U$167,MATCH(V32,$Q$18:$Q$167,0),MATCH(3,$Q$17:$U$17,0)),"") -> B 733 | Y32: =IFERROR(INDEX($Q$18:$U$167,MATCH(V32,$Q$18:$Q$167,0),MATCH(5,$Q$17:$U$17,0)),"") -> TRIGANA | Z32: TRUE | AD32: =IF(D32="","-",D32) -> - | AE32: =IF(F32="","-",F32) -> - | AF32: 0.62569444 | AG32: 0.66666667 | AH32: =COUNTIFS($AD$18:$AD$167,">15:00",$AD$18:$AD$167,"<=16:00") -> 5 | AI32: =COUNTIFS($AE$18:$AE$167,">15:00",$AE$18:$AE$167,"<=16:00") -> 3 | AJ32: =AI32+AH32 -> 8 | AL32: B12 | AM32: =COUNTIFS($H$18:$H$167,AL32,$D$18:$D$167,"<=01:00") -> 0 | AN32: =COUNTIFS($H$18:$H$167,AL32,$D$18:$D$167,">01:00",$D$18:$D$167,"<=02:00") -> 0 | AO32: =COUNTIFS($H$18:$H$167,AL32,$D$18:$D$167,">02:00",$D$18:$D$167,"<=03:00") -> 0 | AP32: =COUNTIFS($H$18:$H$167,AL32,$D$18:$D$167,">03:00",$D$18:$D$167,"<=04:00") -> 0 | AQ32: =COUNTIFS($H$18:$H$167,AL32,$D$18:$D$167,">04:00",$D$18:$D$167,"<=05:00") -> 1 | AR32: =COUNTIFS($H$18:$H$167,AL32,$D$18:$D$167,">05:00",$D$18:$D$167,"<=06:00") -> 0 | AS32: =COUNTIFS($H$18:$H$167,AL32,$D$18:$D$167,">06:00",$D$18:$D$167,"<=07:00") -> 0 | AT32: =COUNTIFS($H$18:$H$167,AL32,$D$18:$D$167,">07:00",$D$18:$D$167,"<=08:00") -> 0 | AU32: =COUNTIFS($H$18:$H$167,AL32,$D$18:$D$167,">08:00",$D$18:$D$167,"<=09:00") -> 0 | AV32: =COUNTIFS($H$18:$H$167,AL32,$D$18:$D$167,">09:00",$D$18:$D$167,"<=10:00") -> 1 | AW32: =COUNTIFS($H$18:$H$167,AL32,$D$18:$D$167,">10:00",$D$18:$D$167,"<=11:00") -> 0 | AX32: =COUNTIFS($H$18:$H$167,AL32,$D$18:$D$167,">11:00",$D$18:$D$167,"<=12:00") -> 0 | AY32: =COUNTIFS($H$18:$H$167,AL32,$D$18:$D$167,">12:00",$D$18:$D$167,"<=13:00") -> 0 | AZ32: =COUNTIFS($H$18:$H$167,AL32,$D$18:$D$167,">13:00",$D$18:$D$167,"<=14:00") -> 1 | BA32: =COUNTIFS($H$18:$H$167,AL32,$D$18:$D$167,">14:00",$D$18:$D$167,"<=15:00") -> 0 | BB32: =COUNTIFS($H$18:$H$167,AL32,$D$18:$D$167,">15:00",$D$18:$D$167,"<=16:00") -> 0 | BC32: =COUNTIFS($H$18:$H$167,AL32,$D$18:$D$167,">16:00",$D$18:$D$167,"<=17:00") -> 0 | BD32: =COUNTIFS($H$18:$H$167,AL32,$D$18:$D$167,">17:00",$D$18:$D$167,"<=18:00") -> 1 | BE32: =COUNTIFS($H$18:$H$167,AL32,$D$18:$D$167,">18:00",$D$18:$D$167,"<=19:00") -> 0 | BF32: =COUNTIFS($H$18:$H$167,AL32,$D$18:$D$167,">19:00",$D$18:$D$167,"<=20:00") -> 0 | BG32: =COUNTIFS($H$18:$H$167,AL32,$D$18:$D$167,">20:00",$D$18:$D$167,"<=21:00") -> 0 | BH32: =COUNTIFS($H$18:$H$167,AL32,$D$18:$D$167,">21:00",$D$18:$D$167,"<=22:00") -> 0 | BI32: =COUNTIFS($H$18:$H$167,AL32,$D$18:$D$167,">22:00",$D$18:$D$167,"<=23:00") -> 0 | BJ32: =COUNTIFS($H$18:$H$167,AL32,$D$18:$D$167,">23:00") -> 0 | BK32: =SUM(AM32:BJ32) -> 4
A33: 16 | B33: PK-IDR | C33: =IF(B33>1,VLOOKUP(B33,DB!$D$4:$E$800,2,0),"") -> CL 850 | D33: - | E33: FALSE | G33: FALSE | H33: SA08 | I33: =IF(K33>1,VLOOKUP(K33,DB!$A$4:$B$500,2,0),"") | J33: =IF(L33>1,VLOOKUP(L33,DB!$A$4:$B$500,2,0),"") | M33: PREMI | O33: =IF(ISBLANK(F33),"RON","") -> RON | Q33: =IF(R33="RON",H33,"") -> SA08 | R33: =IF(O33="RON",O33,"") -> RON | S33: =IF(R33="RON",C33,"") -> CL 850 | T33: =IF(R33="RON",B33,"") -> PK-IDR | U33: =IF(R33="RON",M33,"") -> PREMI | V33: B13 | W33: =IFERROR(INDEX($Q$18:$U$167,MATCH(V33,$Q$18:$Q$167,0),MATCH(4,$Q$17:$U$17,0)),"") | X33: =IFERROR(INDEX($Q$18:$U$167,MATCH(V33,$Q$18:$Q$167,0),MATCH(3,$Q$17:$U$17,0)),"") | Y33: =IFERROR(INDEX($Q$18:$U$167,MATCH(V33,$Q$18:$Q$167,0),MATCH(5,$Q$17:$U$17,0)),"") | Z33: FALSE | AD33: =IF(D33="","-",D33) -> - | AE33: =IF(F33="","-",F33) -> - | AF33: 0.66736111 | AG33: 0.70833333 | AH33: =COUNTIFS($AD$18:$AD$167,">16:00",$AD$18:$AD$167,"<=17:00") -> 6 | AI33: =COUNTIFS($AE$18:$AE$167,">16:00",$AE$18:$AE$167,"<=17:00") -> 1 | AJ33: =AI33+AH33 -> 7 | AL33: B13 | AM33: =COUNTIFS($H$18:$H$167,AL33,$D$18:$D$167,"<=01:00") -> 0 | AN33: =COUNTIFS($H$18:$H$167,AL33,$D$18:$D$167,">01:00",$D$18:$D$167,"<=02:00") -> 0 | AO33: =COUNTIFS($H$18:$H$167,AL33,$D$18:$D$167,">02:00",$D$18:$D$167,"<=03:00") -> 0 | AP33: =COUNTIFS($H$18:$H$167,AL33,$D$18:$D$167,">03:00",$D$18:$D$167,"<=04:00") -> 0 | AQ33: =COUNTIFS($H$18:$H$167,AL33,$D$18:$D$167,">04:00",$D$18:$D$167,"<=05:00") -> 1 | AR33: =COUNTIFS($H$18:$H$167,AL33,$D$18:$D$167,">05:00",$D$18:$D$167,"<=06:00") -> 0 | AS33: =COUNTIFS($H$18:$H$167,AL33,$D$18:$D$167,">06:00",$D$18:$D$167,"<=07:00") -> 0 | AT33: =COUNTIFS($H$18:$H$167,AL33,$D$18:$D$167,">07:00",$D$18:$D$167,"<=08:00") -> 1 | AU33: =COUNTIFS($H$18:$H$167,AL33,$D$18:$D$167,">08:00",$D$18:$D$167,"<=09:00") -> 0 | AV33: =COUNTIFS($H$18:$H$167,AL33,$D$18:$D$167,">09:00",$D$18:$D$167,"<=10:00") -> 0 | AW33: =COUNTIFS($H$18:$H$167,AL33,$D$18:$D$167,">10:00",$D$18:$D$167,"<=11:00") -> 0 | AX33: =COUNTIFS($H$18:$H$167,AL33,$D$18:$D$167,">11:00",$D$18:$D$167,"<=12:00") -> 0 | AY33: =COUNTIFS($H$18:$H$167,AL33,$D$18:$D$167,">12:00",$D$18:$D$167,"<=13:00") -> 0 | AZ33: =COUNTIFS($H$18:$H$167,AL33,$D$18:$D$167,">13:00",$D$18:$D$167,"<=14:00") -> 0 | BA33: =COUNTIFS($H$18:$H$167,AL33,$D$18:$D$167,">14:00",$D$18:$D$167,"<=15:00") -> 0 | BB33: =COUNTIFS($H$18:$H$167,AL33,$D$18:$D$167,">15:00",$D$18:$D$167,"<=16:00") -> 1 | BC33: =COUNTIFS($H$18:$H$167,AL33,$D$18:$D$167,">16:00",$D$18:$D$167,"<=17:00") -> 0 | BD33: =COUNTIFS($H$18:$H$167,AL33,$D$18:$D$167,">17:00",$D$18:$D$167,"<=18:00") -> 0 | BE33: =COUNTIFS($H$18:$H$167,AL33,$D$18:$D$167,">18:00",$D$18:$D$167,"<=19:00") -> 0 | BF33: =COUNTIFS($H$18:$H$167,AL33,$D$18:$D$167,">19:00",$D$18:$D$167,"<=20:00") -> 0 | BG33: =COUNTIFS($H$18:$H$167,AL33,$D$18:$D$167,">20:00",$D$18:$D$167,"<=21:00") -> 1 | BH33: =COUNTIFS($H$18:$H$167,AL33,$D$18:$D$167,">21:00",$D$18:$D$167,"<=22:00") -> 0 | BI33: =COUNTIFS($H$18:$H$167,AL33,$D$18:$D$167,">22:00",$D$18:$D$167,"<=23:00") -> 0 | BJ33: =COUNTIFS($H$18:$H$167,AL33,$D$18:$D$167,">23:00") -> 0 | BK33: =SUM(AM33:BJ33) -> 4
